Workbook

Sheet Start
B2: Cash flow and S-curve
B3: Profit is an opinion about the end of the job. Cash is a fact about today. This file shows both.
B4: The Project Control Hub · free template
B7: FIVE STEPS
B8: 1 | C8: Setup → | D8: The contract terms: value, retention, how long until you are paid, supplier credit, any advance. | E8: 2 minutes
B9: 2 | C9: Cash flow → | D9: The cost you pay each month. The engine values the work, holds retention, pays you later. | E9: 10 minutes
B10: 3 | C10: Dashboard → | D10: Read the deepest point. That is the cash this job must have access to at its worst. | E10: —
B11: 4 | C11: What if → | D11: Test one lever at a time: faster payment, supplier credit, an advance. The profit never moves. | E11: 5 minutes
B12: 5 | C12: Portfolio → | D12: Add the other jobs you are running or bidding. The holes stack; check them against the facility. | E12: 5 minutes
B14: HOW THE MONEY MOVES
C15: You do the work | D15: And pay for it in the month, unless suppliers give you credit.
C16: It is valued and certified | D16: Retention is carved off every certificate; an advance is recovered from it.
C17: You are paid, later | D17: Usually a month after the work. Until then, you are financing the client.
C18: Retention comes back last | D18: Half at completion, half after the defects period. Money earned, held elsewhere.
B20: HOW TO READ THE CELLS
C21: Yellow, blue text | D21: Yours to fill in.
C22: White, black text | D22: A formula. Leave it alone and it keeps working.
C23: Red | D23: Cash below zero; the deepest month is darker. Or a facility that is too small.
C24: Green | D24: Profit, and levers that make the hole shallower.
B26: WHAT IS IN THIS FILE
C27: Dashboard | D27: Six numbers, a paragraph in plain English, four charts and the five levers.
C28: Setup | D28: Contract value, retention, payment and supplier timing, advance, overdraft.
C29: Cash flow | D29: The monthly engine: value, retention, certificates, money in and out, cash position.
C30: What if | D30: The same job on different terms, side by side with the base.
C31: Portfolio | D31: Up to five jobs at once, stacked against the overdraft facility.
B33: EXPLAINED IN
C34: Cost & Cash Topic 16 · Cash flow fundamentals
C35: Cost & Cash Topic 17 · The interim payment cycle
C36: Cost & Cash Topic 18 · Overtrading
C37: Cost & Cash Topic 19 · Managing the hole
B39: Blank: twenty-four months ready to fill. The example file shows the example project.
B44: Free to use and adapt on your own projects. https://theprojectcontrolhub.com/

Sheet Dashboard
B2: Cash flow | K2: The Project Control Hub
B3: =IF(Setup!B7="","Fill in the Setup sheet first",Setup!B6&" · contract "&TEXT(Setup!B7,"$#,##0")&" · retention "&TEXT(Setup!B8,"0%")&" · paid "&Setup!B9&" month(s) after the work")
B5: DEEPEST CASH POSITION | D5: MONTHS BELOW ZERO | F5: COST OF THE HOLE | H5: PROFIT AT THE END | J5: RETENTION STILL HELD | L5: FACILITY HEADROOM
B6: ='Cash flow'!$D$36 | D6: ='Cash flow'!$D$38 | F6: ='Cash flow'!$D$39 | H6: ='Cash flow'!$D$35 | J6: ='Cash flow'!$D$42 | L6: ='Cash flow'!$D$43
B8: =IF('Cash flow'!$D$37="","never below zero","month "&'Cash flow'!$D$37) | D8: ="months the job is financed by you" | F8: ="rule of thumb · month by month "&TEXT('Cash flow'!$D$40,"$#,##0") | H8: ="contract "&TEXT('Cash flow'!$D$34,"$#,##0")&" − cost "&TEXT('Cash flow'!$D$33,"$#,##0") | J8: ="earned, not yet paid" | L8: =IF(Portfolio!G7="","","all jobs together: "&TEXT(Portfolio!G7,"$#,##0"))
B11: =IF('Cash flow'!$D$33=0,"",IF('Cash flow'!$D$36>=0,"This job never needs your cash: the client funds it.","Profit is an opinion; cash is a fact. This job makes "&TEXT('Cash flow'!$D$35,"$#,##0")&" and still needs "&TEXT(-'Cash flow'!$D$36,"$#,##0")&" of cash at its worst, in month "&'Cash flow'!$D$37&". It is below zero for "&'Cash flow'!$D$38&" months, and "&TEXT('Cash flow'!$D$42,"$#,##0")&" of earned money is still held as retention at the end."))
B14: THE CURVE OUT, THE CURVE BACK, AND THE GAP
B32: MOVE THE TIMING, NOT THE PROFIT
B51: FIVE TIMING LEVERS · none of them changes the profit
B52: Lever | F52: Effect on the hole | H52: Where to try it | J52: What it costs you
B53: Front-load the schedule of values | F53: Shallower | H53: Valuation override | J53: A sceptical client QS
B54: Certify and get paid faster | F54: Shallower | H54: What if: payment months | J54: Immaculate applications
B55: Pay your own suppliers later | F55: Shallower | H55: What if: supplier credit | J55: A negotiation
B56: Take a mobilisation advance | F56: Much shallower | H56: What if: advance % | J56: A bank guarantee; recovery later
B57: Buy materials early / let retention build | F57: Deeper | H57: Cost timing; retention % | J57: Cash spent before it is needed
B59: Everything on this page reads from Setup, Cash flow, What if and Portfolio.

Sheet Setup
A1: Setup | D1: The Project Control Hub
A2: The contract terms that decide when money moves. None of them change the profit.
A3: Change a term here and watch the Dashboard: the depth of the hole is a timing decision.
A6: Project
A7: Contract value ($) | D7: Topic 16: $1,000,000.
A8: Retention held on each certificate | B8: 0.05 | D8: Usually 5%. Topic 17.
A9: Months from doing the work to being paid | B9: 1 | D9: Value, certify, pay: usually one month, sometimes two.
A10: Months of credit from suppliers | B10: 0 | D10: 0 = you pay in the month. 1 = 30-day terms or better.
A11: Mobilisation advance (% of contract) | B11: 0 | D11: Paid in month 1. Topic 19: 10% would bury the hole.
A12: Advance recovered from each certificate (%) | B12: 0 | D12: Deducted until the advance is repaid.
A13: First retention release: month | D13: Usually practical completion. Empty if outside the 24 months.
A14: First release: share of retention | B14: 0.5 | D14: Usually half.
A15: Second retention release: month | D15: End of the defects period, often a year after completion.
A16: Second release: share of retention | B16: 0.5 | D16: The other half.
A17: Overdraft interest rate (per year) | D17: Topic 16: 8%.
A18: Overdraft facility ($) | D18: Topic 18: $150,000.
A19: Month 1 ends on | D19: Optional. Dates the months.

Sheet Cash flow
A1: Cash flow | T1: The Project Control Hub
A2: Money out and money in, month by month. The gap between them is the cash this job needs.
A3: Fill the cost you pay each month (column C). Override a valuation (D) only if your schedule of values is front-loaded.
A6: Month | B6: Month end | C6: Cost incurred ($) | D6: Valuation override ($) | E6: Value of work ($) | F6: Advance recovered ($) | G6: Retention deducted ($) | H6: Net certificate ($) | I6: Certificates paid ($) | J6: Advance received ($) | K6: Retention released ($) | L6: Money in ($) | M6: Money out ($) | N6: Cumulative out ($) | O6: Cumulative in ($) | P6: Cash position ($) | Q6: Retention held ($) | R6: Interest this month ($) | S6: Below zero (chart) | T6: Above zero (chart)
A7: 1 | B7: =IF(OR(Setup!$B$19="",Setup!$B$19=0),"",EOMONTH(Setup!$B$19,A7-1)) | E7: =IF(D7<>"",D7,IF(SUM($C$7:$C$30)=0,0,C7*Setup!$B$7/SUM($C$7:$C$30))) | F7: =MAX(0,MIN(Setup!$B$11*Setup!$B$7-0,E7*Setup!$B$12)) | G7: =E7*Setup!$B$8 | H7: =E7-G7-F7 | I7: =IF(A7-Setup!$B$9<1,0,INDEX($H$7:$H$30,A7-Setup!$B$9)) | J7: =IF(A7=1,Setup!$B$11*Setup!$B$7,0) | K7: =IF(A7=Setup!$B$13,SUM($G$7:G7)*Setup!$B$14,0)+IF(A7=Setup!$B$15,SUM($G$7:G7)*Setup!$B$16,0) | L7: =I7+J7+K7 | M7: =IF(A7-Setup!$B$10<1,0,INDEX($C$7:$C$30,A7-Setup!$B$10)) | N7: =SUM($M$7:M7) | O7: =SUM($L$7:L7) | P7: =O7-N7 | Q7: =SUM($G$7:G7)-SUM($K$7:K7) | R7: =IF(P7<0,-P7*Setup!$B$17/12,0) | S7: =MIN(P7,0) | T7: =MAX(P7,0)
A8: 2 | B8: =IF(OR(Setup!$B$19="",Setup!$B$19=0),"",EOMONTH(Setup!$B$19,A8-1)) | E8: =IF(D8<>"",D8,IF(SUM($C$7:$C$30)=0,0,C8*Setup!$B$7/SUM($C$7:$C$30))) | F8: =MAX(0,MIN(Setup!$B$11*Setup!$B$7-SUM($F$7:F7),E8*Setup!$B$12)) | G8: =E8*Setup!$B$8 | H8: =E8-G8-F8 | I8: =IF(A8-Setup!$B$9<1,0,INDEX($H$7:$H$30,A8-Setup!$B$9)) | J8: =IF(A8=1,Setup!$B$11*Setup!$B$7,0) | K8: =IF(A8=Setup!$B$13,SUM($G$7:G8)*Setup!$B$14,0)+IF(A8=Setup!$B$15,SUM($G$7:G8)*Setup!$B$16,0) | L8: =I8+J8+K8 | M8: =IF(A8-Setup!$B$10<1,0,INDEX($C$7:$C$30,A8-Setup!$B$10)) | N8: =SUM($M$7:M8) | O8: =SUM($L$7:L8) | P8: =O8-N8 | Q8: =SUM($G$7:G8)-SUM($K$7:K8) | R8: =IF(P8<0,-P8*Setup!$B$17/12,0) | S8: =MIN(P8,0) | T8: =MAX(P8,0)
A9: 3 | B9: =IF(OR(Setup!$B$19="",Setup!$B$19=0),"",EOMONTH(Setup!$B$19,A9-1)) | E9: =IF(D9<>"",D9,IF(SUM($C$7:$C$30)=0,0,C9*Setup!$B$7/SUM($C$7:$C$30))) | F9: =MAX(0,MIN(Setup!$B$11*Setup!$B$7-SUM($F$7:F8),E9*Setup!$B$12)) | G9: =E9*Setup!$B$8 | H9: =E9-G9-F9 | I9: =IF(A9-Setup!$B$9<1,0,INDEX($H$7:$H$30,A9-Setup!$B$9)) | J9: =IF(A9=1,Setup!$B$11*Setup!$B$7,0) | K9: =IF(A9=Setup!$B$13,SUM($G$7:G9)*Setup!$B$14,0)+IF(A9=Setup!$B$15,SUM($G$7:G9)*Setup!$B$16,0) | L9: =I9+J9+K9 | M9: =IF(A9-Setup!$B$10<1,0,INDEX($C$7:$C$30,A9-Setup!$B$10)) | N9: =SUM($M$7:M9) | O9: =SUM($L$7:L9) | P9: =O9-N9 | Q9: =SUM($G$7:G9)-SUM($K$7:K9) | R9: =IF(P9<0,-P9*Setup!$B$17/12,0) | S9: =MIN(P9,0) | T9: =MAX(P9,0)
A10: 4 | B10: =IF(OR(Setup!$B$19="",Setup!$B$19=0),"",EOMONTH(Setup!$B$19,A10-1)) | E10: =IF(D10<>"",D10,IF(SUM($C$7:$C$30)=0,0,C10*Setup!$B$7/SUM($C$7:$C$30))) | F10: =MAX(0,MIN(Setup!$B$11*Setup!$B$7-SUM($F$7:F9),E10*Setup!$B$12)) | G10: =E10*Setup!$B$8 | H10: =E10-G10-F10 | I10: =IF(A10-Setup!$B$9<1,0,INDEX($H$7:$H$30,A10-Setup!$B$9)) | J10: =IF(A10=1,Setup!$B$11*Setup!$B$7,0) | K10: =IF(A10=Setup!$B$13,SUM($G$7:G10)*Setup!$B$14,0)+IF(A10=Setup!$B$15,SUM($G$7:G10)*Setup!$B$16,0) | L10: =I10+J10+K10 | M10: =IF(A10-Setup!$B$10<1,0,INDEX($C$7:$C$30,A10-Setup!$B$10)) | N10: =SUM($M$7:M10) | O10: =SUM($L$7:L10) | P10: =O10-N10 | Q10: =SUM($G$7:G10)-SUM($K$7:K10) | R10: =IF(P10<0,-P10*Setup!$B$17/12,0) | S10: =MIN(P10,0) | T10: =MAX(P10,0)
A11: 5 | B11: =IF(OR(Setup!$B$19="",Setup!$B$19=0),"",EOMONTH(Setup!$B$19,A11-1)) | E11: =IF(D11<>"",D11,IF(SUM($C$7:$C$30)=0,0,C11*Setup!$B$7/SUM($C$7:$C$30))) | F11: =MAX(0,MIN(Setup!$B$11*Setup!$B$7-SUM($F$7:F10),E11*Setup!$B$12)) | G11: =E11*Setup!$B$8 | H11: =E11-G11-F11 | I11: =IF(A11-Setup!$B$9<1,0,INDEX($H$7:$H$30,A11-Setup!$B$9)) | J11: =IF(A11=1,Setup!$B$11*Setup!$B$7,0) | K11: =IF(A11=Setup!$B$13,SUM($G$7:G11)*Setup!$B$14,0)+IF(A11=Setup!$B$15,SUM($G$7:G11)*Setup!$B$16,0) | L11: =I11+J11+K11 | M11: =IF(A11-Setup!$B$10<1,0,INDEX($C$7:$C$30,A11-Setup!$B$10)) | N11: =SUM($M$7:M11) | O11: =SUM($L$7:L11) | P11: =O11-N11 | Q11: =SUM($G$7:G11)-SUM($K$7:K11) | R11: =IF(P11<0,-P11*Setup!$B$17/12,0) | S11: =MIN(P11,0) | T11: =MAX(P11,0)
A12: 6 | B12: =IF(OR(Setup!$B$19="",Setup!$B$19=0),"",EOMONTH(Setup!$B$19,A12-1)) | E12: =IF(D12<>"",D12,IF(SUM($C$7:$C$30)=0,0,C12*Setup!$B$7/SUM($C$7:$C$30))) | F12: =MAX(0,MIN(Setup!$B$11*Setup!$B$7-SUM($F$7:F11),E12*Setup!$B$12)) | G12: =E12*Setup!$B$8 | H12: =E12-G12-F12 | I12: =IF(A12-Setup!$B$9<1,0,INDEX($H$7:$H$30,A12-Setup!$B$9)) | J12: =IF(A12=1,Setup!$B$11*Setup!$B$7,0) | K12: =IF(A12=Setup!$B$13,SUM($G$7:G12)*Setup!$B$14,0)+IF(A12=Setup!$B$15,SUM($G$7:G12)*Setup!$B$16,0) | L12: =I12+J12+K12 | M12: =IF(A12-Setup!$B$10<1,0,INDEX($C$7:$C$30,A12-Setup!$B$10)) | N12: =SUM($M$7:M12) | O12: =SUM($L$7:L12) | P12: =O12-N12 | Q12: =SUM($G$7:G12)-SUM($K$7:K12) | R12: =IF(P12<0,-P12*Setup!$B$17/12,0) | S12: =MIN(P12,0) | T12: =MAX(P12,0)
A13: 7 | B13: =IF(OR(Setup!$B$19="",Setup!$B$19=0),"",EOMONTH(Setup!$B$19,A13-1)) | E13: =IF(D13<>"",D13,IF(SUM($C$7:$C$30)=0,0,C13*Setup!$B$7/SUM($C$7:$C$30))) | F13: =MAX(0,MIN(Setup!$B$11*Setup!$B$7-SUM($F$7:F12),E13*Setup!$B$12)) | G13: =E13*Setup!$B$8 | H13: =E13-G13-F13 | I13: =IF(A13-Setup!$B$9<1,0,INDEX($H$7:$H$30,A13-Setup!$B$9)) | J13: =IF(A13=1,Setup!$B$11*Setup!$B$7,0) | K13: =IF(A13=Setup!$B$13,SUM($G$7:G13)*Setup!$B$14,0)+IF(A13=Setup!$B$15,SUM($G$7:G13)*Setup!$B$16,0) | L13: =I13+J13+K13 | M13: =IF(A13-Setup!$B$10<1,0,INDEX($C$7:$C$30,A13-Setup!$B$10)) | N13: =SUM($M$7:M13) | O13: =SUM($L$7:L13) | P13: =O13-N13 | Q13: =SUM($G$7:G13)-SUM($K$7:K13) | R13: =IF(P13<0,-P13*Setup!$B$17/12,0) | S13: =MIN(P13,0) | T13: =MAX(P13,0)
A14: 8 | B14: =IF(OR(Setup!$B$19="",Setup!$B$19=0),"",EOMONTH(Setup!$B$19,A14-1)) | E14: =IF(D14<>"",D14,IF(SUM($C$7:$C$30)=0,0,C14*Setup!$B$7/SUM($C$7:$C$30))) | F14: =MAX(0,MIN(Setup!$B$11*Setup!$B$7-SUM($F$7:F13),E14*Setup!$B$12)) | G14: =E14*Setup!$B$8 | H14: =E14-G14-F14 | I14: =IF(A14-Setup!$B$9<1,0,INDEX($H$7:$H$30,A14-Setup!$B$9)) | J14: =IF(A14=1,Setup!$B$11*Setup!$B$7,0) | K14: =IF(A14=Setup!$B$13,SUM($G$7:G14)*Setup!$B$14,0)+IF(A14=Setup!$B$15,SUM($G$7:G14)*Setup!$B$16,0) | L14: =I14+J14+K14 | M14: =IF(A14-Setup!$B$10<1,0,INDEX($C$7:$C$30,A14-Setup!$B$10)) | N14: =SUM($M$7:M14) | O14: =SUM($L$7:L14) | P14: =O14-N14 | Q14: =SUM($G$7:G14)-SUM($K$7:K14) | R14: =IF(P14<0,-P14*Setup!$B$17/12,0) | S14: =MIN(P14,0) | T14: =MAX(P14,0)
A15: 9 | B15: =IF(OR(Setup!$B$19="",Setup!$B$19=0),"",EOMONTH(Setup!$B$19,A15-1)) | E15: =IF(D15<>"",D15,IF(SUM($C$7:$C$30)=0,0,C15*Setup!$B$7/SUM($C$7:$C$30))) | F15: =MAX(0,MIN(Setup!$B$11*Setup!$B$7-SUM($F$7:F14),E15*Setup!$B$12)) | G15: =E15*Setup!$B$8 | H15: =E15-G15-F15 | I15: =IF(A15-Setup!$B$9<1,0,INDEX($H$7:$H$30,A15-Setup!$B$9)) | J15: =IF(A15=1,Setup!$B$11*Setup!$B$7,0) | K15: =IF(A15=Setup!$B$13,SUM($G$7:G15)*Setup!$B$14,0)+IF(A15=Setup!$B$15,SUM($G$7:G15)*Setup!$B$16,0) | L15: =I15+J15+K15 | M15: =IF(A15-Setup!$B$10<1,0,INDEX($C$7:$C$30,A15-Setup!$B$10)) | N15: =SUM($M$7:M15) | O15: =SUM($L$7:L15) | P15: =O15-N15 | Q15: =SUM($G$7:G15)-SUM($K$7:K15) | R15: =IF(P15<0,-P15*Setup!$B$17/12,0) | S15: =MIN(P15,0) | T15: =MAX(P15,0)
A16: 10 | B16: =IF(OR(Setup!$B$19="",Setup!$B$19=0),"",EOMONTH(Setup!$B$19,A16-1)) | E16: =IF(D16<>"",D16,IF(SUM($C$7:$C$30)=0,0,C16*Setup!$B$7/SUM($C$7:$C$30))) | F16: =MAX(0,MIN(Setup!$B$11*Setup!$B$7-SUM($F$7:F15),E16*Setup!$B$12)) | G16: =E16*Setup!$B$8 | H16: =E16-G16-F16 | I16: =IF(A16-Setup!$B$9<1,0,INDEX($H$7:$H$30,A16-Setup!$B$9)) | J16: =IF(A16=1,Setup!$B$11*Setup!$B$7,0) | K16: =IF(A16=Setup!$B$13,SUM($G$7:G16)*Setup!$B$14,0)+IF(A16=Setup!$B$15,SUM($G$7:G16)*Setup!$B$16,0) | L16: =I16+J16+K16 | M16: =IF(A16-Setup!$B$10<1,0,INDEX($C$7:$C$30,A16-Setup!$B$10)) | N16: =SUM($M$7:M16) | O16: =SUM($L$7:L16) | P16: =O16-N16 | Q16: =SUM($G$7:G16)-SUM($K$7:K16) | R16: =IF(P16<0,-P16*Setup!$B$17/12,0) | S16: =MIN(P16,0) | T16: =MAX(P16,0)
A17: 11 | B17: =IF(OR(Setup!$B$19="",Setup!$B$19=0),"",EOMONTH(Setup!$B$19,A17-1)) | E17: =IF(D17<>"",D17,IF(SUM($C$7:$C$30)=0,0,C17*Setup!$B$7/SUM($C$7:$C$30))) | F17: =MAX(0,MIN(Setup!$B$11*Setup!$B$7-SUM($F$7:F16),E17*Setup!$B$12)) | G17: =E17*Setup!$B$8 | H17: =E17-G17-F17 | I17: =IF(A17-Setup!$B$9<1,0,INDEX($H$7:$H$30,A17-Setup!$B$9)) | J17: =IF(A17=1,Setup!$B$11*Setup!$B$7,0) | K17: =IF(A17=Setup!$B$13,SUM($G$7:G17)*Setup!$B$14,0)+IF(A17=Setup!$B$15,SUM($G$7:G17)*Setup!$B$16,0) | L17: =I17+J17+K17 | M17: =IF(A17-Setup!$B$10<1,0,INDEX($C$7:$C$30,A17-Setup!$B$10)) | N17: =SUM($M$7:M17) | O17: =SUM($L$7:L17) | P17: =O17-N17 | Q17: =SUM($G$7:G17)-SUM($K$7:K17) | R17: =IF(P17<0,-P17*Setup!$B$17/12,0) | S17: =MIN(P17,0) | T17: =MAX(P17,0)
A18: 12 | B18: =IF(OR(Setup!$B$19="",Setup!$B$19=0),"",EOMONTH(Setup!$B$19,A18-1)) | E18: =IF(D18<>"",D18,IF(SUM($C$7:$C$30)=0,0,C18*Setup!$B$7/SUM($C$7:$C$30))) | F18: =MAX(0,MIN(Setup!$B$11*Setup!$B$7-SUM($F$7:F17),E18*Setup!$B$12)) | G18: =E18*Setup!$B$8 | H18: =E18-G18-F18 | I18: =IF(A18-Setup!$B$9<1,0,INDEX($H$7:$H$30,A18-Setup!$B$9)) | J18: =IF(A18=1,Setup!$B$11*Setup!$B$7,0) | K18: =IF(A18=Setup!$B$13,SUM($G$7:G18)*Setup!$B$14,0)+IF(A18=Setup!$B$15,SUM($G$7:G18)*Setup!$B$16,0) | L18: =I18+J18+K18 | M18: =IF(A18-Setup!$B$10<1,0,INDEX($C$7:$C$30,A18-Setup!$B$10)) | N18: =SUM($M$7:M18) | O18: =SUM($L$7:L18) | P18: =O18-N18 | Q18: =SUM($G$7:G18)-SUM($K$7:K18) | R18: =IF(P18<0,-P18*Setup!$B$17/12,0) | S18: =MIN(P18,0) | T18: =MAX(P18,0)
A19: 13 | B19: =IF(OR(Setup!$B$19="",Setup!$B$19=0),"",EOMONTH(Setup!$B$19,A19-1)) | E19: =IF(D19<>"",D19,IF(SUM($C$7:$C$30)=0,0,C19*Setup!$B$7/SUM($C$7:$C$30))) | F19: =MAX(0,MIN(Setup!$B$11*Setup!$B$7-SUM($F$7:F18),E19*Setup!$B$12)) | G19: =E19*Setup!$B$8 | H19: =E19-G19-F19 | I19: =IF(A19-Setup!$B$9<1,0,INDEX($H$7:$H$30,A19-Setup!$B$9)) | J19: =IF(A19=1,Setup!$B$11*Setup!$B$7,0) | K19: =IF(A19=Setup!$B$13,SUM($G$7:G19)*Setup!$B$14,0)+IF(A19=Setup!$B$15,SUM($G$7:G19)*Setup!$B$16,0) | L19: =I19+J19+K19 | M19: =IF(A19-Setup!$B$10<1,0,INDEX($C$7:$C$30,A19-Setup!$B$10)) | N19: =SUM($M$7:M19) | O19: =SUM($L$7:L19) | P19: =O19-N19 | Q19: =SUM($G$7:G19)-SUM($K$7:K19) | R19: =IF(P19<0,-P19*Setup!$B$17/12,0) | S19: =MIN(P19,0) | T19: =MAX(P19,0)
... A30: 24 | B30: =IF(OR(Setup!$B$19="",Setup!$B$19=0),"",EOMONTH(Setup!$B$19,A30-1)) | E30: =IF(D30<>"",D30,IF(SUM($C$7:$C$30)=0,0,C30*Setup!$B$7/SUM($C$7:$C$30))) | F30: =MAX(0,MIN(Setup!$B$11*Setup!$B$7-SUM($F$7:F29),E30*Setup!$B$12)) | G30: =E30*Setup!$B$8 | H30: =E30-G30-F30 | I30: =IF(A30-Setup!$B$9<1,0,INDEX($H$7:$H$30,A30-Setup!$B$9)) | J30: =IF(A30=1,Setup!$B$11*Setup!$B$7,0) | K30: =IF(A30=Setup!$B$13,SUM($G$7:G30)*Setup!$B$14,0)+IF(A30=Setup!$B$15,SUM($G$7:G30)*Setup!$B$16,0) | L30: =I30+J30+K30 | M30: =IF(A30-Setup!$B$10<1,0,INDEX($C$7:$C$30,A30-Setup!$B$10)) | N30: =SUM($M$7:M30) | O30: =SUM($L$7:L30) | P30: =O30-N30 | Q30: =SUM($G$7:G30)-SUM($K$7:K30) | R30: =IF(P30<0,-P30*Setup!$B$17/12,0) | S30: =MIN(P30,0) | T30: =MAX(P30,0)
A32: RESULTS
A33: Total cost ($) | D33: =SUM(C7:C30)
A34: Contract value ($) | D34: =Setup!$B$7
A35: Profit at the end ($) | D35: =D34-D33
A36: Deepest cash position ($) | D36: =MIN(P7:P30)
A37: Month of the deepest point | D37: =IF(D36>=0,"",INDEX(A7:A30,MATCH(D36,P7:P30,0)))
A38: Months with the cash position below zero | D38: =COUNTIF(P7:P30,"<0")
A39: Cost of the hole, rule of thumb ($) | D39: =IF(D36>=0,0,-D36*Setup!$B$17*D38/12)
A40: Cost of the hole, month by month ($) | D40: =SUM(R7:R30)
A41: Money in by month 24 ($) | D41: =O30
A42: Retention still held ($) | D42: =Q30
A43: Headroom on the overdraft facility ($) | D43: =IF(Setup!$B$18="","",Setup!$B$18+MIN(0,D36))

Sheet What if
A1: What if | Y1: The Project Control Hub
A2: The same job with different terms. The profit does not move; the hole does.
A3: Change any yellow term in the right-hand panel (column X). The costs come from the Cash flow sheet.
W5: TERMS FOR THIS SCENARIO
A6: Month | B6: Month end | C6: Cost incurred ($) | D6: Valuation override ($) | E6: Value of work ($) | F6: Advance recovered ($) | G6: Retention deducted ($) | H6: Net certificate ($) | I6: Certificates paid ($) | J6: Advance received ($) | K6: Retention released ($) | L6: Money in ($) | M6: Money out ($) | N6: Cumulative out ($) | O6: Cumulative in ($) | P6: Cash position ($) | Q6: Retention held ($) | R6: Interest this month ($) | S6: Below zero (chart) | T6: Above zero (chart) | W6: Each starts equal to Setup. Type over it to test a lever.
A7: 1 | B7: =IF(OR($X$19="",$X$19=0),"",EOMONTH($X$19,A7-1)) | C7: ='Cash flow'!C7 | E7: =IF(D7<>"",D7,IF(SUM($C$7:$C$30)=0,0,C7*$X$7/SUM($C$7:$C$30))) | F7: =MAX(0,MIN($X$11*$X$7-0,E7*$X$12)) | G7: =E7*$X$8 | H7: =E7-G7-F7 | I7: =IF(A7-$X$9<1,0,INDEX($H$7:$H$30,A7-$X$9)) | J7: =IF(A7=1,$X$11*$X$7,0) | K7: =IF(A7=$X$13,SUM($G$7:G7)*$X$14,0)+IF(A7=$X$15,SUM($G$7:G7)*$X$16,0) | L7: =I7+J7+K7 | M7: =IF(A7-$X$10<1,0,INDEX($C$7:$C$30,A7-$X$10)) | N7: =SUM($M$7:M7) | O7: =SUM($L$7:L7) | P7: =O7-N7 | Q7: =SUM($G$7:G7)-SUM($K$7:K7) | R7: =IF(P7<0,-P7*$X$17/12,0) | S7: =MIN(P7,0) | T7: =MAX(P7,0) | W7: Contract value ($) | X7: =Setup!$B$7
A8: 2 | B8: =IF(OR($X$19="",$X$19=0),"",EOMONTH($X$19,A8-1)) | C8: ='Cash flow'!C8 | E8: =IF(D8<>"",D8,IF(SUM($C$7:$C$30)=0,0,C8*$X$7/SUM($C$7:$C$30))) | F8: =MAX(0,MIN($X$11*$X$7-SUM($F$7:F7),E8*$X$12)) | G8: =E8*$X$8 | H8: =E8-G8-F8 | I8: =IF(A8-$X$9<1,0,INDEX($H$7:$H$30,A8-$X$9)) | J8: =IF(A8=1,$X$11*$X$7,0) | K8: =IF(A8=$X$13,SUM($G$7:G8)*$X$14,0)+IF(A8=$X$15,SUM($G$7:G8)*$X$16,0) | L8: =I8+J8+K8 | M8: =IF(A8-$X$10<1,0,INDEX($C$7:$C$30,A8-$X$10)) | N8: =SUM($M$7:M8) | O8: =SUM($L$7:L8) | P8: =O8-N8 | Q8: =SUM($G$7:G8)-SUM($K$7:K8) | R8: =IF(P8<0,-P8*$X$17/12,0) | S8: =MIN(P8,0) | T8: =MAX(P8,0) | W8: Retention held on each certificate | X8: =Setup!$B$8
A9: 3 | B9: =IF(OR($X$19="",$X$19=0),"",EOMONTH($X$19,A9-1)) | C9: ='Cash flow'!C9 | E9: =IF(D9<>"",D9,IF(SUM($C$7:$C$30)=0,0,C9*$X$7/SUM($C$7:$C$30))) | F9: =MAX(0,MIN($X$11*$X$7-SUM($F$7:F8),E9*$X$12)) | G9: =E9*$X$8 | H9: =E9-G9-F9 | I9: =IF(A9-$X$9<1,0,INDEX($H$7:$H$30,A9-$X$9)) | J9: =IF(A9=1,$X$11*$X$7,0) | K9: =IF(A9=$X$13,SUM($G$7:G9)*$X$14,0)+IF(A9=$X$15,SUM($G$7:G9)*$X$16,0) | L9: =I9+J9+K9 | M9: =IF(A9-$X$10<1,0,INDEX($C$7:$C$30,A9-$X$10)) | N9: =SUM($M$7:M9) | O9: =SUM($L$7:L9) | P9: =O9-N9 | Q9: =SUM($G$7:G9)-SUM($K$7:K9) | R9: =IF(P9<0,-P9*$X$17/12,0) | S9: =MIN(P9,0) | T9: =MAX(P9,0) | W9: Months from doing the work to being paid | X9: =Setup!$B$9
A10: 4 | B10: =IF(OR($X$19="",$X$19=0),"",EOMONTH($X$19,A10-1)) | C10: ='Cash flow'!C10 | E10: =IF(D10<>"",D10,IF(SUM($C$7:$C$30)=0,0,C10*$X$7/SUM($C$7:$C$30))) | F10: =MAX(0,MIN($X$11*$X$7-SUM($F$7:F9),E10*$X$12)) | G10: =E10*$X$8 | H10: =E10-G10-F10 | I10: =IF(A10-$X$9<1,0,INDEX($H$7:$H$30,A10-$X$9)) | J10: =IF(A10=1,$X$11*$X$7,0) | K10: =IF(A10=$X$13,SUM($G$7:G10)*$X$14,0)+IF(A10=$X$15,SUM($G$7:G10)*$X$16,0) | L10: =I10+J10+K10 | M10: =IF(A10-$X$10<1,0,INDEX($C$7:$C$30,A10-$X$10)) | N10: =SUM($M$7:M10) | O10: =SUM($L$7:L10) | P10: =O10-N10 | Q10: =SUM($G$7:G10)-SUM($K$7:K10) | R10: =IF(P10<0,-P10*$X$17/12,0) | S10: =MIN(P10,0) | T10: =MAX(P10,0) | W10: Months of credit from suppliers | X10: =Setup!$B$10
A11: 5 | B11: =IF(OR($X$19="",$X$19=0),"",EOMONTH($X$19,A11-1)) | C11: ='Cash flow'!C11 | E11: =IF(D11<>"",D11,IF(SUM($C$7:$C$30)=0,0,C11*$X$7/SUM($C$7:$C$30))) | F11: =MAX(0,MIN($X$11*$X$7-SUM($F$7:F10),E11*$X$12)) | G11: =E11*$X$8 | H11: =E11-G11-F11 | I11: =IF(A11-$X$9<1,0,INDEX($H$7:$H$30,A11-$X$9)) | J11: =IF(A11=1,$X$11*$X$7,0) | K11: =IF(A11=$X$13,SUM($G$7:G11)*$X$14,0)+IF(A11=$X$15,SUM($G$7:G11)*$X$16,0) | L11: =I11+J11+K11 | M11: =IF(A11-$X$10<1,0,INDEX($C$7:$C$30,A11-$X$10)) | N11: =SUM($M$7:M11) | O11: =SUM($L$7:L11) | P11: =O11-N11 | Q11: =SUM($G$7:G11)-SUM($K$7:K11) | R11: =IF(P11<0,-P11*$X$17/12,0) | S11: =MIN(P11,0) | T11: =MAX(P11,0) | W11: Mobilisation advance (% of contract) | X11: =Setup!$B$11
A12: 6 | B12: =IF(OR($X$19="",$X$19=0),"",EOMONTH($X$19,A12-1)) | C12: ='Cash flow'!C12 | E12: =IF(D12<>"",D12,IF(SUM($C$7:$C$30)=0,0,C12*$X$7/SUM($C$7:$C$30))) | F12: =MAX(0,MIN($X$11*$X$7-SUM($F$7:F11),E12*$X$12)) | G12: =E12*$X$8 | H12: =E12-G12-F12 | I12: =IF(A12-$X$9<1,0,INDEX($H$7:$H$30,A12-$X$9)) | J12: =IF(A12=1,$X$11*$X$7,0) | K12: =IF(A12=$X$13,SUM($G$7:G12)*$X$14,0)+IF(A12=$X$15,SUM($G$7:G12)*$X$16,0) | L12: =I12+J12+K12 | M12: =IF(A12-$X$10<1,0,INDEX($C$7:$C$30,A12-$X$10)) | N12: =SUM($M$7:M12) | O12: =SUM($L$7:L12) | P12: =O12-N12 | Q12: =SUM($G$7:G12)-SUM($K$7:K12) | R12: =IF(P12<0,-P12*$X$17/12,0) | S12: =MIN(P12,0) | T12: =MAX(P12,0) | W12: Advance recovered from each certificate (%) | X12: =Setup!$B$12
A13: 7 | B13: =IF(OR($X$19="",$X$19=0),"",EOMONTH($X$19,A13-1)) | C13: ='Cash flow'!C13 | E13: =IF(D13<>"",D13,IF(SUM($C$7:$C$30)=0,0,C13*$X$7/SUM($C$7:$C$30))) | F13: =MAX(0,MIN($X$11*$X$7-SUM($F$7:F12),E13*$X$12)) | G13: =E13*$X$8 | H13: =E13-G13-F13 | I13: =IF(A13-$X$9<1,0,INDEX($H$7:$H$30,A13-$X$9)) | J13: =IF(A13=1,$X$11*$X$7,0) | K13: =IF(A13=$X$13,SUM($G$7:G13)*$X$14,0)+IF(A13=$X$15,SUM($G$7:G13)*$X$16,0) | L13: =I13+J13+K13 | M13: =IF(A13-$X$10<1,0,INDEX($C$7:$C$30,A13-$X$10)) | N13: =SUM($M$7:M13) | O13: =SUM($L$7:L13) | P13: =O13-N13 | Q13: =SUM($G$7:G13)-SUM($K$7:K13) | R13: =IF(P13<0,-P13*$X$17/12,0) | S13: =MIN(P13,0) | T13: =MAX(P13,0) | W13: First retention release: month | X13: =Setup!$B$13
A14: 8 | B14: =IF(OR($X$19="",$X$19=0),"",EOMONTH($X$19,A14-1)) | C14: ='Cash flow'!C14 | E14: =IF(D14<>"",D14,IF(SUM($C$7:$C$30)=0,0,C14*$X$7/SUM($C$7:$C$30))) | F14: =MAX(0,MIN($X$11*$X$7-SUM($F$7:F13),E14*$X$12)) | G14: =E14*$X$8 | H14: =E14-G14-F14 | I14: =IF(A14-$X$9<1,0,INDEX($H$7:$H$30,A14-$X$9)) | J14: =IF(A14=1,$X$11*$X$7,0) | K14: =IF(A14=$X$13,SUM($G$7:G14)*$X$14,0)+IF(A14=$X$15,SUM($G$7:G14)*$X$16,0) | L14: =I14+J14+K14 | M14: =IF(A14-$X$10<1,0,INDEX($C$7:$C$30,A14-$X$10)) | N14: =SUM($M$7:M14) | O14: =SUM($L$7:L14) | P14: =O14-N14 | Q14: =SUM($G$7:G14)-SUM($K$7:K14) | R14: =IF(P14<0,-P14*$X$17/12,0) | S14: =MIN(P14,0) | T14: =MAX(P14,0) | W14: First release: share of retention | X14: =Setup!$B$14
A15: 9 | B15: =IF(OR($X$19="",$X$19=0),"",EOMONTH($X$19,A15-1)) | C15: ='Cash flow'!C15 | E15: =IF(D15<>"",D15,IF(SUM($C$7:$C$30)=0,0,C15*$X$7/SUM($C$7:$C$30))) | F15: =MAX(0,MIN($X$11*$X$7-SUM($F$7:F14),E15*$X$12)) | G15: =E15*$X$8 | H15: =E15-G15-F15 | I15: =IF(A15-$X$9<1,0,INDEX($H$7:$H$30,A15-$X$9)) | J15: =IF(A15=1,$X$11*$X$7,0) | K15: =IF(A15=$X$13,SUM($G$7:G15)*$X$14,0)+IF(A15=$X$15,SUM($G$7:G15)*$X$16,0) | L15: =I15+J15+K15 | M15: =IF(A15-$X$10<1,0,INDEX($C$7:$C$30,A15-$X$10)) | N15: =SUM($M$7:M15) | O15: =SUM($L$7:L15) | P15: =O15-N15 | Q15: =SUM($G$7:G15)-SUM($K$7:K15) | R15: =IF(P15<0,-P15*$X$17/12,0) | S15: =MIN(P15,0) | T15: =MAX(P15,0) | W15: Second retention release: month | X15: =Setup!$B$15
A16: 10 | B16: =IF(OR($X$19="",$X$19=0),"",EOMONTH($X$19,A16-1)) | C16: ='Cash flow'!C16 | E16: =IF(D16<>"",D16,IF(SUM($C$7:$C$30)=0,0,C16*$X$7/SUM($C$7:$C$30))) | F16: =MAX(0,MIN($X$11*$X$7-SUM($F$7:F15),E16*$X$12)) | G16: =E16*$X$8 | H16: =E16-G16-F16 | I16: =IF(A16-$X$9<1,0,INDEX($H$7:$H$30,A16-$X$9)) | J16: =IF(A16=1,$X$11*$X$7,0) | K16: =IF(A16=$X$13,SUM($G$7:G16)*$X$14,0)+IF(A16=$X$15,SUM($G$7:G16)*$X$16,0) | L16: =I16+J16+K16 | M16: =IF(A16-$X$10<1,0,INDEX($C$7:$C$30,A16-$X$10)) | N16: =SUM($M$7:M16) | O16: =SUM($L$7:L16) | P16: =O16-N16 | Q16: =SUM($G$7:G16)-SUM($K$7:K16) | R16: =IF(P16<0,-P16*$X$17/12,0) | S16: =MIN(P16,0) | T16: =MAX(P16,0) | W16: Second release: share of retention | X16: =Setup!$B$16
A17: 11 | B17: =IF(OR($X$19="",$X$19=0),"",EOMONTH($X$19,A17-1)) | C17: ='Cash flow'!C17 | E17: =IF(D17<>"",D17,IF(SUM($C$7:$C$30)=0,0,C17*$X$7/SUM($C$7:$C$30))) | F17: =MAX(0,MIN($X$11*$X$7-SUM($F$7:F16),E17*$X$12)) | G17: =E17*$X$8 | H17: =E17-G17-F17 | I17: =IF(A17-$X$9<1,0,INDEX($H$7:$H$30,A17-$X$9)) | J17: =IF(A17=1,$X$11*$X$7,0) | K17: =IF(A17=$X$13,SUM($G$7:G17)*$X$14,0)+IF(A17=$X$15,SUM($G$7:G17)*$X$16,0) | L17: =I17+J17+K17 | M17: =IF(A17-$X$10<1,0,INDEX($C$7:$C$30,A17-$X$10)) | N17: =SUM($M$7:M17) | O17: =SUM($L$7:L17) | P17: =O17-N17 | Q17: =SUM($G$7:G17)-SUM($K$7:K17) | R17: =IF(P17<0,-P17*$X$17/12,0) | S17: =MIN(P17,0) | T17: =MAX(P17,0) | W17: Overdraft interest rate (per year) | X17: =Setup!$B$17
A18: 12 | B18: =IF(OR($X$19="",$X$19=0),"",EOMONTH($X$19,A18-1)) | C18: ='Cash flow'!C18 | E18: =IF(D18<>"",D18,IF(SUM($C$7:$C$30)=0,0,C18*$X$7/SUM($C$7:$C$30))) | F18: =MAX(0,MIN($X$11*$X$7-SUM($F$7:F17),E18*$X$12)) | G18: =E18*$X$8 | H18: =E18-G18-F18 | I18: =IF(A18-$X$9<1,0,INDEX($H$7:$H$30,A18-$X$9)) | J18: =IF(A18=1,$X$11*$X$7,0) | K18: =IF(A18=$X$13,SUM($G$7:G18)*$X$14,0)+IF(A18=$X$15,SUM($G$7:G18)*$X$16,0) | L18: =I18+J18+K18 | M18: =IF(A18-$X$10<1,0,INDEX($C$7:$C$30,A18-$X$10)) | N18: =SUM($M$7:M18) | O18: =SUM($L$7:L18) | P18: =O18-N18 | Q18: =SUM($G$7:G18)-SUM($K$7:K18) | R18: =IF(P18<0,-P18*$X$17/12,0) | S18: =MIN(P18,0) | T18: =MAX(P18,0) | W18: Overdraft facility ($) | X18: =Setup!$B$18
A19: 13 | B19: =IF(OR($X$19="",$X$19=0),"",EOMONTH($X$19,A19-1)) | C19: ='Cash flow'!C19 | E19: =IF(D19<>"",D19,IF(SUM($C$7:$C$30)=0,0,C19*$X$7/SUM($C$7:$C$30))) | F19: =MAX(0,MIN($X$11*$X$7-SUM($F$7:F18),E19*$X$12)) | G19: =E19*$X$8 | H19: =E19-G19-F19 | I19: =IF(A19-$X$9<1,0,INDEX($H$7:$H$30,A19-$X$9)) | J19: =IF(A19=1,$X$11*$X$7,0) | K19: =IF(A19=$X$13,SUM($G$7:G19)*$X$14,0)+IF(A19=$X$15,SUM($G$7:G19)*$X$16,0) | L19: =I19+J19+K19 | M19: =IF(A19-$X$10<1,0,INDEX($C$7:$C$30,A19-$X$10)) | N19: =SUM($M$7:M19) | O19: =SUM($L$7:L19) | P19: =O19-N19 | Q19: =SUM($G$7:G19)-SUM($K$7:K19) | R19: =IF(P19<0,-P19*$X$17/12,0) | S19: =MIN(P19,0) | T19: =MAX(P19,0) | W19: Month 1 ends on | X19: =Setup!$B$19
A20: 14 | B20: =IF(OR($X$19="",$X$19=0),"",EOMONTH($X$19,A20-1)) | C20: ='Cash flow'!C20 | E20: =IF(D20<>"",D20,IF(SUM($C$7:$C$30)=0,0,C20*$X$7/SUM($C$7:$C$30))) | F20: =MAX(0,MIN($X$11*$X$7-SUM($F$7:F19),E20*$X$12)) | G20: =E20*$X$8 | H20: =E20-G20-F20 | I20: =IF(A20-$X$9<1,0,INDEX($H$7:$H$30,A20-$X$9)) | J20: =IF(A20=1,$X$11*$X$7,0) | K20: =IF(A20=$X$13,SUM($G$7:G20)*$X$14,0)+IF(A20=$X$15,SUM($G$7:G20)*$X$16,0) | L20: =I20+J20+K20 | M20: =IF(A20-$X$10<1,0,INDEX($C$7:$C$30,A20-$X$10)) | N20: =SUM($M$7:M20) | O20: =SUM($L$7:L20) | P20: =O20-N20 | Q20: =SUM($G$7:G20)-SUM($K$7:K20) | R20: =IF(P20<0,-P20*$X$17/12,0) | S20: =MIN(P20,0) | T20: =MAX(P20,0)
A21: 15 | B21: =IF(OR($X$19="",$X$19=0),"",EOMONTH($X$19,A21-1)) | C21: ='Cash flow'!C21 | E21: =IF(D21<>"",D21,IF(SUM($C$7:$C$30)=0,0,C21*$X$7/SUM($C$7:$C$30))) | F21: =MAX(0,MIN($X$11*$X$7-SUM($F$7:F20),E21*$X$12)) | G21: =E21*$X$8 | H21: =E21-G21-F21 | I21: =IF(A21-$X$9<1,0,INDEX($H$7:$H$30,A21-$X$9)) | J21: =IF(A21=1,$X$11*$X$7,0) | K21: =IF(A21=$X$13,SUM($G$7:G21)*$X$14,0)+IF(A21=$X$15,SUM($G$7:G21)*$X$16,0) | L21: =I21+J21+K21 | M21: =IF(A21-$X$10<1,0,INDEX($C$7:$C$30,A21-$X$10)) | N21: =SUM($M$7:M21) | O21: =SUM($L$7:L21) | P21: =O21-N21 | Q21: =SUM($G$7:G21)-SUM($K$7:K21) | R21: =IF(P21<0,-P21*$X$17/12,0) | S21: =MIN(P21,0) | T21: =MAX(P21,0)
A22: 16 | B22: =IF(OR($X$19="",$X$19=0),"",EOMONTH($X$19,A22-1)) | C22: ='Cash flow'!C22 | E22: =IF(D22<>"",D22,IF(SUM($C$7:$C$30)=0,0,C22*$X$7/SUM($C$7:$C$30))) | F22: =MAX(0,MIN($X$11*$X$7-SUM($F$7:F21),E22*$X$12)) | G22: =E22*$X$8 | H22: =E22-G22-F22 | I22: =IF(A22-$X$9<1,0,INDEX($H$7:$H$30,A22-$X$9)) | J22: =IF(A22=1,$X$11*$X$7,0) | K22: =IF(A22=$X$13,SUM($G$7:G22)*$X$14,0)+IF(A22=$X$15,SUM($G$7:G22)*$X$16,0) | L22: =I22+J22+K22 | M22: =IF(A22-$X$10<1,0,INDEX($C$7:$C$30,A22-$X$10)) | N22: =SUM($M$7:M22) | O22: =SUM($L$7:L22) | P22: =O22-N22 | Q22: =SUM($G$7:G22)-SUM($K$7:K22) | R22: =IF(P22<0,-P22*$X$17/12,0) | S22: =MIN(P22,0) | T22: =MAX(P22,0) | W22: BASE AGAINST THIS SCENARIO
A23: 17 | B23: =IF(OR($X$19="",$X$19=0),"",EOMONTH($X$19,A23-1)) | C23: ='Cash flow'!C23 | E23: =IF(D23<>"",D23,IF(SUM($C$7:$C$30)=0,0,C23*$X$7/SUM($C$7:$C$30))) | F23: =MAX(0,MIN($X$11*$X$7-SUM($F$7:F22),E23*$X$12)) | G23: =E23*$X$8 | H23: =E23-G23-F23 | I23: =IF(A23-$X$9<1,0,INDEX($H$7:$H$30,A23-$X$9)) | J23: =IF(A23=1,$X$11*$X$7,0) | K23: =IF(A23=$X$13,SUM($G$7:G23)*$X$14,0)+IF(A23=$X$15,SUM($G$7:G23)*$X$16,0) | L23: =I23+J23+K23 | M23: =IF(A23-$X$10<1,0,INDEX($C$7:$C$30,A23-$X$10)) | N23: =SUM($M$7:M23) | O23: =SUM($L$7:L23) | P23: =O23-N23 | Q23: =SUM($G$7:G23)-SUM($K$7:K23) | R23: =IF(P23<0,-P23*$X$17/12,0) | S23: =MIN(P23,0) | T23: =MAX(P23,0) | X23: Base | Y23: Scenario
A24: 18 | B24: =IF(OR($X$19="",$X$19=0),"",EOMONTH($X$19,A24-1)) | C24: ='Cash flow'!C24 | E24: =IF(D24<>"",D24,IF(SUM($C$7:$C$30)=0,0,C24*$X$7/SUM($C$7:$C$30))) | F24: =MAX(0,MIN($X$11*$X$7-SUM($F$7:F23),E24*$X$12)) | G24: =E24*$X$8 | H24: =E24-G24-F24 | I24: =IF(A24-$X$9<1,0,INDEX($H$7:$H$30,A24-$X$9)) | J24: =IF(A24=1,$X$11*$X$7,0) | K24: =IF(A24=$X$13,SUM($G$7:G24)*$X$14,0)+IF(A24=$X$15,SUM($G$7:G24)*$X$16,0) | L24: =I24+J24+K24 | M24: =IF(A24-$X$10<1,0,INDEX($C$7:$C$30,A24-$X$10)) | N24: =SUM($M$7:M24) | O24: =SUM($L$7:L24) | P24: =O24-N24 | Q24: =SUM($G$7:G24)-SUM($K$7:K24) | R24: =IF(P24<0,-P24*$X$17/12,0) | S24: =MIN(P24,0) | T24: =MAX(P24,0) | W24: Deepest cash position ($) | X24: ='Cash flow'!D36 | Y24: =D36
A25: 19 | B25: =IF(OR($X$19="",$X$19=0),"",EOMONTH($X$19,A25-1)) | C25: ='Cash flow'!C25 | E25: =IF(D25<>"",D25,IF(SUM($C$7:$C$30)=0,0,C25*$X$7/SUM($C$7:$C$30))) | F25: =MAX(0,MIN($X$11*$X$7-SUM($F$7:F24),E25*$X$12)) | G25: =E25*$X$8 | H25: =E25-G25-F25 | I25: =IF(A25-$X$9<1,0,INDEX($H$7:$H$30,A25-$X$9)) | J25: =IF(A25=1,$X$11*$X$7,0) | K25: =IF(A25=$X$13,SUM($G$7:G25)*$X$14,0)+IF(A25=$X$15,SUM($G$7:G25)*$X$16,0) | L25: =I25+J25+K25 | M25: =IF(A25-$X$10<1,0,INDEX($C$7:$C$30,A25-$X$10)) | N25: =SUM($M$7:M25) | O25: =SUM($L$7:L25) | P25: =O25-N25 | Q25: =SUM($G$7:G25)-SUM($K$7:K25) | R25: =IF(P25<0,-P25*$X$17/12,0) | S25: =MIN(P25,0) | T25: =MAX(P25,0) | W25: Month of the deepest point | X25: ='Cash flow'!D37 | Y25: =D37
A26: 20 | B26: =IF(OR($X$19="",$X$19=0),"",EOMONTH($X$19,A26-1)) | C26: ='Cash flow'!C26 | E26: =IF(D26<>"",D26,IF(SUM($C$7:$C$30)=0,0,C26*$X$7/SUM($C$7:$C$30))) | F26: =MAX(0,MIN($X$11*$X$7-SUM($F$7:F25),E26*$X$12)) | G26: =E26*$X$8 | H26: =E26-G26-F26 | I26: =IF(A26-$X$9<1,0,INDEX($H$7:$H$30,A26-$X$9)) | J26: =IF(A26=1,$X$11*$X$7,0) | K26: =IF(A26=$X$13,SUM($G$7:G26)*$X$14,0)+IF(A26=$X$15,SUM($G$7:G26)*$X$16,0) | L26: =I26+J26+K26 | M26: =IF(A26-$X$10<1,0,INDEX($C$7:$C$30,A26-$X$10)) | N26: =SUM($M$7:M26) | O26: =SUM($L$7:L26) | P26: =O26-N26 | Q26: =SUM($G$7:G26)-SUM($K$7:K26) | R26: =IF(P26<0,-P26*$X$17/12,0) | S26: =MIN(P26,0) | T26: =MAX(P26,0) | W26: Months below zero | X26: ='Cash flow'!D38 | Y26: =D38
A27: 21 | B27: =IF(OR($X$19="",$X$19=0),"",EOMONTH($X$19,A27-1)) | C27: ='Cash flow'!C27 | E27: =IF(D27<>"",D27,IF(SUM($C$7:$C$30)=0,0,C27*$X$7/SUM($C$7:$C$30))) | F27: =MAX(0,MIN($X$11*$X$7-SUM($F$7:F26),E27*$X$12)) | G27: =E27*$X$8 | H27: =E27-G27-F27 | I27: =IF(A27-$X$9<1,0,INDEX($H$7:$H$30,A27-$X$9)) | J27: =IF(A27=1,$X$11*$X$7,0) | K27: =IF(A27=$X$13,SUM($G$7:G27)*$X$14,0)+IF(A27=$X$15,SUM($G$7:G27)*$X$16,0) | L27: =I27+J27+K27 | M27: =IF(A27-$X$10<1,0,INDEX($C$7:$C$30,A27-$X$10)) | N27: =SUM($M$7:M27) | O27: =SUM($L$7:L27) | P27: =O27-N27 | Q27: =SUM($G$7:G27)-SUM($K$7:K27) | R27: =IF(P27<0,-P27*$X$17/12,0) | S27: =MIN(P27,0) | T27: =MAX(P27,0) | W27: Cost of the hole, month by month ($) | X27: ='Cash flow'!D40 | Y27: =D40
A28: 22 | B28: =IF(OR($X$19="",$X$19=0),"",EOMONTH($X$19,A28-1)) | C28: ='Cash flow'!C28 | E28: =IF(D28<>"",D28,IF(SUM($C$7:$C$30)=0,0,C28*$X$7/SUM($C$7:$C$30))) | F28: =MAX(0,MIN($X$11*$X$7-SUM($F$7:F27),E28*$X$12)) | G28: =E28*$X$8 | H28: =E28-G28-F28 | I28: =IF(A28-$X$9<1,0,INDEX($H$7:$H$30,A28-$X$9)) | J28: =IF(A28=1,$X$11*$X$7,0) | K28: =IF(A28=$X$13,SUM($G$7:G28)*$X$14,0)+IF(A28=$X$15,SUM($G$7:G28)*$X$16,0) | L28: =I28+J28+K28 | M28: =IF(A28-$X$10<1,0,INDEX($C$7:$C$30,A28-$X$10)) | N28: =SUM($M$7:M28) | O28: =SUM($L$7:L28) | P28: =O28-N28 | Q28: =SUM($G$7:G28)-SUM($K$7:K28) | R28: =IF(P28<0,-P28*$X$17/12,0) | S28: =MIN(P28,0) | T28: =MAX(P28,0) | W28: Profit at the end ($) | X28: ='Cash flow'!D35 | Y28: =D35
A29: 23 | B29: =IF(OR($X$19="",$X$19=0),"",EOMONTH($X$19,A29-1)) | C29: ='Cash flow'!C29 | E29: =IF(D29<>"",D29,IF(SUM($C$7:$C$30)=0,0,C29*$X$7/SUM($C$7:$C$30))) | F29: =MAX(0,MIN($X$11*$X$7-SUM($F$7:F28),E29*$X$12)) | G29: =E29*$X$8 | H29: =E29-G29-F29 | I29: =IF(A29-$X$9<1,0,INDEX($H$7:$H$30,A29-$X$9)) | J29: =IF(A29=1,$X$11*$X$7,0) | K29: =IF(A29=$X$13,SUM($G$7:G29)*$X$14,0)+IF(A29=$X$15,SUM($G$7:G29)*$X$16,0) | L29: =I29+J29+K29 | M29: =IF(A29-$X$10<1,0,INDEX($C$7:$C$30,A29-$X$10)) | N29: =SUM($M$7:M29) | O29: =SUM($L$7:L29) | P29: =O29-N29 | Q29: =SUM($G$7:G29)-SUM($K$7:K29) | R29: =IF(P29<0,-P29*$X$17/12,0) | S29: =MIN(P29,0) | T29: =MAX(P29,0)
A30: 24 | B30: =IF(OR($X$19="",$X$19=0),"",EOMONTH($X$19,A30-1)) | C30: ='Cash flow'!C30 | E30: =IF(D30<>"",D30,IF(SUM($C$7:$C$30)=0,0,C30*$X$7/SUM($C$7:$C$30))) | F30: =MAX(0,MIN($X$11*$X$7-SUM($F$7:F29),E30*$X$12)) | G30: =E30*$X$8 | H30: =E30-G30-F30 | I30: =IF(A30-$X$9<1,0,INDEX($H$7:$H$30,A30-$X$9)) | J30: =IF(A30=1,$X$11*$X$7,0) | K30: =IF(A30=$X$13,SUM($G$7:G30)*$X$14,0)+IF(A30=$X$15,SUM($G$7:G30)*$X$16,0) | L30: =I30+J30+K30 | M30: =IF(A30-$X$10<1,0,INDEX($C$7:$C$30,A30-$X$10)) | N30: =SUM($M$7:M30) | O30: =SUM($L$7:L30) | P30: =O30-N30 | Q30: =SUM($G$7:G30)-SUM($K$7:K30) | R30: =IF(P30<0,-P30*$X$17/12,0) | S30: =MIN(P30,0) | T30: =MAX(P30,0) | W30: Topic 19 on the same job: front-loading took the hole from -$60,462 to about -$20,462, faster certification to about -$8k, and a 10% advance to a surplus of about $30k. Not one of them earned a dollar more.
A32: RESULTS
A33: Total cost ($) | D33: =SUM(C7:C30)
A34: Contract value ($) | D34: =$X$7
A35: Profit at the end ($) | D35: =D34-D33
A36: Deepest cash position ($) | D36: =MIN(P7:P30)
A37: Month of the deepest point | D37: =IF(D36>=0,"",INDEX(A7:A30,MATCH(D36,P7:P30,0)))
A38: Months with the cash position below zero | D38: =COUNTIF(P7:P30,"<0")
A39: Cost of the hole, rule of thumb ($) | D39: =IF(D36>=0,0,-D36*$X$17*D38/12)
A40: Cost of the hole, month by month ($) | D40: =SUM(R7:R30)
A41: Money in by month 24 ($) | D41: =O30
A42: Retention still held ($) | D42: =Q30
...

Sheet Portfolio
A1: Portfolio | K1: The Project Control Hub
A2: Several jobs like this one at once. The holes do not average out; they stack.
A3: Give each job a start month (0 = starts with the first) and a size relative to this one. Compare the total with the facility.
A6: Job | B6: Starts after (months) | C6: Size (× this job) | E6: ALL JOBS TOGETHER
E7: Deepest combined position ($) | G7: =MIN(G18:G53)
E8: Month | G8: =IF(G7>=0,"",INDEX(A18:A53,MATCH(G7,G18:G53,0)))
E9: Overdraft facility ($) | G9: =Setup!B18
E10: Short of the facility by ($) | G10: =IF(OR(G9="",G7>=0),"",MAX(0,-G7-G9))
E11: Combined profit at the end ($) | G11: =SUMPRODUCT((A7:A11<>"")*(B7:B11<>"")*((C7:C11="")+C7:C11))*'Cash flow'!D35
A13: Topic 18 stacks three jobs in their cash-hungry months at once: three holes of $60,462 make $181,386. Spread the starts and watch the total. | E13: The profit arrives at the end of each job; the holes arrive together, at the start.
A17: Month | B17: Job A | C17: Job B | D17: Job C | E17: Job D | F17: Job E | G17: All jobs ($) | H17: Facility ($)
A18: 1 | B18: =IF(OR($A$7="",$B$7=""),0,IF((A18-$B$7)<1,0,IF((A18-$B$7)>24,INDEX('Cash flow'!$P$7:$P$30,24),INDEX('Cash flow'!$P$7:$P$30,(A18-$B$7))))*IF($C$7="",1,$C$7)) | C18: =IF(OR($A$8="",$B$8=""),0,IF((A18-$B$8)<1,0,IF((A18-$B$8)>24,INDEX('Cash flow'!$P$7:$P$30,24),INDEX('Cash flow'!$P$7:$P$30,(A18-$B$8))))*IF($C$8="",1,$C$8)) | D18: =IF(OR($A$9="",$B$9=""),0,IF((A18-$B$9)<1,0,IF((A18-$B$9)>24,INDEX('Cash flow'!$P$7:$P$30,24),INDEX('Cash flow'!$P$7:$P$30,(A18-$B$9))))*IF($C$9="",1,$C$9)) | E18: =IF(OR($A$10="",$B$10=""),0,IF((A18-$B$10)<1,0,IF((A18-$B$10)>24,INDEX('Cash flow'!$P$7:$P$30,24),INDEX('Cash flow'!$P$7:$P$30,(A18-$B$10))))*IF($C$10="",1,$C$10)) | F18: =IF(OR($A$11="",$B$11=""),0,IF((A18-$B$11)<1,0,IF((A18-$B$11)>24,INDEX('Cash flow'!$P$7:$P$30,24),INDEX('Cash flow'!$P$7:$P$30,(A18-$B$11))))*IF($C$11="",1,$C$11)) | G18: =SUM(B18:F18) | H18: =IF(Setup!$B$18="",NA(),-Setup!$B$18)
A19: 2 | B19: =IF(OR($A$7="",$B$7=""),0,IF((A19-$B$7)<1,0,IF((A19-$B$7)>24,INDEX('Cash flow'!$P$7:$P$30,24),INDEX('Cash flow'!$P$7:$P$30,(A19-$B$7))))*IF($C$7="",1,$C$7)) | C19: =IF(OR($A$8="",$B$8=""),0,IF((A19-$B$8)<1,0,IF((A19-$B$8)>24,INDEX('Cash flow'!$P$7:$P$30,24),INDEX('Cash flow'!$P$7:$P$30,(A19-$B$8))))*IF($C$8="",1,$C$8)) | D19: =IF(OR($A$9="",$B$9=""),0,IF((A19-$B$9)<1,0,IF((A19-$B$9)>24,INDEX('Cash flow'!$P$7:$P$30,24),INDEX('Cash flow'!$P$7:$P$30,(A19-$B$9))))*IF($C$9="",1,$C$9)) | E19: =IF(OR($A$10="",$B$10=""),0,IF((A19-$B$10)<1,0,IF((A19-$B$10)>24,INDEX('Cash flow'!$P$7:$P$30,24),INDEX('Cash flow'!$P$7:$P$30,(A19-$B$10))))*IF($C$10="",1,$C$10)) | F19: =IF(OR($A$11="",$B$11=""),0,IF((A19-$B$11)<1,0,IF((A19-$B$11)>24,INDEX('Cash flow'!$P$7:$P$30,24),INDEX('Cash flow'!$P$7:$P$30,(A19-$B$11))))*IF($C$11="",1,$C$11)) | G19: =SUM(B19:F19) | H19: =IF(Setup!$B$18="",NA(),-Setup!$B$18)
A20: 3 | B20: =IF(OR($A$7="",$B$7=""),0,IF((A20-$B$7)<1,0,IF((A20-$B$7)>24,INDEX('Cash flow'!$P$7:$P$30,24),INDEX('Cash flow'!$P$7:$P$30,(A20-$B$7))))*IF($C$7="",1,$C$7)) | C20: =IF(OR($A$8="",$B$8=""),0,IF((A20-$B$8)<1,0,IF((A20-$B$8)>24,INDEX('Cash flow'!$P$7:$P$30,24),INDEX('Cash flow'!$P$7:$P$30,(A20-$B$8))))*IF($C$8="",1,$C$8)) | D20: =IF(OR($A$9="",$B$9=""),0,IF((A20-$B$9)<1,0,IF((A20-$B$9)>24,INDEX('Cash flow'!$P$7:$P$30,24),INDEX('Cash flow'!$P$7:$P$30,(A20-$B$9))))*IF($C$9="",1,$C$9)) | E20: =IF(OR($A$10="",$B$10=""),0,IF((A20-$B$10)<1,0,IF((A20-$B$10)>24,INDEX('Cash flow'!$P$7:$P$30,24),INDEX('Cash flow'!$P$7:$P$30,(A20-$B$10))))*IF($C$10="",1,$C$10)) | F20: =IF(OR($A$11="",$B$11=""),0,IF((A20-$B$11)<1,0,IF((A20-$B$11)>24,INDEX('Cash flow'!$P$7:$P$30,24),INDEX('Cash flow'!$P$7:$P$30,(A20-$B$11))))*IF($C$11="",1,$C$11)) | G20: =SUM(B20:F20) | H20: =IF(Setup!$B$18="",NA(),-Setup!$B$18)
A21: 4 | B21: =IF(OR($A$7="",$B$7=""),0,IF((A21-$B$7)<1,0,IF((A21-$B$7)>24,INDEX('Cash flow'!$P$7:$P$30,24),INDEX('Cash flow'!$P$7:$P$30,(A21-$B$7))))*IF($C$7="",1,$C$7)) | C21: =IF(OR($A$8="",$B$8=""),0,IF((A21-$B$8)<1,0,IF((A21-$B$8)>24,INDEX('Cash flow'!$P$7:$P$30,24),INDEX('Cash flow'!$P$7:$P$30,(A21-$B$8))))*IF($C$8="",1,$C$8)) | D21: =IF(OR($A$9="",$B$9=""),0,IF((A21-$B$9)<1,0,IF((A21-$B$9)>24,INDEX('Cash flow'!$P$7:$P$30,24),INDEX('Cash flow'!$P$7:$P$30,(A21-$B$9))))*IF($C$9="",1,$C$9)) | E21: =IF(OR($A$10="",$B$10=""),0,IF((A21-$B$10)<1,0,IF((A21-$B$10)>24,INDEX('Cash flow'!$P$7:$P$30,24),INDEX('Cash flow'!$P$7:$P$30,(A21-$B$10))))*IF($C$10="",1,$C$10)) | F21: =IF(OR($A$11="",$B$11=""),0,IF((A21-$B$11)<1,0,IF((A21-$B$11)>24,INDEX('Cash flow'!$P$7:$P$30,24),INDEX('Cash flow'!$P$7:$P$30,(A21-$B$11))))*IF($C$11="",1,$C$11)) | G21: =SUM(B21:F21) | H21: =IF(Setup!$B$18="",NA(),-Setup!$B$18)
A22: 5 | B22: =IF(OR($A$7="",$B$7=""),0,IF((A22-$B$7)<1,0,IF((A22-$B$7)>24,INDEX('Cash flow'!$P$7:$P$30,24),INDEX('Cash flow'!$P$7:$P$30,(A22-$B$7))))*IF($C$7="",1,$C$7)) | C22: =IF(OR($A$8="",$B$8=""),0,IF((A22-$B$8)<1,0,IF((A22-$B$8)>24,INDEX('Cash flow'!$P$7:$P$30,24),INDEX('Cash flow'!$P$7:$P$30,(A22-$B$8))))*IF($C$8="",1,$C$8)) | D22: =IF(OR($A$9="",$B$9=""),0,IF((A22-$B$9)<1,0,IF((A22-$B$9)>24,INDEX('Cash flow'!$P$7:$P$30,24),INDEX('Cash flow'!$P$7:$P$30,(A22-$B$9))))*IF($C$9="",1,$C$9)) | E22: =IF(OR($A$10="",$B$10=""),0,IF((A22-$B$10)<1,0,IF((A22-$B$10)>24,INDEX('Cash flow'!$P$7:$P$30,24),INDEX('Cash flow'!$P$7:$P$30,(A22-$B$10))))*IF($C$10="",1,$C$10)) | F22: =IF(OR($A$11="",$B$11=""),0,IF((A22-$B$11)<1,0,IF((A22-$B$11)>24,INDEX('Cash flow'!$P$7:$P$30,24),INDEX('Cash flow'!$P$7:$P$30,(A22-$B$11))))*IF($C$11="",1,$C$11)) | G22: =SUM(B22:F22) | H22: =IF(Setup!$B$18="",NA(),-Setup!$B$18)
A23: 6 | B23: =IF(OR($A$7="",$B$7=""),0,IF((A23-$B$7)<1,0,IF((A23-$B$7)>24,INDEX('Cash flow'!$P$7:$P$30,24),INDEX('Cash flow'!$P$7:$P$30,(A23-$B$7))))*IF($C$7="",1,$C$7)) | C23: =IF(OR($A$8="",$B$8=""),0,IF((A23-$B$8)<1,0,IF((A23-$B$8)>24,INDEX('Cash flow'!$P$7:$P$30,24),INDEX('Cash flow'!$P$7:$P$30,(A23-$B$8))))*IF($C$8="",1,$C$8)) | D23: =IF(OR($A$9="",$B$9=""),0,IF((A23-$B$9)<1,0,IF((A23-$B$9)>24,INDEX('Cash flow'!$P$7:$P$30,24),INDEX('Cash flow'!$P$7:$P$30,(A23-$B$9))))*IF($C$9="",1,$C$9)) | E23: =IF(OR($A$10="",$B$10=""),0,IF((A23-$B$10)<1,0,IF((A23-$B$10)>24,INDEX('Cash flow'!$P$7:$P$30,24),INDEX('Cash flow'!$P$7:$P$30,(A23-$B$10))))*IF($C$10="",1,$C$10)) | F23: =IF(OR($A$11="",$B$11=""),0,IF((A23-$B$11)<1,0,IF((A23-$B$11)>24,INDEX('Cash flow'!$P$7:$P$30,24),INDEX('Cash flow'!$P$7:$P$30,(A23-$B$11))))*IF($C$11="",1,$C$11)) | G23: =SUM(B23:F23) | H23: =IF(Setup!$B$18="",NA(),-Setup!$B$18)
A24: 7 | B24: =IF(OR($A$7="",$B$7=""),0,IF((A24-$B$7)<1,0,IF((A24-$B$7)>24,INDEX('Cash flow'!$P$7:$P$30,24),INDEX('Cash flow'!$P$7:$P$30,(A24-$B$7))))*IF($C$7="",1,$C$7)) | C24: =IF(OR($A$8="",$B$8=""),0,IF((A24-$B$8)<1,0,IF((A24-$B$8)>24,INDEX('Cash flow'!$P$7:$P$30,24),INDEX('Cash flow'!$P$7:$P$30,(A24-$B$8))))*IF($C$8="",1,$C$8)) | D24: =IF(OR($A$9="",$B$9=""),0,IF((A24-$B$9)<1,0,IF((A24-$B$9)>24,INDEX('Cash flow'!$P$7:$P$30,24),INDEX('Cash flow'!$P$7:$P$30,(A24-$B$9))))*IF($C$9="",1,$C$9)) | E24: =IF(OR($A$10="",$B$10=""),0,IF((A24-$B$10)<1,0,IF((A24-$B$10)>24,INDEX('Cash flow'!$P$7:$P$30,24),INDEX('Cash flow'!$P$7:$P$30,(A24-$B$10))))*IF($C$10="",1,$C$10)) | F24: =IF(OR($A$11="",$B$11=""),0,IF((A24-$B$11)<1,0,IF((A24-$B$11)>24,INDEX('Cash flow'!$P$7:$P$30,24),INDEX('Cash flow'!$P$7:$P$30,(A24-$B$11))))*IF($C$11="",1,$C$11)) | G24: =SUM(B24:F24) | H24: =IF(Setup!$B$18="",NA(),-Setup!$B$18)
A25: 8 | B25: =IF(OR($A$7="",$B$7=""),0,IF((A25-$B$7)<1,0,IF((A25-$B$7)>24,INDEX('Cash flow'!$P$7:$P$30,24),INDEX('Cash flow'!$P$7:$P$30,(A25-$B$7))))*IF($C$7="",1,$C$7)) | C25: =IF(OR($A$8="",$B$8=""),0,IF((A25-$B$8)<1,0,IF((A25-$B$8)>24,INDEX('Cash flow'!$P$7:$P$30,24),INDEX('Cash flow'!$P$7:$P$30,(A25-$B$8))))*IF($C$8="",1,$C$8)) | D25: =IF(OR($A$9="",$B$9=""),0,IF((A25-$B$9)<1,0,IF((A25-$B$9)>24,INDEX('Cash flow'!$P$7:$P$30,24),INDEX('Cash flow'!$P$7:$P$30,(A25-$B$9))))*IF($C$9="",1,$C$9)) | E25: =IF(OR($A$10="",$B$10=""),0,IF((A25-$B$10)<1,0,IF((A25-$B$10)>24,INDEX('Cash flow'!$P$7:$P$30,24),INDEX('Cash flow'!$P$7:$P$30,(A25-$B$10))))*IF($C$10="",1,$C$10)) | F25: =IF(OR($A$11="",$B$11=""),0,IF((A25-$B$11)<1,0,IF((A25-$B$11)>24,INDEX('Cash flow'!$P$7:$P$30,24),INDEX('Cash flow'!$P$7:$P$30,(A25-$B$11))))*IF($C$11="",1,$C$11)) | G25: =SUM(B25:F25) | H25: =IF(Setup!$B$18="",NA(),-Setup!$B$18)
A26: 9 | B26: =IF(OR($A$7="",$B$7=""),0,IF((A26-$B$7)<1,0,IF((A26-$B$7)>24,INDEX('Cash flow'!$P$7:$P$30,24),INDEX('Cash flow'!$P$7:$P$30,(A26-$B$7))))*IF($C$7="",1,$C$7)) | C26: =IF(OR($A$8="",$B$8=""),0,IF((A26-$B$8)<1,0,IF((A26-$B$8)>24,INDEX('Cash flow'!$P$7:$P$30,24),INDEX('Cash flow'!$P$7:$P$30,(A26-$B$8))))*IF($C$8="",1,$C$8)) | D26: =IF(OR($A$9="",$B$9=""),0,IF((A26-$B$9)<1,0,IF((A26-$B$9)>24,INDEX('Cash flow'!$P$7:$P$30,24),INDEX('Cash flow'!$P$7:$P$30,(A26-$B$9))))*IF($C$9="",1,$C$9)) | E26: =IF(OR($A$10="",$B$10=""),0,IF((A26-$B$10)<1,0,IF((A26-$B$10)>24,INDEX('Cash flow'!$P$7:$P$30,24),INDEX('Cash flow'!$P$7:$P$30,(A26-$B$10))))*IF($C$10="",1,$C$10)) | F26: =IF(OR($A$11="",$B$11=""),0,IF((A26-$B$11)<1,0,IF((A26-$B$11)>24,INDEX('Cash flow'!$P$7:$P$30,24),INDEX('Cash flow'!$P$7:$P$30,(A26-$B$11))))*IF($C$11="",1,$C$11)) | G26: =SUM(B26:F26) | H26: =IF(Setup!$B$18="",NA(),-Setup!$B$18)
A27: 10 | B27: =IF(OR($A$7="",$B$7=""),0,IF((A27-$B$7)<1,0,IF((A27-$B$7)>24,INDEX('Cash flow'!$P$7:$P$30,24),INDEX('Cash flow'!$P$7:$P$30,(A27-$B$7))))*IF($C$7="",1,$C$7)) | C27: =IF(OR($A$8="",$B$8=""),0,IF((A27-$B$8)<1,0,IF((A27-$B$8)>24,INDEX('Cash flow'!$P$7:$P$30,24),INDEX('Cash flow'!$P$7:$P$30,(A27-$B$8))))*IF($C$8="",1,$C$8)) | D27: =IF(OR($A$9="",$B$9=""),0,IF((A27-$B$9)<1,0,IF((A27-$B$9)>24,INDEX('Cash flow'!$P$7:$P$30,24),INDEX('Cash flow'!$P$7:$P$30,(A27-$B$9))))*IF($C$9="",1,$C$9)) | E27: =IF(OR($A$10="",$B$10=""),0,IF((A27-$B$10)<1,0,IF((A27-$B$10)>24,INDEX('Cash flow'!$P$7:$P$30,24),INDEX('Cash flow'!$P$7:$P$30,(A27-$B$10))))*IF($C$10="",1,$C$10)) | F27: =IF(OR($A$11="",$B$11=""),0,IF((A27-$B$11)<1,0,IF((A27-$B$11)>24,INDEX('Cash flow'!$P$7:$P$30,24),INDEX('Cash flow'!$P$7:$P$30,(A27-$B$11))))*IF($C$11="",1,$C$11)) | G27: =SUM(B27:F27) | H27: =IF(Setup!$B$18="",NA(),-Setup!$B$18)
A28: 11 | B28: =IF(OR($A$7="",$B$7=""),0,IF((A28-$B$7)<1,0,IF((A28-$B$7)>24,INDEX('Cash flow'!$P$7:$P$30,24),INDEX('Cash flow'!$P$7:$P$30,(A28-$B$7))))*IF($C$7="",1,$C$7)) | C28: =IF(OR($A$8="",$B$8=""),0,IF((A28-$B$8)<1,0,IF((A28-$B$8)>24,INDEX('Cash flow'!$P$7:$P$30,24),INDEX('Cash flow'!$P$7:$P$30,(A28-$B$8))))*IF($C$8="",1,$C$8)) | D28: =IF(OR($A$9="",$B$9=""),0,IF((A28-$B$9)<1,0,IF((A28-$B$9)>24,INDEX('Cash flow'!$P$7:$P$30,24),INDEX('Cash flow'!$P$7:$P$30,(A28-$B$9))))*IF($C$9="",1,$C$9)) | E28: =IF(OR($A$10="",$B$10=""),0,IF((A28-$B$10)<1,0,IF((A28-$B$10)>24,INDEX('Cash flow'!$P$7:$P$30,24),INDEX('Cash flow'!$P$7:$P$30,(A28-$B$10))))*IF($C$10="",1,$C$10)) | F28: =IF(OR($A$11="",$B$11=""),0,IF((A28-$B$11)<1,0,IF((A28-$B$11)>24,INDEX('Cash flow'!$P$7:$P$30,24),INDEX('Cash flow'!$P$7:$P$30,(A28-$B$11))))*IF($C$11="",1,$C$11)) | G28: =SUM(B28:F28) | H28: =IF(Setup!$B$18="",NA(),-Setup!$B$18)
A29: 12 | B29: =IF(OR($A$7="",$B$7=""),0,IF((A29-$B$7)<1,0,IF((A29-$B$7)>24,INDEX('Cash flow'!$P$7:$P$30,24),INDEX('Cash flow'!$P$7:$P$30,(A29-$B$7))))*IF($C$7="",1,$C$7)) | C29: =IF(OR($A$8="",$B$8=""),0,IF((A29-$B$8)<1,0,IF((A29-$B$8)>24,INDEX('Cash flow'!$P$7:$P$30,24),INDEX('Cash flow'!$P$7:$P$30,(A29-$B$8))))*IF($C$8="",1,$C$8)) | D29: =IF(OR($A$9="",$B$9=""),0,IF((A29-$B$9)<1,0,IF((A29-$B$9)>24,INDEX('Cash flow'!$P$7:$P$30,24),INDEX('Cash flow'!$P$7:$P$30,(A29-$B$9))))*IF($C$9="",1,$C$9)) | E29: =IF(OR($A$10="",$B$10=""),0,IF((A29-$B$10)<1,0,IF((A29-$B$10)>24,INDEX('Cash flow'!$P$7:$P$30,24),INDEX('Cash flow'!$P$7:$P$30,(A29-$B$10))))*IF($C$10="",1,$C$10)) | F29: =IF(OR($A$11="",$B$11=""),0,IF((A29-$B$11)<1,0,IF((A29-$B$11)>24,INDEX('Cash flow'!$P$7:$P$30,24),INDEX('Cash flow'!$P$7:$P$30,(A29-$B$11))))*IF($C$11="",1,$C$11)) | G29: =SUM(B29:F29) | H29: =IF(Setup!$B$18="",NA(),-Setup!$B$18)
... A53: 36 | B53: =IF(OR($A$7="",$B$7=""),0,IF((A53-$B$7)<1,0,IF((A53-$B$7)>24,INDEX('Cash flow'!$P$7:$P$30,24),INDEX('Cash flow'!$P$7:$P$30,(A53-$B$7))))*IF($C$7="",1,$C$7)) | C53: =IF(OR($A$8="",$B$8=""),0,IF((A53-$B$8)<1,0,IF((A53-$B$8)>24,INDEX('Cash flow'!$P$7:$P$30,24),INDEX('Cash flow'!$P$7:$P$30,(A53-$B$8))))*IF($C$8="",1,$C$8)) | D53: =IF(OR($A$9="",$B$9=""),0,IF((A53-$B$9)<1,0,IF((A53-$B$9)>24,INDEX('Cash flow'!$P$7:$P$30,24),INDEX('Cash flow'!$P$7:$P$30,(A53-$B$9))))*IF($C$9="",1,$C$9)) | E53: =IF(OR($A$10="",$B$10=""),0,IF((A53-$B$10)<1,0,IF((A53-$B$10)>24,INDEX('Cash flow'!$P$7:$P$30,24),INDEX('Cash flow'!$P$7:$P$30,(A53-$B$10))))*IF($C$10="",1,$C$10)) | F53: =IF(OR($A$11="",$B$11=""),0,IF((A53-$B$11)<1,0,IF((A53-$B$11)>24,INDEX('Cash flow'!$P$7:$P$30,24),INDEX('Cash flow'!$P$7:$P$30,(A53-$B$11))))*IF($C$11="",1,$C$11)) | G53: =SUM(B53:F53) | H53: =IF(Setup!$B$18="",NA(),-Setup!$B$18)
