Workbook
Name WeekEnd: '15 Chart data'!$C$22
Name WeekNo: '02 Dashboard'!$C$4
Name WeekReports: '15 Chart data'!$C$23
Name WeekStart: '15 Chart data'!$C$21

Sheet 00 Start
B2: Daily site report | F2: The Project Control Hub
B3: The record nobody reads until a claim, an incident or a test result needs it. Make it one that stands.
B4: The Project Control Hub · free template · example: the example project, 2 to 13 March
B7: EVERY DAY, IN FIVE STEPS · type each fact once, in a log; the report and the Dashboard read from there
B8: 1 | C8: 03 Day log → | D8: One line for the day: report no., time issued, weather, rainfall, working day, prepared by. | E8: 1 minute
B9: 2 | C9: 04 Resource log → | D9: Every crew and every machine, each against its P6 activity ID: number, hours, idle reason. | E9: 5 minutes
B10: 3 | C10: 05 Work done log → | D10: The quantity done on each P6 activity, and where it came from: counted, estimated or not yet reported. | E10: 5 minutes
B11: 4 | C11: 06 Event log → | D11: Events, instructions and delays; deliveries in the Delivery log, safety in the Safety log. A claim? Notice calendar. | E11: 3 minutes
B12: 5 | C12: 01 Daily report → | D12: Pick the date in B5: the report builds itself. Blanks go to Not yet reported, corrections to the Revision log. | E12: 1 minute
B14: COUNTED, OR REMEMBERED?
C15: Counted | D15: Somebody measured it today: the survey, the store, the attendance sheet.
C16: Estimated | D16: A foreman’s figure. Allowed, but labelled, and measured later.
C17: Not yet reported | D17: The day has not finished producing it. A visible blank beats a quiet wrong number.
B19: TWO WAYS TO JUDGE A DAILY REPORT
C20: Went out on time | D20: Easy to measure, easy to hit, and easy to game by sending an emptier report earlier.
C21: Never revised after | D21: Cannot be gamed by hurrying. The Dashboard shows both; the second is the one that matters.
B23: HOW TO READ THE CELLS
C24: Yellow, blue text | D24: Yours to fill in: only in the log sheets, Setup, Contract hours and P6 activities.
C25: White, black text | D25: A formula. Leave it alone and it keeps working. The Daily report and Dashboard are all formulas.
C26: Red | D26: Lost day, not reported, overdue, or an event that could become a claim.
B28: WHAT IS IN THIS FILE
C29: READ AND SEND · built for you
C30: 01 Daily report | D30: A view, not a form: pick a date and it fills itself from the logs. Ready to send.
C31: 02 Dashboard | D31: The week, picked in C4: six numbers, productivity, four charts, quantities, key events.
C32: EVERY DAY · type the facts
C33: 03 Day log | D33: One line a day: the header facts. People, plant, events and claims fill themselves.
C34: 04 Resource log | D34: Every crew and machine against its P6 activity: man-hours and machine-hours.
C35: 05 Work done log | D35: One line per P6 activity per day: quantities, with their source.
C36: 06 Event log | D36: Events, instructions, delays and visitors, with the P6 activity affected.
C37: 07 Delivery log | D37: Every delivery, with delivery note, short or damaged, and its P6 activity.
C38: 08 Safety log | D38: Incidents, near misses, toolbox talks and inspections.
C39: FOLLOW UP · close the gaps
C40: 09 Not yet reported | D40: Explicit blanks, followed up until closed.
C41: 10 Revision log | D41: Every correction, with the old value, the new one and why.
C42: 11 Notice calendar | D42: Every event that could become a claim, with its notice deadline.
C43: ONCE PER PROJECT · set up
C44: 12 P6 activities | D44: The Primavera P6 activity list: paste your P6 export here. Every drop-down reads from it.
C45: 13 Contract hours | D45: Contract quantity and man-hours per P6 activity: the baseline for productivity.
C46: 14 Setup | D46: The deadline, the notice period and every drop-down list.
C47: 15 Chart data | D47: Locked calculations behind the Dashboard charts. Nothing to type here.
...

Sheet 01 Daily report
A1: Daily site report | H1: The Project Control Hub
A2: One day, on one page. Every figure says where it came from.
A3: Pick the date in B5. Everything on this page is pulled from the logs: type the facts once, in the Day log, Resource log, Work done log, Delivery log, Event log and Safety log.
A4: =IF($B$5="","Pick a date in B5",IF(COUNTIF('03 Day log'!$A$8:$A$38,$B$5)=0,"⚠ This date is not in the Day log yet: add the day there first","Built automatically from the logs for the date in B5. Change the facts in the logs, not here.")) -> Built automatically from the logs for the date in B5. Change the facts in the logs, not here.
A5: Date | B5: 46084 | E5: Revision | F5: =IF(B5="","",COUNTIF('10 Revision log'!$A$7:$A$56,B5)) -> 1 | G5: raised by each line on the Revision log
A6: Report no. | B6: =IF($B$5="","",IFERROR(_xlfn.LET(_xlpm.v,INDEX('03 Day log'!$B$8:$B$38,MATCH($B$5,'03 Day log'!$A$8:$A$38,0)),IF(_xlpm.v="","",_xlpm.v)),"")) -> 41 | E6: Due by | F6: ='14 Setup'!B7 -> 0.58333333
A7: Issued at | B7: =IF($B$5="","",IFERROR(_xlfn.LET(_xlpm.v,INDEX('03 Day log'!$C$8:$C$38,MATCH($B$5,'03 Day log'!$A$8:$A$38,0)),IF(_xlpm.v="","",_xlpm.v)),"")) -> 0.58333333 | E7: On time? | F7: =IF(OR(B7="",F6=""),"",IF(B7<=F6,"✔ on time","Late by "&TEXT(B7-F6,"h:mm"))) -> ✔ on time
A8: Weather, morning | B8: =IF($B$5="","",IFERROR(_xlfn.LET(_xlpm.v,INDEX('03 Day log'!$M$8:$M$38,MATCH($B$5,'03 Day log'!$A$8:$A$38,0)),IF(_xlpm.v="","",_xlpm.v)),"")) -> Dry | E8: Prepared by | F8: =IF($B$5="","",IFERROR(_xlfn.LET(_xlpm.v,INDEX('03 Day log'!$Q$8:$Q$38,MATCH($B$5,'03 Day log'!$A$8:$A$38,0)),IF(_xlpm.v="","",_xlpm.v)),"")) -> Site engineer
A9: Weather, afternoon | B9: =IF($B$5="","",IFERROR(_xlfn.LET(_xlpm.v,INDEX('03 Day log'!$N$8:$N$38,MATCH($B$5,'03 Day log'!$A$8:$A$38,0)),IF(_xlpm.v="","",_xlpm.v)),"")) -> Rain | E9: Checked by | F9: =IF($B$5="","",IFERROR(_xlfn.LET(_xlpm.v,INDEX('03 Day log'!$R$8:$R$38,MATCH($B$5,'03 Day log'!$A$8:$A$38,0)),IF(_xlpm.v="","",_xlpm.v)),""))
A10: Working conditions | B10: =IF($B$5="","",IFERROR(_xlfn.LET(_xlpm.v,INDEX('03 Day log'!$G$8:$G$38,MATCH($B$5,'03 Day log'!$A$8:$A$38,0)),IF(_xlpm.v="","",_xlpm.v)),"")) -> Part lost | E10: Project | F10: ='14 Setup'!B6 -> Example project
A11: Rainfall (mm) | B11: =IF($B$5="","",IFERROR(_xlfn.LET(_xlpm.v,INDEX('03 Day log'!$O$8:$O$38,MATCH($B$5,'03 Day log'!$A$8:$A$38,0)),IF(_xlpm.v="","",_xlpm.v)),"")) | E11: Temp. (°C) | F11: =IF($B$5="","",IFERROR(_xlfn.LET(_xlpm.v,INDEX('03 Day log'!$P$8:$P$38,MATCH($B$5,'03 Day log'!$A$8:$A$38,0)),IF(_xlpm.v="","",_xlpm.v)),"")) -> 6
A13: LABOUR | H13: =IF($B$5="","",IF(COUNTIFS('04 Resource log'!$A$7:$A$506,$B$5,'04 Resource log'!$E$7:$E$506,"Labour")>10,"⚠ "&COUNTIFS('04 Resource log'!$A$7:$A$506,$B$5,'04 Resource log'!$E$7:$E$506,"Labour")&" lines in the Resource log: only 10 fit here",""))
A14: Company | B14: Trade | C14: Headcount | D14: Hours each | E14: Man-hours | F14: P6 Activity ID | G14: Note
A15: {=IF($B$5="","",IFERROR(_xlfn.LET(_xlpm.v,INDEX(_xlfn._xlws.FILTER('04 Resource log'!$G$7:$G$506,('04 Resource log'!$A$7:$A$506=$B$5)*('04 Resource log'!$E$7:$E$506="Labour")),ROWS($A$15:A15)),IF(_xlpm.v="","",_xlpm.v)),""))} -> Piling sub | B15: {=IF($B$5="","",IFERROR(_xlfn.LET(_xlpm.v,INDEX(_xlfn._xlws.FILTER('04 Resource log'!$F$7:$F$506,('04 Resource log'!$A$7:$A$506=$B$5)*('04 Resource log'!$E$7:$E$506="Labour")),ROWS($A$15:A15)),IF(_xlpm.v="","",_xlpm.v)),""))} -> Piling crew | C15: {=IF($B$5="","",IFERROR(_xlfn.LET(_xlpm.v,INDEX(_xlfn._xlws.FILTER('04 Resource log'!$H$7:$H$506,('04 Resource log'!$A$7:$A$506=$B$5)*('04 Resource log'!$E$7:$E$506="Labour")),ROWS($A$15:A15)),IF(_xlpm.v="","",_xlpm.v)),""))} -> 6 | D15: {=IF($B$5="","",IFERROR(_xlfn.LET(_xlpm.v,INDEX(_xlfn._xlws.FILTER('04 Resource log'!$I$7:$I$506,('04 Resource log'!$A$7:$A$506=$B$5)*('04 Resource log'!$E$7:$E$506="Labour")),ROWS($A$15:A15)),IF(_xlpm.v="","",_xlpm.v)),""))} -> 9 | E15: =IF(OR(C15="",D15=""),"",C15*D15) -> 54 | F15: {=IF($B$5="","",IFERROR(_xlfn.LET(_xlpm.v,INDEX(_xlfn._xlws.FILTER('04 Resource log'!$B$7:$B$506,('04 Resource log'!$A$7:$A$506=$B$5)*('04 Resource log'!$E$7:$E$506="Labour")),ROWS($A$15:A15)),IF(_xlpm.v="","",_xlpm.v)),""))} -> A1000
A16: {=IF($B$5="","",IFERROR(_xlfn.LET(_xlpm.v,INDEX(_xlfn._xlws.FILTER('04 Resource log'!$G$7:$G$506,('04 Resource log'!$A$7:$A$506=$B$5)*('04 Resource log'!$E$7:$E$506="Labour")),ROWS($A$15:A16)),IF(_xlpm.v="","",_xlpm.v)),""))} -> Rebar sub | B16: {=IF($B$5="","",IFERROR(_xlfn.LET(_xlpm.v,INDEX(_xlfn._xlws.FILTER('04 Resource log'!$F$7:$F$506,('04 Resource log'!$A$7:$A$506=$B$5)*('04 Resource log'!$E$7:$E$506="Labour")),ROWS($A$15:A16)),IF(_xlpm.v="","",_xlpm.v)),""))} -> Rebar gang | C16: {=IF($B$5="","",IFERROR(_xlfn.LET(_xlpm.v,INDEX(_xlfn._xlws.FILTER('04 Resource log'!$H$7:$H$506,('04 Resource log'!$A$7:$A$506=$B$5)*('04 Resource log'!$E$7:$E$506="Labour")),ROWS($A$15:A16)),IF(_xlpm.v="","",_xlpm.v)),""))} -> 8 | D16: {=IF($B$5="","",IFERROR(_xlfn.LET(_xlpm.v,INDEX(_xlfn._xlws.FILTER('04 Resource log'!$I$7:$I$506,('04 Resource log'!$A$7:$A$506=$B$5)*('04 Resource log'!$E$7:$E$506="Labour")),ROWS($A$15:A16)),IF(_xlpm.v="","",_xlpm.v)),""))} -> 9 | E16: =IF(OR(C16="",D16=""),"",C16*D16) -> 72 | F16: {=IF($B$5="","",IFERROR(_xlfn.LET(_xlpm.v,INDEX(_xlfn._xlws.FILTER('04 Resource log'!$B$7:$B$506,('04 Resource log'!$A$7:$A$506=$B$5)*('04 Resource log'!$E$7:$E$506="Labour")),ROWS($A$15:A16)),IF(_xlpm.v="","",_xlpm.v)),""))} -> A1100
A17: {=IF($B$5="","",IFERROR(_xlfn.LET(_xlpm.v,INDEX(_xlfn._xlws.FILTER('04 Resource log'!$G$7:$G$506,('04 Resource log'!$A$7:$A$506=$B$5)*('04 Resource log'!$E$7:$E$506="Labour")),ROWS($A$15:A17)),IF(_xlpm.v="","",_xlpm.v)),""))} -> Concrete sub | B17: {=IF($B$5="","",IFERROR(_xlfn.LET(_xlpm.v,INDEX(_xlfn._xlws.FILTER('04 Resource log'!$F$7:$F$506,('04 Resource log'!$A$7:$A$506=$B$5)*('04 Resource log'!$E$7:$E$506="Labour")),ROWS($A$15:A17)),IF(_xlpm.v="","",_xlpm.v)),""))} -> Concrete gang | C17: {=IF($B$5="","",IFERROR(_xlfn.LET(_xlpm.v,INDEX(_xlfn._xlws.FILTER('04 Resource log'!$H$7:$H$506,('04 Resource log'!$A$7:$A$506=$B$5)*('04 Resource log'!$E$7:$E$506="Labour")),ROWS($A$15:A17)),IF(_xlpm.v="","",_xlpm.v)),""))} -> 6 | D17: {=IF($B$5="","",IFERROR(_xlfn.LET(_xlpm.v,INDEX(_xlfn._xlws.FILTER('04 Resource log'!$I$7:$I$506,('04 Resource log'!$A$7:$A$506=$B$5)*('04 Resource log'!$E$7:$E$506="Labour")),ROWS($A$15:A17)),IF(_xlpm.v="","",_xlpm.v)),""))} -> 9 | E17: =IF(OR(C17="",D17=""),"",C17*D17) -> 54 | F17: {=IF($B$5="","",IFERROR(_xlfn.LET(_xlpm.v,INDEX(_xlfn._xlws.FILTER('04 Resource log'!$B$7:$B$506,('04 Resource log'!$A$7:$A$506=$B$5)*('04 Resource log'!$E$7:$E$506="Labour")),ROWS($A$15:A17)),IF(_xlpm.v="","",_xlpm.v)),""))} -> A1200
A18: {=IF($B$5="","",IFERROR(_xlfn.LET(_xlpm.v,INDEX(_xlfn._xlws.FILTER('04 Resource log'!$G$7:$G$506,('04 Resource log'!$A$7:$A$506=$B$5)*('04 Resource log'!$E$7:$E$506="Labour")),ROWS($A$15:A18)),IF(_xlpm.v="","",_xlpm.v)),""))} -> Groundworks | B18: {=IF($B$5="","",IFERROR(_xlfn.LET(_xlpm.v,INDEX(_xlfn._xlws.FILTER('04 Resource log'!$F$7:$F$506,('04 Resource log'!$A$7:$A$506=$B$5)*('04 Resource log'!$E$7:$E$506="Labour")),ROWS($A$15:A18)),IF(_xlpm.v="","",_xlpm.v)),""))} -> Groundworks | C18: {=IF($B$5="","",IFERROR(_xlfn.LET(_xlpm.v,INDEX(_xlfn._xlws.FILTER('04 Resource log'!$H$7:$H$506,('04 Resource log'!$A$7:$A$506=$B$5)*('04 Resource log'!$E$7:$E$506="Labour")),ROWS($A$15:A18)),IF(_xlpm.v="","",_xlpm.v)),""))} -> 5 | D18: {=IF($B$5="","",IFERROR(_xlfn.LET(_xlpm.v,INDEX(_xlfn._xlws.FILTER('04 Resource log'!$I$7:$I$506,('04 Resource log'!$A$7:$A$506=$B$5)*('04 Resource log'!$E$7:$E$506="Labour")),ROWS($A$15:A18)),IF(_xlpm.v="","",_xlpm.v)),""))} -> 9 | E18: =IF(OR(C18="",D18=""),"",C18*D18) -> 45 | F18: {=IF($B$5="","",IFERROR(_xlfn.LET(_xlpm.v,INDEX(_xlfn._xlws.FILTER('04 Resource log'!$B$7:$B$506,('04 Resource log'!$A$7:$A$506=$B$5)*('04 Resource log'!$E$7:$E$506="Labour")),ROWS($A$15:A18)),IF(_xlpm.v="","",_xlpm.v)),""))} -> A1300
A19: {=IF($B$5="","",IFERROR(_xlfn.LET(_xlpm.v,INDEX(_xlfn._xlws.FILTER('04 Resource log'!$G$7:$G$506,('04 Resource log'!$A$7:$A$506=$B$5)*('04 Resource log'!$E$7:$E$506="Labour")),ROWS($A$15:A19)),IF(_xlpm.v="","",_xlpm.v)),""))} -> Main contractor | B19: {=IF($B$5="","",IFERROR(_xlfn.LET(_xlpm.v,INDEX(_xlfn._xlws.FILTER('04 Resource log'!$F$7:$F$506,('04 Resource log'!$A$7:$A$506=$B$5)*('04 Resource log'!$E$7:$E$506="Labour")),ROWS($A$15:A19)),IF(_xlpm.v="","",_xlpm.v)),""))} -> Supervision | C19: {=IF($B$5="","",IFERROR(_xlfn.LET(_xlpm.v,INDEX(_xlfn._xlws.FILTER('04 Resource log'!$H$7:$H$506,('04 Resource log'!$A$7:$A$506=$B$5)*('04 Resource log'!$E$7:$E$506="Labour")),ROWS($A$15:A19)),IF(_xlpm.v="","",_xlpm.v)),""))} -> 3 | D19: {=IF($B$5="","",IFERROR(_xlfn.LET(_xlpm.v,INDEX(_xlfn._xlws.FILTER('04 Resource log'!$I$7:$I$506,('04 Resource log'!$A$7:$A$506=$B$5)*('04 Resource log'!$E$7:$E$506="Labour")),ROWS($A$15:A19)),IF(_xlpm.v="","",_xlpm.v)),""))} -> 10 | E19: =IF(OR(C19="",D19=""),"",C19*D19) -> 30 | F19: {=IF($B$5="","",IFERROR(_xlfn.LET(_xlpm.v,INDEX(_xlfn._xlws.FILTER('04 Resource log'!$B$7:$B$506,('04 Resource log'!$A$7:$A$506=$B$5)*('04 Resource log'!$E$7:$E$506="Labour")),ROWS($A$15:A19)),IF(_xlpm.v="","",_xlpm.v)),""))} -> INDIRECT
A20: {=IF($B$5="","",IFERROR(_xlfn.LET(_xlpm.v,INDEX(_xlfn._xlws.FILTER('04 Resource log'!$G$7:$G$506,('04 Resource log'!$A$7:$A$506=$B$5)*('04 Resource log'!$E$7:$E$506="Labour")),ROWS($A$15:A20)),IF(_xlpm.v="","",_xlpm.v)),""))} | B20: {=IF($B$5="","",IFERROR(_xlfn.LET(_xlpm.v,INDEX(_xlfn._xlws.FILTER('04 Resource log'!$F$7:$F$506,('04 Resource log'!$A$7:$A$506=$B$5)*('04 Resource log'!$E$7:$E$506="Labour")),ROWS($A$15:A20)),IF(_xlpm.v="","",_xlpm.v)),""))} | C20: {=IF($B$5="","",IFERROR(_xlfn.LET(_xlpm.v,INDEX(_xlfn._xlws.FILTER('04 Resource log'!$H$7:$H$506,('04 Resource log'!$A$7:$A$506=$B$5)*('04 Resource log'!$E$7:$E$506="Labour")),ROWS($A$15:A20)),IF(_xlpm.v="","",_xlpm.v)),""))} | D20: {=IF($B$5="","",IFERROR(_xlfn.LET(_xlpm.v,INDEX(_xlfn._xlws.FILTER('04 Resource log'!$I$7:$I$506,('04 Resource log'!$A$7:$A$506=$B$5)*('04 Resource log'!$E$7:$E$506="Labour")),ROWS($A$15:A20)),IF(_xlpm.v="","",_xlpm.v)),""))} | E20: =IF(OR(C20="",D20=""),"",C20*D20) | F20: {=IF($B$5="","",IFERROR(_xlfn.LET(_xlpm.v,INDEX(_xlfn._xlws.FILTER('04 Resource log'!$B$7:$B$506,('04 Resource log'!$A$7:$A$506=$B$5)*('04 Resource log'!$E$7:$E$506="Labour")),ROWS($A$15:A20)),IF(_xlpm.v="","",_xlpm.v)),""))}
A21: {=IF($B$5="","",IFERROR(_xlfn.LET(_xlpm.v,INDEX(_xlfn._xlws.FILTER('04 Resource log'!$G$7:$G$506,('04 Resource log'!$A$7:$A$506=$B$5)*('04 Resource log'!$E$7:$E$506="Labour")),ROWS($A$15:A21)),IF(_xlpm.v="","",_xlpm.v)),""))} | B21: {=IF($B$5="","",IFERROR(_xlfn.LET(_xlpm.v,INDEX(_xlfn._xlws.FILTER('04 Resource log'!$F$7:$F$506,('04 Resource log'!$A$7:$A$506=$B$5)*('04 Resource log'!$E$7:$E$506="Labour")),ROWS($A$15:A21)),IF(_xlpm.v="","",_xlpm.v)),""))} | C21: {=IF($B$5="","",IFERROR(_xlfn.LET(_xlpm.v,INDEX(_xlfn._xlws.FILTER('04 Resource log'!$H$7:$H$506,('04 Resource log'!$A$7:$A$506=$B$5)*('04 Resource log'!$E$7:$E$506="Labour")),ROWS($A$15:A21)),IF(_xlpm.v="","",_xlpm.v)),""))} | D21: {=IF($B$5="","",IFERROR(_xlfn.LET(_xlpm.v,INDEX(_xlfn._xlws.FILTER('04 Resource log'!$I$7:$I$506,('04 Resource log'!$A$7:$A$506=$B$5)*('04 Resource log'!$E$7:$E$506="Labour")),ROWS($A$15:A21)),IF(_xlpm.v="","",_xlpm.v)),""))} | E21: =IF(OR(C21="",D21=""),"",C21*D21) | F21: {=IF($B$5="","",IFERROR(_xlfn.LET(_xlpm.v,INDEX(_xlfn._xlws.FILTER('04 Resource log'!$B$7:$B$506,('04 Resource log'!$A$7:$A$506=$B$5)*('04 Resource log'!$E$7:$E$506="Labour")),ROWS($A$15:A21)),IF(_xlpm.v="","",_xlpm.v)),""))}
A22: {=IF($B$5="","",IFERROR(_xlfn.LET(_xlpm.v,INDEX(_xlfn._xlws.FILTER('04 Resource log'!$G$7:$G$506,('04 Resource log'!$A$7:$A$506=$B$5)*('04 Resource log'!$E$7:$E$506="Labour")),ROWS($A$15:A22)),IF(_xlpm.v="","",_xlpm.v)),""))} | B22: {=IF($B$5="","",IFERROR(_xlfn.LET(_xlpm.v,INDEX(_xlfn._xlws.FILTER('04 Resource log'!$F$7:$F$506,('04 Resource log'!$A$7:$A$506=$B$5)*('04 Resource log'!$E$7:$E$506="Labour")),ROWS($A$15:A22)),IF(_xlpm.v="","",_xlpm.v)),""))} | C22: {=IF($B$5="","",IFERROR(_xlfn.LET(_xlpm.v,INDEX(_xlfn._xlws.FILTER('04 Resource log'!$H$7:$H$506,('04 Resource log'!$A$7:$A$506=$B$5)*('04 Resource log'!$E$7:$E$506="Labour")),ROWS($A$15:A22)),IF(_xlpm.v="","",_xlpm.v)),""))} | D22: {=IF($B$5="","",IFERROR(_xlfn.LET(_xlpm.v,INDEX(_xlfn._xlws.FILTER('04 Resource log'!$I$7:$I$506,('04 Resource log'!$A$7:$A$506=$B$5)*('04 Resource log'!$E$7:$E$506="Labour")),ROWS($A$15:A22)),IF(_xlpm.v="","",_xlpm.v)),""))} | E22: =IF(OR(C22="",D22=""),"",C22*D22) | F22: {=IF($B$5="","",IFERROR(_xlfn.LET(_xlpm.v,INDEX(_xlfn._xlws.FILTER('04 Resource log'!$B$7:$B$506,('04 Resource log'!$A$7:$A$506=$B$5)*('04 Resource log'!$E$7:$E$506="Labour")),ROWS($A$15:A22)),IF(_xlpm.v="","",_xlpm.v)),""))}
A23: {=IF($B$5="","",IFERROR(_xlfn.LET(_xlpm.v,INDEX(_xlfn._xlws.FILTER('04 Resource log'!$G$7:$G$506,('04 Resource log'!$A$7:$A$506=$B$5)*('04 Resource log'!$E$7:$E$506="Labour")),ROWS($A$15:A23)),IF(_xlpm.v="","",_xlpm.v)),""))} | B23: {=IF($B$5="","",IFERROR(_xlfn.LET(_xlpm.v,INDEX(_xlfn._xlws.FILTER('04 Resource log'!$F$7:$F$506,('04 Resource log'!$A$7:$A$506=$B$5)*('04 Resource log'!$E$7:$E$506="Labour")),ROWS($A$15:A23)),IF(_xlpm.v="","",_xlpm.v)),""))} | C23: {=IF($B$5="","",IFERROR(_xlfn.LET(_xlpm.v,INDEX(_xlfn._xlws.FILTER('04 Resource log'!$H$7:$H$506,('04 Resource log'!$A$7:$A$506=$B$5)*('04 Resource log'!$E$7:$E$506="Labour")),ROWS($A$15:A23)),IF(_xlpm.v="","",_xlpm.v)),""))} | D23: {=IF($B$5="","",IFERROR(_xlfn.LET(_xlpm.v,INDEX(_xlfn._xlws.FILTER('04 Resource log'!$I$7:$I$506,('04 Resource log'!$A$7:$A$506=$B$5)*('04 Resource log'!$E$7:$E$506="Labour")),ROWS($A$15:A23)),IF(_xlpm.v="","",_xlpm.v)),""))} | E23: =IF(OR(C23="",D23=""),"",C23*D23) | F23: {=IF($B$5="","",IFERROR(_xlfn.LET(_xlpm.v,INDEX(_xlfn._xlws.FILTER('04 Resource log'!$B$7:$B$506,('04 Resource log'!$A$7:$A$506=$B$5)*('04 Resource log'!$E$7:$E$506="Labour")),ROWS($A$15:A23)),IF(_xlpm.v="","",_xlpm.v)),""))}
A24: {=IF($B$5="","",IFERROR(_xlfn.LET(_xlpm.v,INDEX(_xlfn._xlws.FILTER('04 Resource log'!$G$7:$G$506,('04 Resource log'!$A$7:$A$506=$B$5)*('04 Resource log'!$E$7:$E$506="Labour")),ROWS($A$15:A24)),IF(_xlpm.v="","",_xlpm.v)),""))} | B24: {=IF($B$5="","",IFERROR(_xlfn.LET(_xlpm.v,INDEX(_xlfn._xlws.FILTER('04 Resource log'!$F$7:$F$506,('04 Resource log'!$A$7:$A$506=$B$5)*('04 Resource log'!$E$7:$E$506="Labour")),ROWS($A$15:A24)),IF(_xlpm.v="","",_xlpm.v)),""))} | C24: {=IF($B$5="","",IFERROR(_xlfn.LET(_xlpm.v,INDEX(_xlfn._xlws.FILTER('04 Resource log'!$H$7:$H$506,('04 Resource log'!$A$7:$A$506=$B$5)*('04 Resource log'!$E$7:$E$506="Labour")),ROWS($A$15:A24)),IF(_xlpm.v="","",_xlpm.v)),""))} | D24: {=IF($B$5="","",IFERROR(_xlfn.LET(_xlpm.v,INDEX(_xlfn._xlws.FILTER('04 Resource log'!$I$7:$I$506,('04 Resource log'!$A$7:$A$506=$B$5)*('04 Resource log'!$E$7:$E$506="Labour")),ROWS($A$15:A24)),IF(_xlpm.v="","",_xlpm.v)),""))} | E24: =IF(OR(C24="",D24=""),"",C24*D24) | F24: {=IF($B$5="","",IFERROR(_xlfn.LET(_xlpm.v,INDEX(_xlfn._xlws.FILTER('04 Resource log'!$B$7:$B$506,('04 Resource log'!$A$7:$A$506=$B$5)*('04 Resource log'!$E$7:$E$506="Labour")),ROWS($A$15:A24)),IF(_xlpm.v="","",_xlpm.v)),""))}
B25: Total on site | C25: =SUM(C15:C24) -> 28 | E25: =SUM(E15:E24) -> 255
A27: PLANT | H27: =IF($B$5="","",IF(COUNTIFS('04 Resource log'!$A$7:$A$506,$B$5,'04 Resource log'!$E$7:$E$506,"Plant")>8,"⚠ "&COUNTIFS('04 Resource log'!$A$7:$A$506,$B$5,'04 Resource log'!$E$7:$E$506,"Plant")&" lines in the Resource log: only 8 fit here",""))
A28: Plant | C28: On site | D28: Working | E28: Idle | F28: P6 Activity ID | G28: Hours each | H28: Why idle
A29: {=IF($B$5="","",IFERROR(_xlfn.LET(_xlpm.v,INDEX(_xlfn._xlws.FILTER('04 Resource log'!$F$7:$F$506,('04 Resource log'!$A$7:$A$506=$B$5)*('04 Resource log'!$E$7:$E$506="Plant")),ROWS($A$29:A29)),IF(_xlpm.v="","",_xlpm.v)),""))} -> Piling rig | C29: {=IF($B$5="","",IFERROR(_xlfn.LET(_xlpm.v,INDEX(_xlfn._xlws.FILTER('04 Resource log'!$K$7:$K$506,('04 Resource log'!$A$7:$A$506=$B$5)*('04 Resource log'!$E$7:$E$506="Plant")),ROWS($A$29:A29)),IF(_xlpm.v="","",_xlpm.v)),""))} -> 1 | D29: {=IF($B$5="","",IFERROR(_xlfn.LET(_xlpm.v,INDEX(_xlfn._xlws.FILTER('04 Resource log'!$H$7:$H$506,('04 Resource log'!$A$7:$A$506=$B$5)*('04 Resource log'!$E$7:$E$506="Plant")),ROWS($A$29:A29)),IF(_xlpm.v="","",_xlpm.v)),""))} -> 1 | E29: =IF(OR(C29="",D29=""),"",C29-D29) -> 0 | F29: {=IF($B$5="","",IFERROR(_xlfn.LET(_xlpm.v,INDEX(_xlfn._xlws.FILTER('04 Resource log'!$B$7:$B$506,('04 Resource log'!$A$7:$A$506=$B$5)*('04 Resource log'!$E$7:$E$506="Plant")),ROWS($A$29:A29)),IF(_xlpm.v="","",_xlpm.v)),""))} -> A1000 | G29: {=IF($B$5="","",IFERROR(_xlfn.LET(_xlpm.v,INDEX(_xlfn._xlws.FILTER('04 Resource log'!$I$7:$I$506,('04 Resource log'!$A$7:$A$506=$B$5)*('04 Resource log'!$E$7:$E$506="Plant")),ROWS($A$29:A29)),IF(_xlpm.v="","",_xlpm.v)),""))} -> 9 | H29: {=IF($B$5="","",IFERROR(_xlfn.LET(_xlpm.v,INDEX(_xlfn._xlws.FILTER('04 Resource log'!$L$7:$L$506,('04 Resource log'!$A$7:$A$506=$B$5)*('04 Resource log'!$E$7:$E$506="Plant")),ROWS($A$29:A29)),IF(_xlpm.v="","",_xlpm.v)),""))}
A30: {=IF($B$5="","",IFERROR(_xlfn.LET(_xlpm.v,INDEX(_xlfn._xlws.FILTER('04 Resource log'!$F$7:$F$506,('04 Resource log'!$A$7:$A$506=$B$5)*('04 Resource log'!$E$7:$E$506="Plant")),ROWS($A$29:A30)),IF(_xlpm.v="","",_xlpm.v)),""))} -> Crawler crane | C30: {=IF($B$5="","",IFERROR(_xlfn.LET(_xlpm.v,INDEX(_xlfn._xlws.FILTER('04 Resource log'!$K$7:$K$506,('04 Resource log'!$A$7:$A$506=$B$5)*('04 Resource log'!$E$7:$E$506="Plant")),ROWS($A$29:A30)),IF(_xlpm.v="","",_xlpm.v)),""))} -> 1 | D30: {=IF($B$5="","",IFERROR(_xlfn.LET(_xlpm.v,INDEX(_xlfn._xlws.FILTER('04 Resource log'!$H$7:$H$506,('04 Resource log'!$A$7:$A$506=$B$5)*('04 Resource log'!$E$7:$E$506="Plant")),ROWS($A$29:A30)),IF(_xlpm.v="","",_xlpm.v)),""))} -> 1 | E30: =IF(OR(C30="",D30=""),"",C30-D30) -> 0 | F30: {=IF($B$5="","",IFERROR(_xlfn.LET(_xlpm.v,INDEX(_xlfn._xlws.FILTER('04 Resource log'!$B$7:$B$506,('04 Resource log'!$A$7:$A$506=$B$5)*('04 Resource log'!$E$7:$E$506="Plant")),ROWS($A$29:A30)),IF(_xlpm.v="","",_xlpm.v)),""))} -> A1100 | G30: {=IF($B$5="","",IFERROR(_xlfn.LET(_xlpm.v,INDEX(_xlfn._xlws.FILTER('04 Resource log'!$I$7:$I$506,('04 Resource log'!$A$7:$A$506=$B$5)*('04 Resource log'!$E$7:$E$506="Plant")),ROWS($A$29:A30)),IF(_xlpm.v="","",_xlpm.v)),""))} -> 9 | H30: {=IF($B$5="","",IFERROR(_xlfn.LET(_xlpm.v,INDEX(_xlfn._xlws.FILTER('04 Resource log'!$L$7:$L$506,('04 Resource log'!$A$7:$A$506=$B$5)*('04 Resource log'!$E$7:$E$506="Plant")),ROWS($A$29:A30)),IF(_xlpm.v="","",_xlpm.v)),""))}
A31: {=IF($B$5="","",IFERROR(_xlfn.LET(_xlpm.v,INDEX(_xlfn._xlws.FILTER('04 Resource log'!$F$7:$F$506,('04 Resource log'!$A$7:$A$506=$B$5)*('04 Resource log'!$E$7:$E$506="Plant")),ROWS($A$29:A31)),IF(_xlpm.v="","",_xlpm.v)),""))} -> Excavator | C31: {=IF($B$5="","",IFERROR(_xlfn.LET(_xlpm.v,INDEX(_xlfn._xlws.FILTER('04 Resource log'!$K$7:$K$506,('04 Resource log'!$A$7:$A$506=$B$5)*('04 Resource log'!$E$7:$E$506="Plant")),ROWS($A$29:A31)),IF(_xlpm.v="","",_xlpm.v)),""))} -> 2 | D31: {=IF($B$5="","",IFERROR(_xlfn.LET(_xlpm.v,INDEX(_xlfn._xlws.FILTER('04 Resource log'!$H$7:$H$506,('04 Resource log'!$A$7:$A$506=$B$5)*('04 Resource log'!$E$7:$E$506="Plant")),ROWS($A$29:A31)),IF(_xlpm.v="","",_xlpm.v)),""))} -> 1 | E31: =IF(OR(C31="",D31=""),"",C31-D31) -> 1 | F31: {=IF($B$5="","",IFERROR(_xlfn.LET(_xlpm.v,INDEX(_xlfn._xlws.FILTER('04 Resource log'!$B$7:$B$506,('04 Resource log'!$A$7:$A$506=$B$5)*('04 Resource log'!$E$7:$E$506="Plant")),ROWS($A$29:A31)),IF(_xlpm.v="","",_xlpm.v)),""))} -> A1300 | G31: {=IF($B$5="","",IFERROR(_xlfn.LET(_xlpm.v,INDEX(_xlfn._xlws.FILTER('04 Resource log'!$I$7:$I$506,('04 Resource log'!$A$7:$A$506=$B$5)*('04 Resource log'!$E$7:$E$506="Plant")),ROWS($A$29:A31)),IF(_xlpm.v="","",_xlpm.v)),""))} -> 9 | H31: {=IF($B$5="","",IFERROR(_xlfn.LET(_xlpm.v,INDEX(_xlfn._xlws.FILTER('04 Resource log'!$L$7:$L$506,('04 Resource log'!$A$7:$A$506=$B$5)*('04 Resource log'!$E$7:$E$506="Plant")),ROWS($A$29:A31)),IF(_xlpm.v="","",_xlpm.v)),""))} -> No operator
A32: {=IF($B$5="","",IFERROR(_xlfn.LET(_xlpm.v,INDEX(_xlfn._xlws.FILTER('04 Resource log'!$F$7:$F$506,('04 Resource log'!$A$7:$A$506=$B$5)*('04 Resource log'!$E$7:$E$506="Plant")),ROWS($A$29:A32)),IF(_xlpm.v="","",_xlpm.v)),""))} -> Concrete pump | C32: {=IF($B$5="","",IFERROR(_xlfn.LET(_xlpm.v,INDEX(_xlfn._xlws.FILTER('04 Resource log'!$K$7:$K$506,('04 Resource log'!$A$7:$A$506=$B$5)*('04 Resource log'!$E$7:$E$506="Plant")),ROWS($A$29:A32)),IF(_xlpm.v="","",_xlpm.v)),""))} -> 1 | D32: {=IF($B$5="","",IFERROR(_xlfn.LET(_xlpm.v,INDEX(_xlfn._xlws.FILTER('04 Resource log'!$H$7:$H$506,('04 Resource log'!$A$7:$A$506=$B$5)*('04 Resource log'!$E$7:$E$506="Plant")),ROWS($A$29:A32)),IF(_xlpm.v="","",_xlpm.v)),""))} -> 0 | E32: =IF(OR(C32="",D32=""),"",C32-D32) -> 1 | F32: {=IF($B$5="","",IFERROR(_xlfn.LET(_xlpm.v,INDEX(_xlfn._xlws.FILTER('04 Resource log'!$B$7:$B$506,('04 Resource log'!$A$7:$A$506=$B$5)*('04 Resource log'!$E$7:$E$506="Plant")),ROWS($A$29:A32)),IF(_xlpm.v="","",_xlpm.v)),""))} -> A1200 | G32: {=IF($B$5="","",IFERROR(_xlfn.LET(_xlpm.v,INDEX(_xlfn._xlws.FILTER('04 Resource log'!$I$7:$I$506,('04 Resource log'!$A$7:$A$506=$B$5)*('04 Resource log'!$E$7:$E$506="Plant")),ROWS($A$29:A32)),IF(_xlpm.v="","",_xlpm.v)),""))} -> 0 | H32: {=IF($B$5="","",IFERROR(_xlfn.LET(_xlpm.v,INDEX(_xlfn._xlws.FILTER('04 Resource log'!$L$7:$L$506,('04 Resource log'!$A$7:$A$506=$B$5)*('04 Resource log'!$E$7:$E$506="Plant")),ROWS($A$29:A32)),IF(_xlpm.v="","",_xlpm.v)),""))} -> Standby
A33: {=IF($B$5="","",IFERROR(_xlfn.LET(_xlpm.v,INDEX(_xlfn._xlws.FILTER('04 Resource log'!$F$7:$F$506,('04 Resource log'!$A$7:$A$506=$B$5)*('04 Resource log'!$E$7:$E$506="Plant")),ROWS($A$29:A33)),IF(_xlpm.v="","",_xlpm.v)),""))} | C33: {=IF($B$5="","",IFERROR(_xlfn.LET(_xlpm.v,INDEX(_xlfn._xlws.FILTER('04 Resource log'!$K$7:$K$506,('04 Resource log'!$A$7:$A$506=$B$5)*('04 Resource log'!$E$7:$E$506="Plant")),ROWS($A$29:A33)),IF(_xlpm.v="","",_xlpm.v)),""))} | D33: {=IF($B$5="","",IFERROR(_xlfn.LET(_xlpm.v,INDEX(_xlfn._xlws.FILTER('04 Resource log'!$H$7:$H$506,('04 Resource log'!$A$7:$A$506=$B$5)*('04 Resource log'!$E$7:$E$506="Plant")),ROWS($A$29:A33)),IF(_xlpm.v="","",_xlpm.v)),""))} | E33: =IF(OR(C33="",D33=""),"",C33-D33) | F33: {=IF($B$5="","",IFERROR(_xlfn.LET(_xlpm.v,INDEX(_xlfn._xlws.FILTER('04 Resource log'!$B$7:$B$506,('04 Resource log'!$A$7:$A$506=$B$5)*('04 Resource log'!$E$7:$E$506="Plant")),ROWS($A$29:A33)),IF(_xlpm.v="","",_xlpm.v)),""))} | G33: {=IF($B$5="","",IFERROR(_xlfn.LET(_xlpm.v,INDEX(_xlfn._xlws.FILTER('04 Resource log'!$I$7:$I$506,('04 Resource log'!$A$7:$A$506=$B$5)*('04 Resource log'!$E$7:$E$506="Plant")),ROWS($A$29:A33)),IF(_xlpm.v="","",_xlpm.v)),""))} | H33: {=IF($B$5="","",IFERROR(_xlfn.LET(_xlpm.v,INDEX(_xlfn._xlws.FILTER('04 Resource log'!$L$7:$L$506,('04 Resource log'!$A$7:$A$506=$B$5)*('04 Resource log'!$E$7:$E$506="Plant")),ROWS($A$29:A33)),IF(_xlpm.v="","",_xlpm.v)),""))}
A34: {=IF($B$5="","",IFERROR(_xlfn.LET(_xlpm.v,INDEX(_xlfn._xlws.FILTER('04 Resource log'!$F$7:$F$506,('04 Resource log'!$A$7:$A$506=$B$5)*('04 Resource log'!$E$7:$E$506="Plant")),ROWS($A$29:A34)),IF(_xlpm.v="","",_xlpm.v)),""))} | C34: {=IF($B$5="","",IFERROR(_xlfn.LET(_xlpm.v,INDEX(_xlfn._xlws.FILTER('04 Resource log'!$K$7:$K$506,('04 Resource log'!$A$7:$A$506=$B$5)*('04 Resource log'!$E$7:$E$506="Plant")),ROWS($A$29:A34)),IF(_xlpm.v="","",_xlpm.v)),""))} | D34: {=IF($B$5="","",IFERROR(_xlfn.LET(_xlpm.v,INDEX(_xlfn._xlws.FILTER('04 Resource log'!$H$7:$H$506,('04 Resource log'!$A$7:$A$506=$B$5)*('04 Resource log'!$E$7:$E$506="Plant")),ROWS($A$29:A34)),IF(_xlpm.v="","",_xlpm.v)),""))} | E34: =IF(OR(C34="",D34=""),"",C34-D34) | F34: {=IF($B$5="","",IFERROR(_xlfn.LET(_xlpm.v,INDEX(_xlfn._xlws.FILTER('04 Resource log'!$B$7:$B$506,('04 Resource log'!$A$7:$A$506=$B$5)*('04 Resource log'!$E$7:$E$506="Plant")),ROWS($A$29:A34)),IF(_xlpm.v="","",_xlpm.v)),""))} | G34: {=IF($B$5="","",IFERROR(_xlfn.LET(_xlpm.v,INDEX(_xlfn._xlws.FILTER('04 Resource log'!$I$7:$I$506,('04 Resource log'!$A$7:$A$506=$B$5)*('04 Resource log'!$E$7:$E$506="Plant")),ROWS($A$29:A34)),IF(_xlpm.v="","",_xlpm.v)),""))} | H34: {=IF($B$5="","",IFERROR(_xlfn.LET(_xlpm.v,INDEX(_xlfn._xlws.FILTER('04 Resource log'!$L$7:$L$506,('04 Resource log'!$A$7:$A$506=$B$5)*('04 Resource log'!$E$7:$E$506="Plant")),ROWS($A$29:A34)),IF(_xlpm.v="","",_xlpm.v)),""))}
A35: {=IF($B$5="","",IFERROR(_xlfn.LET(_xlpm.v,INDEX(_xlfn._xlws.FILTER('04 Resource log'!$F$7:$F$506,('04 Resource log'!$A$7:$A$506=$B$5)*('04 Resource log'!$E$7:$E$506="Plant")),ROWS($A$29:A35)),IF(_xlpm.v="","",_xlpm.v)),""))} | C35: {=IF($B$5="","",IFERROR(_xlfn.LET(_xlpm.v,INDEX(_xlfn._xlws.FILTER('04 Resource log'!$K$7:$K$506,('04 Resource log'!$A$7:$A$506=$B$5)*('04 Resource log'!$E$7:$E$506="Plant")),ROWS($A$29:A35)),IF(_xlpm.v="","",_xlpm.v)),""))} | D35: {=IF($B$5="","",IFERROR(_xlfn.LET(_xlpm.v,INDEX(_xlfn._xlws.FILTER('04 Resource log'!$H$7:$H$506,('04 Resource log'!$A$7:$A$506=$B$5)*('04 Resource log'!$E$7:$E$506="Plant")),ROWS($A$29:A35)),IF(_xlpm.v="","",_xlpm.v)),""))} | E35: =IF(OR(C35="",D35=""),"",C35-D35) | F35: {=IF($B$5="","",IFERROR(_xlfn.LET(_xlpm.v,INDEX(_xlfn._xlws.FILTER('04 Resource log'!$B$7:$B$506,('04 Resource log'!$A$7:$A$506=$B$5)*('04 Resource log'!$E$7:$E$506="Plant")),ROWS($A$29:A35)),IF(_xlpm.v="","",_xlpm.v)),""))} | G35: {=IF($B$5="","",IFERROR(_xlfn.LET(_xlpm.v,INDEX(_xlfn._xlws.FILTER('04 Resource log'!$I$7:$I$506,('04 Resource log'!$A$7:$A$506=$B$5)*('04 Resource log'!$E$7:$E$506="Plant")),ROWS($A$29:A35)),IF(_xlpm.v="","",_xlpm.v)),""))} | H35: {=IF($B$5="","",IFERROR(_xlfn.LET(_xlpm.v,INDEX(_xlfn._xlws.FILTER('04 Resource log'!$L$7:$L$506,('04 Resource log'!$A$7:$A$506=$B$5)*('04 Resource log'!$E$7:$E$506="Plant")),ROWS($A$29:A35)),IF(_xlpm.v="","",_xlpm.v)),""))}
A36: {=IF($B$5="","",IFERROR(_xlfn.LET(_xlpm.v,INDEX(_xlfn._xlws.FILTER('04 Resource log'!$F$7:$F$506,('04 Resource log'!$A$7:$A$506=$B$5)*('04 Resource log'!$E$7:$E$506="Plant")),ROWS($A$29:A36)),IF(_xlpm.v="","",_xlpm.v)),""))} | C36: {=IF($B$5="","",IFERROR(_xlfn.LET(_xlpm.v,INDEX(_xlfn._xlws.FILTER('04 Resource log'!$K$7:$K$506,('04 Resource log'!$A$7:$A$506=$B$5)*('04 Resource log'!$E$7:$E$506="Plant")),ROWS($A$29:A36)),IF(_xlpm.v="","",_xlpm.v)),""))} | D36: {=IF($B$5="","",IFERROR(_xlfn.LET(_xlpm.v,INDEX(_xlfn._xlws.FILTER('04 Resource log'!$H$7:$H$506,('04 Resource log'!$A$7:$A$506=$B$5)*('04 Resource log'!$E$7:$E$506="Plant")),ROWS($A$29:A36)),IF(_xlpm.v="","",_xlpm.v)),""))} | E36: =IF(OR(C36="",D36=""),"",C36-D36) | F36: {=IF($B$5="","",IFERROR(_xlfn.LET(_xlpm.v,INDEX(_xlfn._xlws.FILTER('04 Resource log'!$B$7:$B$506,('04 Resource log'!$A$7:$A$506=$B$5)*('04 Resource log'!$E$7:$E$506="Plant")),ROWS($A$29:A36)),IF(_xlpm.v="","",_xlpm.v)),""))} | G36: {=IF($B$5="","",IFERROR(_xlfn.LET(_xlpm.v,INDEX(_xlfn._xlws.FILTER('04 Resource log'!$I$7:$I$506,('04 Resource log'!$A$7:$A$506=$B$5)*('04 Resource log'!$E$7:$E$506="Plant")),ROWS($A$29:A36)),IF(_xlpm.v="","",_xlpm.v)),""))} | H36: {=IF($B$5="","",IFERROR(_xlfn.LET(_xlpm.v,INDEX(_xlfn._xlws.FILTER('04 Resource log'!$L$7:$L$506,('04 Resource log'!$A$7:$A$506=$B$5)*('04 Resource log'!$E$7:$E$506="Plant")),ROWS($A$29:A36)),IF(_xlpm.v="","",_xlpm.v)),""))}
B37: Working | D37: =SUM(D29:D36) -> 3 | E37: =SUM(E29:E36) -> 2 | G37: =SUMPRODUCT(D29:D36,G29:G36) -> 27 | H37: machine-hours
A39: WORK DONE | H39: =IF($B$5="","",IF(COUNTIFS('05 Work done log'!$A$7:$A$506,$B$5)>12,"⚠ "&COUNTIFS('05 Work done log'!$A$7:$A$506,$B$5)&" lines in the Work done log: only 12 fit here",""))
A40: P6 Activity ID | B40: Activity | C40: Location | D40: Quantity | E40: Unit | F40: Source | G40: Comment
A41: {=IF($B$5="","",IFERROR(_xlfn.LET(_xlpm.v,INDEX(_xlfn._xlws.FILTER('05 Work done log'!$B$7:$B$506,'05 Work done log'!$A$7:$A$506=$B$5),ROWS($A$41:A41)),IF(_xlpm.v="","",_xlpm.v)),""))} -> A1000 | B41: =IF(A41="","",IFERROR(INDEX('12 P6 activities'!$B$7:$B$206,MATCH(A41,'12 P6 activities'!$A$7:$A$206,0)),"ID not in P6 list")) -> Bored piles, north | C41: {=IF($B$5="","",IFERROR(_xlfn.LET(_xlpm.v,INDEX(_xlfn._xlws.FILTER('05 Work done log'!$E$7:$E$506,'05 Work done log'!$A$7:$A$506=$B$5),ROWS($A$41:A41)),IF(_xlpm.v="","",_xlpm.v)),""))} -> North piling area | D41: {=IF($B$5="","",IFERROR(_xlfn.LET(_xlpm.v,INDEX(_xlfn._xlws.FILTER('05 Work done log'!$F$7:$F$506,'05 Work done log'!$A$7:$A$506=$B$5),ROWS($A$41:A41)),IF(_xlpm.v="","",_xlpm.v)),""))} -> 2 | E41: =IF(A41="","",IFERROR(INDEX('12 P6 activities'!$E$7:$E$206,MATCH(A41,'12 P6 activities'!$A$7:$A$206,0)),"")) -> no. | F41: {=IF($B$5="","",IFERROR(_xlfn.LET(_xlpm.v,INDEX(_xlfn._xlws.FILTER('05 Work done log'!$H$7:$H$506,'05 Work done log'!$A$7:$A$506=$B$5),ROWS($A$41:A41)),IF(_xlpm.v="","",_xlpm.v)),""))} -> Counted | G41: {=IF($B$5="","",IFERROR(_xlfn.LET(_xlpm.v,INDEX(_xlfn._xlws.FILTER('05 Work done log'!$I$7:$I$506,'05 Work done log'!$A$7:$A$506=$B$5),ROWS($A$41:A41)),IF(_xlpm.v="","",_xlpm.v)),""))} -> P17, P18. Penetration rate changed: see events
A42: {=IF($B$5="","",IFERROR(_xlfn.LET(_xlpm.v,INDEX(_xlfn._xlws.FILTER('05 Work done log'!$B$7:$B$506,'05 Work done log'!$A$7:$A$506=$B$5),ROWS($A$41:A42)),IF(_xlpm.v="","",_xlpm.v)),""))} -> A1100 | B42: =IF(A42="","",IFERROR(INDEX('12 P6 activities'!$B$7:$B$206,MATCH(A42,'12 P6 activities'!$A$7:$A$206,0)),"ID not in P6 list")) -> Raft reinforcement, bay 1 | C42: {=IF($B$5="","",IFERROR(_xlfn.LET(_xlpm.v,INDEX(_xlfn._xlws.FILTER('05 Work done log'!$E$7:$E$506,'05 Work done log'!$A$7:$A$506=$B$5),ROWS($A$41:A42)),IF(_xlpm.v="","",_xlpm.v)),""))} -> Raft bay 1 | D42: {=IF($B$5="","",IFERROR(_xlfn.LET(_xlpm.v,INDEX(_xlfn._xlws.FILTER('05 Work done log'!$F$7:$F$506,'05 Work done log'!$A$7:$A$506=$B$5),ROWS($A$41:A42)),IF(_xlpm.v="","",_xlpm.v)),""))} -> 3.5 | E42: =IF(A42="","",IFERROR(INDEX('12 P6 activities'!$E$7:$E$206,MATCH(A42,'12 P6 activities'!$A$7:$A$206,0)),"")) -> t | F42: {=IF($B$5="","",IFERROR(_xlfn.LET(_xlpm.v,INDEX(_xlfn._xlws.FILTER('05 Work done log'!$H$7:$H$506,'05 Work done log'!$A$7:$A$506=$B$5),ROWS($A$41:A42)),IF(_xlpm.v="","",_xlpm.v)),""))} -> Counted | G42: {=IF($B$5="","",IFERROR(_xlfn.LET(_xlpm.v,INDEX(_xlfn._xlws.FILTER('05 Work done log'!$I$7:$I$506,'05 Work done log'!$A$7:$A$506=$B$5),ROWS($A$41:A42)),IF(_xlpm.v="","",_xlpm.v)),""))} -> About 16 hours a tonne
A43: {=IF($B$5="","",IFERROR(_xlfn.LET(_xlpm.v,INDEX(_xlfn._xlws.FILTER('05 Work done log'!$B$7:$B$506,'05 Work done log'!$A$7:$A$506=$B$5),ROWS($A$41:A43)),IF(_xlpm.v="","",_xlpm.v)),""))} -> A1200 | B43: =IF(A43="","",IFERROR(INDEX('12 P6 activities'!$B$7:$B$206,MATCH(A43,'12 P6 activities'!$A$7:$A$206,0)),"ID not in P6 list")) -> Blinding, substation slab | C43: {=IF($B$5="","",IFERROR(_xlfn.LET(_xlpm.v,INDEX(_xlfn._xlws.FILTER('05 Work done log'!$E$7:$E$506,'05 Work done log'!$A$7:$A$506=$B$5),ROWS($A$41:A43)),IF(_xlpm.v="","",_xlpm.v)),""))} -> Substation slab | D43: {=IF($B$5="","",IFERROR(_xlfn.LET(_xlpm.v,INDEX(_xlfn._xlws.FILTER('05 Work done log'!$F$7:$F$506,'05 Work done log'!$A$7:$A$506=$B$5),ROWS($A$41:A43)),IF(_xlpm.v="","",_xlpm.v)),""))} -> 38 | E43: =IF(A43="","",IFERROR(INDEX('12 P6 activities'!$E$7:$E$206,MATCH(A43,'12 P6 activities'!$A$7:$A$206,0)),"")) -> m² | F43: {=IF($B$5="","",IFERROR(_xlfn.LET(_xlpm.v,INDEX(_xlfn._xlws.FILTER('05 Work done log'!$H$7:$H$506,'05 Work done log'!$A$7:$A$506=$B$5),ROWS($A$41:A43)),IF(_xlpm.v="","",_xlpm.v)),""))} -> Counted | G43: {=IF($B$5="","",IFERROR(_xlfn.LET(_xlpm.v,INDEX(_xlfn._xlws.FILTER('05 Work done log'!$I$7:$I$506,'05 Work done log'!$A$7:$A$506=$B$5),ROWS($A$41:A43)),IF(_xlpm.v="","",_xlpm.v)),""))} -> Survey completed next morning (revision 1)
...

Sheet 02 Dashboard
B2: Daily reports | K2: The Project Control Hub
B3: =IF(COUNT('03 Day log'!$A$8:$A$38)=0,"Log your first day on the Day log",IF('14 Setup'!B6="","",'14 Setup'!B6&" · ")&"weekly view · log runs "&TEXT(MIN('03 Day log'!$A$8:$A$38),"d mmm")&" to "&TEXT(MAX('03 Day log'!$A$8:$A$38),"d mmm yyyy")&" · due by "&TEXT('14 Setup'!B7,"hh:mm")) -> Example project · weekly view · log runs 2 Mar to 13 Mar 2026 · due by 14:00
B4: WEEK | C4: 1 | E4: =IF(WeekStart="","","Mon "&TEXT(WeekStart,"d mmm")&" to Sun "&TEXT(WeekEnd,"d mmm yyyy")&" · week "&WeekNo&" of "&'15 Chart data'!$C$20&" · "&WeekReports&" reports") -> Mon 2 Mar to Sun 8 Mar 2026 · week 1 of 2 · 5 reports
B6: REPORTS ON TIME | D6: NEVER REVISED | F6: WORKING DAYS LOST | H6: AVERAGE ON SITE | J6: RAISED, NOT REPORTED | L6: POSSIBLE CLAIMS
B7: =IF(WeekReports=0,"",COUNTIFS('03 Day log'!$D$8:$D$38,"Y",'03 Day log'!$A$8:$A$38,">="&WeekStart,'03 Day log'!$A$8:$A$38,"<="&WeekEnd)/WeekReports) -> 0.8 | D7: =IF(WeekReports=0,"",COUNTIFS('03 Day log'!$E$8:$E$38,0,'03 Day log'!$A$8:$A$38,">="&WeekStart,'03 Day log'!$A$8:$A$38,"<="&WeekEnd)/WeekReports) -> 0.6 | F7: =COUNTIFS('03 Day log'!$G$8:$G$38,"Lost",'03 Day log'!$A$8:$A$38,">="&WeekStart,'03 Day log'!$A$8:$A$38,"<="&WeekEnd)+'14 Setup'!$B$9*COUNTIFS('03 Day log'!$G$8:$G$38,"Part lost",'03 Day log'!$A$8:$A$38,">="&WeekStart,'03 Day log'!$A$8:$A$38,"<="&WeekEnd) -> 2 | H7: =IF(WeekReports=0,"",AVERAGEIFS('03 Day log'!$H$8:$H$38,'03 Day log'!$A$8:$A$38,">="&WeekStart,'03 Day log'!$A$8:$A$38,"<="&WeekEnd)) -> 22.6 | J7: =COUNTIFS('09 Not yet reported'!$H$7:$H$46,"Open",'09 Not yet reported'!$A$7:$A$46,">="&WeekStart,'09 Not yet reported'!$A$7:$A$46,"<="&WeekEnd)+COUNTIFS('09 Not yet reported'!$H$7:$H$46,"Overdue",'09 Not yet reported'!$A$7:$A$46,">="&WeekStart,'09 Not yet reported'!$A$7:$A$46,"<="&WeekEnd) -> 2 | L7: =SUMIFS('03 Day log'!$K$8:$K$38,'03 Day log'!$A$8:$A$38,">="&WeekStart,'03 Day log'!$A$8:$A$38,"<="&WeekEnd) -> 2
B9: =COUNTIFS('03 Day log'!$D$8:$D$38,"N",'03 Day log'!$A$8:$A$38,">="&WeekStart,'03 Day log'!$A$8:$A$38,"<="&WeekEnd)&" late" -> 1 late | D9: ="the measure that matters · "&SUMIFS('03 Day log'!$E$8:$E$38,'03 Day log'!$A$8:$A$38,">="&WeekStart,'03 Day log'!$A$8:$A$38,"<="&WeekEnd)&" revisions" -> the measure that matters · 3 revisions | F9: =COUNTIFS('03 Day log'!$G$8:$G$38,"Lost",'03 Day log'!$A$8:$A$38,">="&WeekStart,'03 Day log'!$A$8:$A$38,"<="&WeekEnd)&" lost, "&COUNTIFS('03 Day log'!$G$8:$G$38,"Part lost",'03 Day log'!$A$8:$A$38,">="&WeekStart,'03 Day log'!$A$8:$A$38,"<="&WeekEnd)&" part lost" -> 1 lost, 2 part lost | H9: ="people a day · peak "&IF(WeekReports=0,0,_xlfn.MAXIFS('03 Day log'!$H$8:$H$38,'03 Day log'!$A$8:$A$38,">="&WeekStart,'03 Day log'!$A$8:$A$38,"<="&WeekEnd)) -> people a day · peak 28 | J9: ="raised this week · "&(COUNTIF('09 Not yet reported'!$H$7:$H$46,"Open")+COUNTIF('09 Not yet reported'!$H$7:$H$46,"Overdue"))&" open in total" -> raised this week · 2 open in total | L9: ="notices: "&COUNTIF('11 Notice calendar'!$G$7:$G$46,"Open")&" open, "&COUNTIF('11 Notice calendar'!$G$7:$G$46,"Overdue")&" overdue" -> notices: 2 open, 0 overdue
B12: =IF(WeekReports=0,"No reports logged for this week.","This week, of "&WeekReports&" reports, "&COUNTIFS('03 Day log'!$D$8:$D$38,"Y",'03 Day log'!$A$8:$A$38,">="&WeekStart,'03 Day log'!$A$8:$A$38,"<="&WeekEnd)&" went out on time and "&COUNTIFS('03 Day log'!$E$8:$E$38,0,'03 Day log'!$A$8:$A$38,">="&WeekStart,'03 Day log'!$A$8:$A$38,"<="&WeekEnd)&" never changed afterwards. Judge the report by the second number: a report that stands is worth more than one that arrives early and is corrected three times.") -> This week, of 5 reports, 4 went out on time and 3 never changed afterwards. Judge the report by the second number: a report that stands is worth more than one that arrives early and is corrected three times.
B15: THE WEEK IN FOUR CHARTS
B50: WHAT THIS WEEK’S REPORTS RECORD · the evidence a claim will ask for later
B51: Date | C51: Working day | D51: People | E51: Revisions | F51: Claims | G51: Key event
B52: ='15 Chart data'!$B26 -> 46083 | C52: ='15 Chart data'!$G26 -> Workable | D52: =IF('15 Chart data'!$D26="","",'15 Chart data'!$D26) -> 26 | E52: =IFERROR(IF('15 Chart data'!$E26="","",'15 Chart data'!$E26),"") -> 0 | F52: ='15 Chart data'!$H26 -> 0 | G52: =IF('15 Chart data'!$G26="","no report",'15 Chart data'!$I26) -> Piling P15 and P16
B53: ='15 Chart data'!$B27 -> 46084 | C53: ='15 Chart data'!$G27 -> Part lost | D53: =IF('15 Chart data'!$D27="","",'15 Chart data'!$D27) -> 28 | E53: =IFERROR(IF('15 Chart data'!$E27="","",'15 Chart data'!$E27),"") -> 1 | F53: ='15 Chart data'!$H27 -> 2 | G53: =IF('15 Chart data'!$G27="","no report",'15 Chart data'!$I27) -> Piling rig: penetration rate changed at P17 and P18, consistent with rock. Driller’s log kept.
B54: ='15 Chart data'!$B28 -> 46085 | C54: ='15 Chart data'!$G28 -> Part lost | D54: =IF('15 Chart data'!$D28="","",'15 Chart data'!$D28) -> 22 | E54: =IFERROR(IF('15 Chart data'!$E28="","",'15 Chart data'!$E28),"") -> 0 | F54: ='15 Chart data'!$H28 -> 0 | G54: =IF('15 Chart data'!$G28="","no report",'15 Chart data'!$I28) -> Bar schedule revision for bay 2 requested
B55: ='15 Chart data'!$B29 -> 46086 | C55: ='15 Chart data'!$G29 -> Lost | D55: =IF('15 Chart data'!$D29="","",'15 Chart data'!$D29) -> 10 | E55: =IFERROR(IF('15 Chart data'!$E29="","",'15 Chart data'!$E29),"") -> 2 | F55: ='15 Chart data'!$H29 -> 0 | G55: =IF('15 Chart data'!$G29="","no report",'15 Chart data'!$I29) -> No pours: heavy rain
B56: ='15 Chart data'!$B30 -> 46087 | C56: ='15 Chart data'!$G30 -> Workable | D56: =IF('15 Chart data'!$D30="","",'15 Chart data'!$D30) -> 27 | E56: =IFERROR(IF('15 Chart data'!$E30="","",'15 Chart data'!$E30),"") -> 0 | F56: ='15 Chart data'!$H30 -> 0 | G56: =IF('15 Chart data'!$G30="","no report",'15 Chart data'!$I30) -> Crane booked for 17 March
B57: ='15 Chart data'!$B31 -> 46088 | C57: ='15 Chart data'!$G31 | D57: =IF('15 Chart data'!$D31="","",'15 Chart data'!$D31) | E57: =IFERROR(IF('15 Chart data'!$E31="","",'15 Chart data'!$E31),"") | F57: ='15 Chart data'!$H31 | G57: =IF('15 Chart data'!$G31="","no report",'15 Chart data'!$I31) -> no report
B58: ='15 Chart data'!$B32 -> 46089 | C58: ='15 Chart data'!$G32 | D58: =IF('15 Chart data'!$D32="","",'15 Chart data'!$D32) | E58: =IFERROR(IF('15 Chart data'!$E32="","",'15 Chart data'!$E32),"") | F58: ='15 Chart data'!$H32 | G58: =IF('15 Chart data'!$G32="","no report",'15 Chart data'!$I32) -> no report
B61: WORK DONE THIS WEEK · quantities by P6 activity, from the Work done log
B62: P6 ID | C62: Activity | E62: Unit | F62: =WeekStart -> 46083 | G62: =IF(F62="","",F62+1) -> 46084 | H62: =IF(G62="","",G62+1) -> 46085 | I62: =IF(H62="","",H62+1) -> 46086 | J62: =IF(I62="","",I62+1) -> 46087 | K62: =IF(J62="","",J62+1) -> 46088 | L62: =IF(K62="","",K62+1) -> 46089 | M62: Week total
B63: {=IFERROR(INDEX(_xlfn._xlws.SORT(_xlfn.UNIQUE(_xlfn._xlws.FILTER('05 Work done log'!$B$7:$B$506,('05 Work done log'!$A$7:$A$506>=WeekStart)*('05 Work done log'!$A$7:$A$506<=WeekEnd)*('05 Work done log'!$B$7:$B$506<>"")))),ROWS($B$63:B63)),"")} -> A1000 | C63: =IF($B63="","",IFERROR(INDEX('12 P6 activities'!$B$7:$B$206,MATCH($B63,'12 P6 activities'!$A$7:$A$206,0)),"ID not in P6 list")) -> Bored piles, north | E63: =IF($B63="","",IFERROR(INDEX('12 P6 activities'!$E$7:$E$206,MATCH($B63,'12 P6 activities'!$A$7:$A$206,0)),"")) -> no. | F63: =IF($B63="","",SUMIFS('05 Work done log'!$F$7:$F$506,'05 Work done log'!$B$7:$B$506,$B63,'05 Work done log'!$A$7:$A$506,F$62)) -> 0 | G63: =IF($B63="","",SUMIFS('05 Work done log'!$F$7:$F$506,'05 Work done log'!$B$7:$B$506,$B63,'05 Work done log'!$A$7:$A$506,G$62)) -> 2 | H63: =IF($B63="","",SUMIFS('05 Work done log'!$F$7:$F$506,'05 Work done log'!$B$7:$B$506,$B63,'05 Work done log'!$A$7:$A$506,H$62)) -> 0 | I63: =IF($B63="","",SUMIFS('05 Work done log'!$F$7:$F$506,'05 Work done log'!$B$7:$B$506,$B63,'05 Work done log'!$A$7:$A$506,I$62)) -> 0 | J63: =IF($B63="","",SUMIFS('05 Work done log'!$F$7:$F$506,'05 Work done log'!$B$7:$B$506,$B63,'05 Work done log'!$A$7:$A$506,J$62)) -> 0 | K63: =IF($B63="","",SUMIFS('05 Work done log'!$F$7:$F$506,'05 Work done log'!$B$7:$B$506,$B63,'05 Work done log'!$A$7:$A$506,K$62)) -> 0 | L63: =IF($B63="","",SUMIFS('05 Work done log'!$F$7:$F$506,'05 Work done log'!$B$7:$B$506,$B63,'05 Work done log'!$A$7:$A$506,L$62)) -> 0 | M63: =IF($B63="","",SUM(F63:L63)) -> 2
B64: {=IFERROR(INDEX(_xlfn._xlws.SORT(_xlfn.UNIQUE(_xlfn._xlws.FILTER('05 Work done log'!$B$7:$B$506,('05 Work done log'!$A$7:$A$506>=WeekStart)*('05 Work done log'!$A$7:$A$506<=WeekEnd)*('05 Work done log'!$B$7:$B$506<>"")))),ROWS($B$63:B64)),"")} -> A1100 | C64: =IF($B64="","",IFERROR(INDEX('12 P6 activities'!$B$7:$B$206,MATCH($B64,'12 P6 activities'!$A$7:$A$206,0)),"ID not in P6 list")) -> Raft reinforcement, bay 1 | E64: =IF($B64="","",IFERROR(INDEX('12 P6 activities'!$E$7:$E$206,MATCH($B64,'12 P6 activities'!$A$7:$A$206,0)),"")) -> t | F64: =IF($B64="","",SUMIFS('05 Work done log'!$F$7:$F$506,'05 Work done log'!$B$7:$B$506,$B64,'05 Work done log'!$A$7:$A$506,F$62)) -> 0 | G64: =IF($B64="","",SUMIFS('05 Work done log'!$F$7:$F$506,'05 Work done log'!$B$7:$B$506,$B64,'05 Work done log'!$A$7:$A$506,G$62)) -> 3.5 | H64: =IF($B64="","",SUMIFS('05 Work done log'!$F$7:$F$506,'05 Work done log'!$B$7:$B$506,$B64,'05 Work done log'!$A$7:$A$506,H$62)) -> 0 | I64: =IF($B64="","",SUMIFS('05 Work done log'!$F$7:$F$506,'05 Work done log'!$B$7:$B$506,$B64,'05 Work done log'!$A$7:$A$506,I$62)) -> 0 | J64: =IF($B64="","",SUMIFS('05 Work done log'!$F$7:$F$506,'05 Work done log'!$B$7:$B$506,$B64,'05 Work done log'!$A$7:$A$506,J$62)) -> 0 | K64: =IF($B64="","",SUMIFS('05 Work done log'!$F$7:$F$506,'05 Work done log'!$B$7:$B$506,$B64,'05 Work done log'!$A$7:$A$506,K$62)) -> 0 | L64: =IF($B64="","",SUMIFS('05 Work done log'!$F$7:$F$506,'05 Work done log'!$B$7:$B$506,$B64,'05 Work done log'!$A$7:$A$506,L$62)) -> 0 | M64: =IF($B64="","",SUM(F64:L64)) -> 3.5
B65: {=IFERROR(INDEX(_xlfn._xlws.SORT(_xlfn.UNIQUE(_xlfn._xlws.FILTER('05 Work done log'!$B$7:$B$506,('05 Work done log'!$A$7:$A$506>=WeekStart)*('05 Work done log'!$A$7:$A$506<=WeekEnd)*('05 Work done log'!$B$7:$B$506<>"")))),ROWS($B$63:B65)),"")} -> A1200 | C65: =IF($B65="","",IFERROR(INDEX('12 P6 activities'!$B$7:$B$206,MATCH($B65,'12 P6 activities'!$A$7:$A$206,0)),"ID not in P6 list")) -> Blinding, substation slab | E65: =IF($B65="","",IFERROR(INDEX('12 P6 activities'!$E$7:$E$206,MATCH($B65,'12 P6 activities'!$A$7:$A$206,0)),"")) -> m² | F65: =IF($B65="","",SUMIFS('05 Work done log'!$F$7:$F$506,'05 Work done log'!$B$7:$B$506,$B65,'05 Work done log'!$A$7:$A$506,F$62)) -> 0 | G65: =IF($B65="","",SUMIFS('05 Work done log'!$F$7:$F$506,'05 Work done log'!$B$7:$B$506,$B65,'05 Work done log'!$A$7:$A$506,G$62)) -> 38 | H65: =IF($B65="","",SUMIFS('05 Work done log'!$F$7:$F$506,'05 Work done log'!$B$7:$B$506,$B65,'05 Work done log'!$A$7:$A$506,H$62)) -> 0 | I65: =IF($B65="","",SUMIFS('05 Work done log'!$F$7:$F$506,'05 Work done log'!$B$7:$B$506,$B65,'05 Work done log'!$A$7:$A$506,I$62)) -> 0 | J65: =IF($B65="","",SUMIFS('05 Work done log'!$F$7:$F$506,'05 Work done log'!$B$7:$B$506,$B65,'05 Work done log'!$A$7:$A$506,J$62)) -> 0 | K65: =IF($B65="","",SUMIFS('05 Work done log'!$F$7:$F$506,'05 Work done log'!$B$7:$B$506,$B65,'05 Work done log'!$A$7:$A$506,K$62)) -> 0 | L65: =IF($B65="","",SUMIFS('05 Work done log'!$F$7:$F$506,'05 Work done log'!$B$7:$B$506,$B65,'05 Work done log'!$A$7:$A$506,L$62)) -> 0 | M65: =IF($B65="","",SUM(F65:L65)) -> 38
B66: {=IFERROR(INDEX(_xlfn._xlws.SORT(_xlfn.UNIQUE(_xlfn._xlws.FILTER('05 Work done log'!$B$7:$B$506,('05 Work done log'!$A$7:$A$506>=WeekStart)*('05 Work done log'!$A$7:$A$506<=WeekEnd)*('05 Work done log'!$B$7:$B$506<>"")))),ROWS($B$63:B66)),"")} -> A1300 | C66: =IF($B66="","",IFERROR(INDEX('12 P6 activities'!$B$7:$B$206,MATCH($B66,'12 P6 activities'!$A$7:$A$206,0)),"ID not in P6 list")) -> Drainage run D2 | E66: =IF($B66="","",IFERROR(INDEX('12 P6 activities'!$E$7:$E$206,MATCH($B66,'12 P6 activities'!$A$7:$A$206,0)),"")) -> m | F66: =IF($B66="","",SUMIFS('05 Work done log'!$F$7:$F$506,'05 Work done log'!$B$7:$B$506,$B66,'05 Work done log'!$A$7:$A$506,F$62)) -> 0 | G66: =IF($B66="","",SUMIFS('05 Work done log'!$F$7:$F$506,'05 Work done log'!$B$7:$B$506,$B66,'05 Work done log'!$A$7:$A$506,G$62)) -> 24 | H66: =IF($B66="","",SUMIFS('05 Work done log'!$F$7:$F$506,'05 Work done log'!$B$7:$B$506,$B66,'05 Work done log'!$A$7:$A$506,H$62)) -> 0 | I66: =IF($B66="","",SUMIFS('05 Work done log'!$F$7:$F$506,'05 Work done log'!$B$7:$B$506,$B66,'05 Work done log'!$A$7:$A$506,I$62)) -> 0 | J66: =IF($B66="","",SUMIFS('05 Work done log'!$F$7:$F$506,'05 Work done log'!$B$7:$B$506,$B66,'05 Work done log'!$A$7:$A$506,J$62)) -> 0 | K66: =IF($B66="","",SUMIFS('05 Work done log'!$F$7:$F$506,'05 Work done log'!$B$7:$B$506,$B66,'05 Work done log'!$A$7:$A$506,K$62)) -> 0 | L66: =IF($B66="","",SUMIFS('05 Work done log'!$F$7:$F$506,'05 Work done log'!$B$7:$B$506,$B66,'05 Work done log'!$A$7:$A$506,L$62)) -> 0 | M66: =IF($B66="","",SUM(F66:L66)) -> 24
B67: {=IFERROR(INDEX(_xlfn._xlws.SORT(_xlfn.UNIQUE(_xlfn._xlws.FILTER('05 Work done log'!$B$7:$B$506,('05 Work done log'!$A$7:$A$506>=WeekStart)*('05 Work done log'!$A$7:$A$506<=WeekEnd)*('05 Work done log'!$B$7:$B$506<>"")))),ROWS($B$63:B67)),"")} | C67: =IF($B67="","",IFERROR(INDEX('12 P6 activities'!$B$7:$B$206,MATCH($B67,'12 P6 activities'!$A$7:$A$206,0)),"ID not in P6 list")) | E67: =IF($B67="","",IFERROR(INDEX('12 P6 activities'!$E$7:$E$206,MATCH($B67,'12 P6 activities'!$A$7:$A$206,0)),"")) | F67: =IF($B67="","",SUMIFS('05 Work done log'!$F$7:$F$506,'05 Work done log'!$B$7:$B$506,$B67,'05 Work done log'!$A$7:$A$506,F$62)) | G67: =IF($B67="","",SUMIFS('05 Work done log'!$F$7:$F$506,'05 Work done log'!$B$7:$B$506,$B67,'05 Work done log'!$A$7:$A$506,G$62)) | H67: =IF($B67="","",SUMIFS('05 Work done log'!$F$7:$F$506,'05 Work done log'!$B$7:$B$506,$B67,'05 Work done log'!$A$7:$A$506,H$62)) | I67: =IF($B67="","",SUMIFS('05 Work done log'!$F$7:$F$506,'05 Work done log'!$B$7:$B$506,$B67,'05 Work done log'!$A$7:$A$506,I$62)) | J67: =IF($B67="","",SUMIFS('05 Work done log'!$F$7:$F$506,'05 Work done log'!$B$7:$B$506,$B67,'05 Work done log'!$A$7:$A$506,J$62)) | K67: =IF($B67="","",SUMIFS('05 Work done log'!$F$7:$F$506,'05 Work done log'!$B$7:$B$506,$B67,'05 Work done log'!$A$7:$A$506,K$62)) | L67: =IF($B67="","",SUMIFS('05 Work done log'!$F$7:$F$506,'05 Work done log'!$B$7:$B$506,$B67,'05 Work done log'!$A$7:$A$506,L$62)) | M67: =IF($B67="","",SUM(F67:L67))
B68: {=IFERROR(INDEX(_xlfn._xlws.SORT(_xlfn.UNIQUE(_xlfn._xlws.FILTER('05 Work done log'!$B$7:$B$506,('05 Work done log'!$A$7:$A$506>=WeekStart)*('05 Work done log'!$A$7:$A$506<=WeekEnd)*('05 Work done log'!$B$7:$B$506<>"")))),ROWS($B$63:B68)),"")} | C68: =IF($B68="","",IFERROR(INDEX('12 P6 activities'!$B$7:$B$206,MATCH($B68,'12 P6 activities'!$A$7:$A$206,0)),"ID not in P6 list")) | E68: =IF($B68="","",IFERROR(INDEX('12 P6 activities'!$E$7:$E$206,MATCH($B68,'12 P6 activities'!$A$7:$A$206,0)),"")) | F68: =IF($B68="","",SUMIFS('05 Work done log'!$F$7:$F$506,'05 Work done log'!$B$7:$B$506,$B68,'05 Work done log'!$A$7:$A$506,F$62)) | G68: =IF($B68="","",SUMIFS('05 Work done log'!$F$7:$F$506,'05 Work done log'!$B$7:$B$506,$B68,'05 Work done log'!$A$7:$A$506,G$62)) | H68: =IF($B68="","",SUMIFS('05 Work done log'!$F$7:$F$506,'05 Work done log'!$B$7:$B$506,$B68,'05 Work done log'!$A$7:$A$506,H$62)) | I68: =IF($B68="","",SUMIFS('05 Work done log'!$F$7:$F$506,'05 Work done log'!$B$7:$B$506,$B68,'05 Work done log'!$A$7:$A$506,I$62)) | J68: =IF($B68="","",SUMIFS('05 Work done log'!$F$7:$F$506,'05 Work done log'!$B$7:$B$506,$B68,'05 Work done log'!$A$7:$A$506,J$62)) | K68: =IF($B68="","",SUMIFS('05 Work done log'!$F$7:$F$506,'05 Work done log'!$B$7:$B$506,$B68,'05 Work done log'!$A$7:$A$506,K$62)) | L68: =IF($B68="","",SUMIFS('05 Work done log'!$F$7:$F$506,'05 Work done log'!$B$7:$B$506,$B68,'05 Work done log'!$A$7:$A$506,L$62)) | M68: =IF($B68="","",SUM(F68:L68))
B69: {=IFERROR(INDEX(_xlfn._xlws.SORT(_xlfn.UNIQUE(_xlfn._xlws.FILTER('05 Work done log'!$B$7:$B$506,('05 Work done log'!$A$7:$A$506>=WeekStart)*('05 Work done log'!$A$7:$A$506<=WeekEnd)*('05 Work done log'!$B$7:$B$506<>"")))),ROWS($B$63:B69)),"")} | C69: =IF($B69="","",IFERROR(INDEX('12 P6 activities'!$B$7:$B$206,MATCH($B69,'12 P6 activities'!$A$7:$A$206,0)),"ID not in P6 list")) | E69: =IF($B69="","",IFERROR(INDEX('12 P6 activities'!$E$7:$E$206,MATCH($B69,'12 P6 activities'!$A$7:$A$206,0)),"")) | F69: =IF($B69="","",SUMIFS('05 Work done log'!$F$7:$F$506,'05 Work done log'!$B$7:$B$506,$B69,'05 Work done log'!$A$7:$A$506,F$62)) | G69: =IF($B69="","",SUMIFS('05 Work done log'!$F$7:$F$506,'05 Work done log'!$B$7:$B$506,$B69,'05 Work done log'!$A$7:$A$506,G$62)) | H69: =IF($B69="","",SUMIFS('05 Work done log'!$F$7:$F$506,'05 Work done log'!$B$7:$B$506,$B69,'05 Work done log'!$A$7:$A$506,H$62)) | I69: =IF($B69="","",SUMIFS('05 Work done log'!$F$7:$F$506,'05 Work done log'!$B$7:$B$506,$B69,'05 Work done log'!$A$7:$A$506,I$62)) | J69: =IF($B69="","",SUMIFS('05 Work done log'!$F$7:$F$506,'05 Work done log'!$B$7:$B$506,$B69,'05 Work done log'!$A$7:$A$506,J$62)) | K69: =IF($B69="","",SUMIFS('05 Work done log'!$F$7:$F$506,'05 Work done log'!$B$7:$B$506,$B69,'05 Work done log'!$A$7:$A$506,K$62)) | L69: =IF($B69="","",SUMIFS('05 Work done log'!$F$7:$F$506,'05 Work done log'!$B$7:$B$506,$B69,'05 Work done log'!$A$7:$A$506,L$62)) | M69: =IF($B69="","",SUM(F69:L69))
B70: {=IFERROR(INDEX(_xlfn._xlws.SORT(_xlfn.UNIQUE(_xlfn._xlws.FILTER('05 Work done log'!$B$7:$B$506,('05 Work done log'!$A$7:$A$506>=WeekStart)*('05 Work done log'!$A$7:$A$506<=WeekEnd)*('05 Work done log'!$B$7:$B$506<>"")))),ROWS($B$63:B70)),"")} | C70: =IF($B70="","",IFERROR(INDEX('12 P6 activities'!$B$7:$B$206,MATCH($B70,'12 P6 activities'!$A$7:$A$206,0)),"ID not in P6 list")) | E70: =IF($B70="","",IFERROR(INDEX('12 P6 activities'!$E$7:$E$206,MATCH($B70,'12 P6 activities'!$A$7:$A$206,0)),"")) | F70: =IF($B70="","",SUMIFS('05 Work done log'!$F$7:$F$506,'05 Work done log'!$B$7:$B$506,$B70,'05 Work done log'!$A$7:$A$506,F$62)) | G70: =IF($B70="","",SUMIFS('05 Work done log'!$F$7:$F$506,'05 Work done log'!$B$7:$B$506,$B70,'05 Work done log'!$A$7:$A$506,G$62)) | H70: =IF($B70="","",SUMIFS('05 Work done log'!$F$7:$F$506,'05 Work done log'!$B$7:$B$506,$B70,'05 Work done log'!$A$7:$A$506,H$62)) | I70: =IF($B70="","",SUMIFS('05 Work done log'!$F$7:$F$506,'05 Work done log'!$B$7:$B$506,$B70,'05 Work done log'!$A$7:$A$506,I$62)) | J70: =IF($B70="","",SUMIFS('05 Work done log'!$F$7:$F$506,'05 Work done log'!$B$7:$B$506,$B70,'05 Work done log'!$A$7:$A$506,J$62)) | K70: =IF($B70="","",SUMIFS('05 Work done log'!$F$7:$F$506,'05 Work done log'!$B$7:$B$506,$B70,'05 Work done log'!$A$7:$A$506,K$62)) | L70: =IF($B70="","",SUMIFS('05 Work done log'!$F$7:$F$506,'05 Work done log'!$B$7:$B$506,$B70,'05 Work done log'!$A$7:$A$506,L$62)) | M70: =IF($B70="","",SUM(F70:L70))
B71: {=IFERROR(INDEX(_xlfn._xlws.SORT(_xlfn.UNIQUE(_xlfn._xlws.FILTER('05 Work done log'!$B$7:$B$506,('05 Work done log'!$A$7:$A$506>=WeekStart)*('05 Work done log'!$A$7:$A$506<=WeekEnd)*('05 Work done log'!$B$7:$B$506<>"")))),ROWS($B$63:B71)),"")} | C71: =IF($B71="","",IFERROR(INDEX('12 P6 activities'!$B$7:$B$206,MATCH($B71,'12 P6 activities'!$A$7:$A$206,0)),"ID not in P6 list")) | E71: =IF($B71="","",IFERROR(INDEX('12 P6 activities'!$E$7:$E$206,MATCH($B71,'12 P6 activities'!$A$7:$A$206,0)),"")) | F71: =IF($B71="","",SUMIFS('05 Work done log'!$F$7:$F$506,'05 Work done log'!$B$7:$B$506,$B71,'05 Work done log'!$A$7:$A$506,F$62)) | G71: =IF($B71="","",SUMIFS('05 Work done log'!$F$7:$F$506,'05 Work done log'!$B$7:$B$506,$B71,'05 Work done log'!$A$7:$A$506,G$62)) | H71: =IF($B71="","",SUMIFS('05 Work done log'!$F$7:$F$506,'05 Work done log'!$B$7:$B$506,$B71,'05 Work done log'!$A$7:$A$506,H$62)) | I71: =IF($B71="","",SUMIFS('05 Work done log'!$F$7:$F$506,'05 Work done log'!$B$7:$B$506,$B71,'05 Work done log'!$A$7:$A$506,I$62)) | J71: =IF($B71="","",SUMIFS('05 Work done log'!$F$7:$F$506,'05 Work done log'!$B$7:$B$506,$B71,'05 Work done log'!$A$7:$A$506,J$62)) | K71: =IF($B71="","",SUMIFS('05 Work done log'!$F$7:$F$506,'05 Work done log'!$B$7:$B$506,$B71,'05 Work done log'!$A$7:$A$506,K$62)) | L71: =IF($B71="","",SUMIFS('05 Work done log'!$F$7:$F$506,'05 Work done log'!$B$7:$B$506,$B71,'05 Work done log'!$A$7:$A$506,L$62)) | M71: =IF($B71="","",SUM(F71:L71))
B72: {=IFERROR(INDEX(_xlfn._xlws.SORT(_xlfn.UNIQUE(_xlfn._xlws.FILTER('05 Work done log'!$B$7:$B$506,('05 Work done log'!$A$7:$A$506>=WeekStart)*('05 Work done log'!$A$7:$A$506<=WeekEnd)*('05 Work done log'!$B$7:$B$506<>"")))),ROWS($B$63:B72)),"")} | C72: =IF($B72="","",IFERROR(INDEX('12 P6 activities'!$B$7:$B$206,MATCH($B72,'12 P6 activities'!$A$7:$A$206,0)),"ID not in P6 list")) | E72: =IF($B72="","",IFERROR(INDEX('12 P6 activities'!$E$7:$E$206,MATCH($B72,'12 P6 activities'!$A$7:$A$206,0)),"")) | F72: =IF($B72="","",SUMIFS('05 Work done log'!$F$7:$F$506,'05 Work done log'!$B$7:$B$506,$B72,'05 Work done log'!$A$7:$A$506,F$62)) | G72: =IF($B72="","",SUMIFS('05 Work done log'!$F$7:$F$506,'05 Work done log'!$B$7:$B$506,$B72,'05 Work done log'!$A$7:$A$506,G$62)) | H72: =IF($B72="","",SUMIFS('05 Work done log'!$F$7:$F$506,'05 Work done log'!$B$7:$B$506,$B72,'05 Work done log'!$A$7:$A$506,H$62)) | I72: =IF($B72="","",SUMIFS('05 Work done log'!$F$7:$F$506,'05 Work done log'!$B$7:$B$506,$B72,'05 Work done log'!$A$7:$A$506,I$62)) | J72: =IF($B72="","",SUMIFS('05 Work done log'!$F$7:$F$506,'05 Work done log'!$B$7:$B$506,$B72,'05 Work done log'!$A$7:$A$506,J$62)) | K72: =IF($B72="","",SUMIFS('05 Work done log'!$F$7:$F$506,'05 Work done log'!$B$7:$B$506,$B72,'05 Work done log'!$A$7:$A$506,K$62)) | L72: =IF($B72="","",SUMIFS('05 Work done log'!$F$7:$F$506,'05 Work done log'!$B$7:$B$506,$B72,'05 Work done log'!$A$7:$A$506,L$62)) | M72: =IF($B72="","",SUM(F72:L72))
B73: {=IFERROR(INDEX(_xlfn._xlws.SORT(_xlfn.UNIQUE(_xlfn._xlws.FILTER('05 Work done log'!$B$7:$B$506,('05 Work done log'!$A$7:$A$506>=WeekStart)*('05 Work done log'!$A$7:$A$506<=WeekEnd)*('05 Work done log'!$B$7:$B$506<>"")))),ROWS($B$63:B73)),"")} | C73: =IF($B73="","",IFERROR(INDEX('12 P6 activities'!$B$7:$B$206,MATCH($B73,'12 P6 activities'!$A$7:$A$206,0)),"ID not in P6 list")) | E73: =IF($B73="","",IFERROR(INDEX('12 P6 activities'!$E$7:$E$206,MATCH($B73,'12 P6 activities'!$A$7:$A$206,0)),"")) | F73: =IF($B73="","",SUMIFS('05 Work done log'!$F$7:$F$506,'05 Work done log'!$B$7:$B$506,$B73,'05 Work done log'!$A$7:$A$506,F$62)) | G73: =IF($B73="","",SUMIFS('05 Work done log'!$F$7:$F$506,'05 Work done log'!$B$7:$B$506,$B73,'05 Work done log'!$A$7:$A$506,G$62)) | H73: =IF($B73="","",SUMIFS('05 Work done log'!$F$7:$F$506,'05 Work done log'!$B$7:$B$506,$B73,'05 Work done log'!$A$7:$A$506,H$62)) | I73: =IF($B73="","",SUMIFS('05 Work done log'!$F$7:$F$506,'05 Work done log'!$B$7:$B$506,$B73,'05 Work done log'!$A$7:$A$506,I$62)) | J73: =IF($B73="","",SUMIFS('05 Work done log'!$F$7:$F$506,'05 Work done log'!$B$7:$B$506,$B73,'05 Work done log'!$A$7:$A$506,J$62)) | K73: =IF($B73="","",SUMIFS('05 Work done log'!$F$7:$F$506,'05 Work done log'!$B$7:$B$506,$B73,'05 Work done log'!$A$7:$A$506,K$62)) | L73: =IF($B73="","",SUMIFS('05 Work done log'!$F$7:$F$506,'05 Work done log'!$B$7:$B$506,$B73,'05 Work done log'!$A$7:$A$506,L$62)) | M73: =IF($B73="","",SUM(F73:L73))
