Workbook

Sheet Start
B2: Notice and time-bar calendar
B3: Every clock in the contract, and the days left on each, counted from when you became aware.
B4: The Project Control Hub · free template · example: the rock in the north pile bores
B7: FIVE STEPS
B8: 1 | C8: Setup → | D8: Leave "As at" on today. Pick the contract form: it decides who the Notice goes to. | E8: 1 minute
B9: 2 | C9: Events → | D9: Anything that might become a claim gets a row the day somebody notices it: a driller’s log, a short delivery, a level that does not match. Write what fixed the date. | E9: 2 minutes each
B10: 3 | C10: Events → | D10: When the Notice goes: its date and the four tests. When the detailed claim goes: its date, and whether the contractual basis is in it. | E10: —
B11: 4 | C11: Engineer clocks → | D11: The Engineer’s 14 and 7 days. If they pass in silence, the position moves your way. | E11: 1 minute each
B12: 5 | C12: Determinations → | D12: Every determination, the day it lands. 28 days, and no way back. | E12: 1 minute each
B14: FOUR TESTS OF A NOTICE · sub-clause 1.3
C15: In writing | D15: A paper original signed by the authorised representative, or from the named electronic system.
C16: Identified as a Notice | D16: It says it is a Notice. An accurate email that does not is not one.
C17: Delivered the stated way | D17: By hand or courier against receipt, or through the stated system.
C18: To the stated address | D18: The address in the Contract Data, not the person you speak to every morning.
B20: THREE BANDS
C21: Ends a right | D21: Notice of Claim 28 d, detailed claim 84 d, Notice of Dissatisfaction 28 d.
C22: Runs for you | D22: The Engineer’s 14 days on a late Notice, 14 on a lapse, 7 on a challenge.
C23: Procedure | D23: Consultation, programme, suspension: stages, not bars. Panic here is expensive.
B25: WHAT IS IN THIS FILE
C26: Dashboard | D26: Six numbers, a paragraph, the next twelve deadlines, and two charts.
C27: Setup | D27: As at, contract form, warning window.
C28: The clocks | D28: All eleven periods with clause, consequence, band and rescue.
C29: Events | D29: The log: dates, the four tests, both claim clocks, status and the next action.
C30: Engineer clocks | D30: The silences that run for you.
C31: Determinations | D31: The clock with no rescue.
C32: Deadlines | D32: A helper list the Dashboard sorts. Nothing to fill in.
B34: EXPLAINED IN
C35: Contract Topic 1 · The notice behind the entitlement
C36: Contract Topic 10 · Notices and time bars
B38: Example: the rock in the north pile bores (Contract Topic 1). The site engineer emailed the resident engineer on a Tuesday and got back "noted, discuss Thursday"; nobody served a Notice. Forty-one days later the 28 days have passed by 13. The rock was worth $48,450 against a net margin of $48,163. The calendar dates and the second event are illustrative; the lesson counts days. The other two events are illustrative too.
B43: Clause numbers follow FIDIC 2017 as used in the lessons. Check your own contract. Free to use and adapt. https://theprojectcontrolhub.com/

Sheet Dashboard
B2: Notices and time bars | K2: The Project Control Hub
B3: =IF(Setup!$B$7="","Fill in the Setup sheet first",IF(Setup!B6="","",Setup!B6&" · ")&"as at "&TEXT(Setup!$B$7,"d mmm yyyy")&" · "&Setup!B8&" Book: Notices go to "&Setup!B9) -> Example project · as at 13 Apr 2026 · Red Book: Notices go to the Engineer
B5: OPEN EVENTS | D5: NOTICES DUE SOON | F5: 28 DAYS PASSED, NO NOTICE | H5: LATE NOTICES AT RISK | J5: DETAILED CLAIMS DUE ≤ 14 DAYS | L5: NO-RESCUE CLOCKS OPEN
B6: =COUNTIFS(Events!$B$7:$B$36,"<>",Events!$C$7:$C$36,"<>",Events!$R$7:$R$36,"") -> 3 | D6: =COUNTIFS(Events!$N$7:$N$36,">=0",Events!$N$7:$N$36,"<="&Setup!$B$10) -> 1 | F6: =COUNTIF(Events!$N$7:$N$36,"<0") -> 1 | H6: =COUNTIF(Events!$T$7:$T$36,"Late: t*") -> 0 | J6: =COUNTIFS(Events!$Q$7:$Q$36,">=0",Events!$Q$7:$Q$36,"<=14") -> 0 | L6: =COUNTIFS(Determinations!$F$7:$F$26,">=0") -> 0
B8: ="money at stake "&TEXT(SUMIFS(Events!$E$7:$E$36,Events!$B$7:$B$36,"<>",Events!$R$7:$R$36,""),"$#,##0") -> money at stake $48,450 | D8: ="within "&Setup!$B$10&" days, not yet served" -> within 7 days, not yet served | F8: ="serve now; hope the Engineer is slow" -> serve now; hope the Engineer is slow | H8: ="the Engineer's 14 days still running" -> the Engineer's 14 days still running | J8: =COUNTIF(Events!$Q$7:$Q$36,"<0")&" already past 84 days" -> 0 already past 84 days | L8: =COUNTIF(Determinations!$H$7:$H$26,"Missed*")&" determination(s) already final" -> 0 determination(s) already final
B11: ="Missing a Notice does not reduce the entitlement: it ends it. Today "&F6&" event(s) are past the 28 days without a Notice, "&D6&" Notice(s) fall due within "&Setup!$B$10&" days, and "&L6&" determination(s) are on the one clock with no way back." -> Missing a Notice does not reduce the entitlement: it ends it. Today 1 event(s) are past the 28 days without a Notice, 1 Notice(s) fall due within 7 days, and 0 determination(s) are on the one clock with no way back.
B14: THE NEXT DEADLINES, EARLIEST FIRST · missed ones at the top
B15: Deadline | C15: Days left | D15: Event / item | H15: Clock | K15: Rescue
B16: =IFERROR(INDEX(Deadlines!$A$7:$A$106,MATCH(SMALL(Deadlines!$E$7:$E$106,1),Deadlines!$E$7:$E$106,0)),"") -> 46112 | C16: =IF(B16="","",B16-Setup!$B$7) -> -13 | D16: =IFERROR(INDEX(Deadlines!$B$7:$B$106,MATCH(SMALL(Deadlines!$E$7:$E$106,1),Deadlines!$E$7:$E$106,0)),"") -> E01 · Rock in the north pile bores | H16: =IFERROR(INDEX(Deadlines!$C$7:$C$106,MATCH(SMALL(Deadlines!$E$7:$E$106,1),Deadlines!$E$7:$E$106,0)),"") -> Notice of Claim · 28 d | K16: =IFERROR(INDEX(Deadlines!$D$7:$D$106,MATCH(SMALL(Deadlines!$E$7:$E$106,1),Deadlines!$E$7:$E$106,0)),"") -> Engineer silent 14 days
B17: =IFERROR(INDEX(Deadlines!$A$7:$A$106,MATCH(SMALL(Deadlines!$E$7:$E$106,2),Deadlines!$E$7:$E$106,0)),"") -> 46129 | C17: =IF(B17="","",B17-Setup!$B$7) -> 4 | D17: =IFERROR(INDEX(Deadlines!$B$7:$B$106,MATCH(SMALL(Deadlines!$E$7:$E$106,2),Deadlines!$E$7:$E$106,0)),"") -> E03 · Groundwater in the raft excavation | H17: =IFERROR(INDEX(Deadlines!$C$7:$C$106,MATCH(SMALL(Deadlines!$E$7:$E$106,2),Deadlines!$E$7:$E$106,0)),"") -> Notice of Claim · 28 d | K17: =IFERROR(INDEX(Deadlines!$D$7:$D$106,MATCH(SMALL(Deadlines!$E$7:$E$106,2),Deadlines!$E$7:$E$106,0)),"") -> Engineer silent 14 days
B18: =IFERROR(INDEX(Deadlines!$A$7:$A$106,MATCH(SMALL(Deadlines!$E$7:$E$106,3),Deadlines!$E$7:$E$106,0)),"") -> 46168 | C18: =IF(B18="","",B18-Setup!$B$7) -> 43 | D18: =IFERROR(INDEX(Deadlines!$B$7:$B$106,MATCH(SMALL(Deadlines!$E$7:$E$106,3),Deadlines!$E$7:$E$106,0)),"") -> E01 · Rock in the north pile bores | H18: =IFERROR(INDEX(Deadlines!$C$7:$C$106,MATCH(SMALL(Deadlines!$E$7:$E$106,3),Deadlines!$E$7:$E$106,0)),"") -> Detailed claim · 84 d | K18: =IFERROR(INDEX(Deadlines!$D$7:$D$106,MATCH(SMALL(Deadlines!$E$7:$E$106,3),Deadlines!$E$7:$E$106,0)),"") -> Engineer silent 14 days
B19: =IFERROR(INDEX(Deadlines!$A$7:$A$106,MATCH(SMALL(Deadlines!$E$7:$E$106,4),Deadlines!$E$7:$E$106,0)),"") -> 46169 | C19: =IF(B19="","",B19-Setup!$B$7) -> 44 | D19: =IFERROR(INDEX(Deadlines!$B$7:$B$106,MATCH(SMALL(Deadlines!$E$7:$E$106,4),Deadlines!$E$7:$E$106,0)),"") -> E02 · Late bar schedule revision, raft bay 2 | H19: =IFERROR(INDEX(Deadlines!$C$7:$C$106,MATCH(SMALL(Deadlines!$E$7:$E$106,4),Deadlines!$E$7:$E$106,0)),"") -> Detailed claim · 84 d | K19: =IFERROR(INDEX(Deadlines!$D$7:$D$106,MATCH(SMALL(Deadlines!$E$7:$E$106,4),Deadlines!$E$7:$E$106,0)),"") -> Engineer silent 14 days
B20: =IFERROR(INDEX(Deadlines!$A$7:$A$106,MATCH(SMALL(Deadlines!$E$7:$E$106,5),Deadlines!$E$7:$E$106,0)),"") -> 46185 | C20: =IF(B20="","",B20-Setup!$B$7) -> 60 | D20: =IFERROR(INDEX(Deadlines!$B$7:$B$106,MATCH(SMALL(Deadlines!$E$7:$E$106,5),Deadlines!$E$7:$E$106,0)),"") -> E03 · Groundwater in the raft excavation | H20: =IFERROR(INDEX(Deadlines!$C$7:$C$106,MATCH(SMALL(Deadlines!$E$7:$E$106,5),Deadlines!$E$7:$E$106,0)),"") -> Detailed claim · 84 d | K20: =IFERROR(INDEX(Deadlines!$D$7:$D$106,MATCH(SMALL(Deadlines!$E$7:$E$106,5),Deadlines!$E$7:$E$106,0)),"") -> Engineer silent 14 days
B21: =IFERROR(INDEX(Deadlines!$A$7:$A$106,MATCH(SMALL(Deadlines!$E$7:$E$106,6),Deadlines!$E$7:$E$106,0)),"") | C21: =IF(B21="","",B21-Setup!$B$7) | D21: =IFERROR(INDEX(Deadlines!$B$7:$B$106,MATCH(SMALL(Deadlines!$E$7:$E$106,6),Deadlines!$E$7:$E$106,0)),"") | H21: =IFERROR(INDEX(Deadlines!$C$7:$C$106,MATCH(SMALL(Deadlines!$E$7:$E$106,6),Deadlines!$E$7:$E$106,0)),"") | K21: =IFERROR(INDEX(Deadlines!$D$7:$D$106,MATCH(SMALL(Deadlines!$E$7:$E$106,6),Deadlines!$E$7:$E$106,0)),"")
B22: =IFERROR(INDEX(Deadlines!$A$7:$A$106,MATCH(SMALL(Deadlines!$E$7:$E$106,7),Deadlines!$E$7:$E$106,0)),"") | C22: =IF(B22="","",B22-Setup!$B$7) | D22: =IFERROR(INDEX(Deadlines!$B$7:$B$106,MATCH(SMALL(Deadlines!$E$7:$E$106,7),Deadlines!$E$7:$E$106,0)),"") | H22: =IFERROR(INDEX(Deadlines!$C$7:$C$106,MATCH(SMALL(Deadlines!$E$7:$E$106,7),Deadlines!$E$7:$E$106,0)),"") | K22: =IFERROR(INDEX(Deadlines!$D$7:$D$106,MATCH(SMALL(Deadlines!$E$7:$E$106,7),Deadlines!$E$7:$E$106,0)),"")
B23: =IFERROR(INDEX(Deadlines!$A$7:$A$106,MATCH(SMALL(Deadlines!$E$7:$E$106,8),Deadlines!$E$7:$E$106,0)),"") | C23: =IF(B23="","",B23-Setup!$B$7) | D23: =IFERROR(INDEX(Deadlines!$B$7:$B$106,MATCH(SMALL(Deadlines!$E$7:$E$106,8),Deadlines!$E$7:$E$106,0)),"") | H23: =IFERROR(INDEX(Deadlines!$C$7:$C$106,MATCH(SMALL(Deadlines!$E$7:$E$106,8),Deadlines!$E$7:$E$106,0)),"") | K23: =IFERROR(INDEX(Deadlines!$D$7:$D$106,MATCH(SMALL(Deadlines!$E$7:$E$106,8),Deadlines!$E$7:$E$106,0)),"")
B24: =IFERROR(INDEX(Deadlines!$A$7:$A$106,MATCH(SMALL(Deadlines!$E$7:$E$106,9),Deadlines!$E$7:$E$106,0)),"") | C24: =IF(B24="","",B24-Setup!$B$7) | D24: =IFERROR(INDEX(Deadlines!$B$7:$B$106,MATCH(SMALL(Deadlines!$E$7:$E$106,9),Deadlines!$E$7:$E$106,0)),"") | H24: =IFERROR(INDEX(Deadlines!$C$7:$C$106,MATCH(SMALL(Deadlines!$E$7:$E$106,9),Deadlines!$E$7:$E$106,0)),"") | K24: =IFERROR(INDEX(Deadlines!$D$7:$D$106,MATCH(SMALL(Deadlines!$E$7:$E$106,9),Deadlines!$E$7:$E$106,0)),"")
B25: =IFERROR(INDEX(Deadlines!$A$7:$A$106,MATCH(SMALL(Deadlines!$E$7:$E$106,10),Deadlines!$E$7:$E$106,0)),"") | C25: =IF(B25="","",B25-Setup!$B$7) | D25: =IFERROR(INDEX(Deadlines!$B$7:$B$106,MATCH(SMALL(Deadlines!$E$7:$E$106,10),Deadlines!$E$7:$E$106,0)),"") | H25: =IFERROR(INDEX(Deadlines!$C$7:$C$106,MATCH(SMALL(Deadlines!$E$7:$E$106,10),Deadlines!$E$7:$E$106,0)),"") | K25: =IFERROR(INDEX(Deadlines!$D$7:$D$106,MATCH(SMALL(Deadlines!$E$7:$E$106,10),Deadlines!$E$7:$E$106,0)),"")
B26: =IFERROR(INDEX(Deadlines!$A$7:$A$106,MATCH(SMALL(Deadlines!$E$7:$E$106,11),Deadlines!$E$7:$E$106,0)),"") | C26: =IF(B26="","",B26-Setup!$B$7) | D26: =IFERROR(INDEX(Deadlines!$B$7:$B$106,MATCH(SMALL(Deadlines!$E$7:$E$106,11),Deadlines!$E$7:$E$106,0)),"") | H26: =IFERROR(INDEX(Deadlines!$C$7:$C$106,MATCH(SMALL(Deadlines!$E$7:$E$106,11),Deadlines!$E$7:$E$106,0)),"") | K26: =IFERROR(INDEX(Deadlines!$D$7:$D$106,MATCH(SMALL(Deadlines!$E$7:$E$106,11),Deadlines!$E$7:$E$106,0)),"")
B27: =IFERROR(INDEX(Deadlines!$A$7:$A$106,MATCH(SMALL(Deadlines!$E$7:$E$106,12),Deadlines!$E$7:$E$106,0)),"") | C27: =IF(B27="","",B27-Setup!$B$7) | D27: =IFERROR(INDEX(Deadlines!$B$7:$B$106,MATCH(SMALL(Deadlines!$E$7:$E$106,12),Deadlines!$E$7:$E$106,0)),"") | H27: =IFERROR(INDEX(Deadlines!$C$7:$C$106,MATCH(SMALL(Deadlines!$E$7:$E$106,12),Deadlines!$E$7:$E$106,0)),"") | K27: =IFERROR(INDEX(Deadlines!$D$7:$D$106,MATCH(SMALL(Deadlines!$E$7:$E$106,12),Deadlines!$E$7:$E$106,0)),"")
B30: HOW MUCH TIME IS LEFT
H48: Red ends a right · green runs for you · grey is procedure
B50: Everything on this page reads from Setup, Events, Engineer clocks and Determinations.

Sheet Setup
A1: Setup | D1: The Project Control Hub
A2: The date the calendar counts from, and the contract form.
A3: "As at" is today unless you type a date. Every days-left figure counts from it.
A6: Project | B6: Example project
A7: As at | B7: 46125 | D7: Today by default. The example is fixed at 41 days after the rock.
A8: Contract form | B8: Red | D8: Red, Yellow or Silver Book (FIDIC 2017), as used in the lessons.
A9: Notices go to | B9: =IF(B8="Silver","the other Party","the Engineer") -> the Engineer | D9: Red and Yellow: the Engineer. Silver: there is no Engineer, so the other Party.
A10: Warn me this many days ahead | B10: 7 | D10: Deadlines inside this window turn amber.
A11: Prepared by | B11: Commercial
A13: Clause numbers follow the FIDIC 2017 Red and Yellow Books as used in the Contract track. Check the periods in your own contract before relying on them.

Sheet The clocks
A1: The clocks, on one page | F1: The Project Control Hub
A2: Three end a right, three run for you, five are procedure.
A3: Both claim clocks start the day you became aware, or should have become aware, of the event.
A6: Days | B6: Clause | C6: What it is | D6: If missed | E6: Band | F6: Rescue
A7: 28 | B7: 20.2.1 | C7: Notice of Claim | D7: Entitlement gone: the other Party is discharged | E7: Ends a right | F7: Engineer silent for 14 days
A8: 84 | B8: 20.2.4 | C8: Fully detailed Claim, with the contractual basis | D8: The Notice of Claim lapses | E8: Ends a right | F8: Engineer silent for 14 days
A9: 28 | B9: 3.7.5 | C9: Notice of Dissatisfaction with a determination | D9: Final and binding | E9: Ends a right | F9: None
A10: 14 | B10: 20.2.2 | C10: Engineer says your Notice was late | D10: If silent, your Notice is valid | E10: Runs for you | F10: —
A11: 7 | B11: 3.5 | C11: Engineer answers your challenge to an instruction | D11: If silent, the instruction is revoked | E11: Runs for you | F11: —
A12: 14 | B12: 20.2.4 | C12: Engineer declares a lapse | D12: If silent, your Notice survives | E12: Runs for you | F12: —
A13: 42 | B13: 3.7.3 | C13: Consultation to reach agreement | D13: Moves to determination | E13: Procedure | F13: —
A14: 28 | B14: 8.3 | C14: Initial programme | D14: A breach, not a bar | E14: Procedure | F14: —
A15: 28 | B15: 2.4 | C15: Employer shows it can pay | D15: Opens 16.1 | E15: Procedure | F15: —
A16: 21 | B16: 16.1 | C16: Wait before suspending | D16: A floor, not a deadline | E16: Procedure | F16: —
A17: 42 | B17: 3.6 | C17: Notice of a new Engineer | D17: 14 days to object | E17: Procedure | F17: —
A19: Serving the Notice on day 27 leaves 57 days for the detailed claim, not 84: both clocks started together.
A20: The Notice of Dissatisfaction is the only fatal clock with no way back. It arrives when everybody is tired and the argument feels finished.

Sheet Events
A1: Events | W1: The Project Control Hub
A2: One row per event that might become a claim. The clock starts when you became aware, not when you decided to claim.
A3: Fill the yellow cells. The deadlines, the days left, the status and the next action work themselves out.
A6: ID | B6: Event | C6: Became aware (date) | D6: What fixed that date | E6: Money at stake ($) | F6: Owner | G6: Notice served (date) | H6: In writing | I6: Identified as a Notice | J6: Delivered the stated way | K6: To the stated address | L6: Notice valid? | M6: 28-day deadline | N6: Days left (Notice) | O6: Engineer objected to a late Notice on | P6: 84-day deadline | Q6: Days left (claim) | R6: Detailed claim submitted (date) | S6: Contractual basis stated? | T6: Notice status | U6: Claim status | V6: Next action | W6: Note
A7: E01 | B7: Rock in the north pile bores | C7: 46084 | D7: Driller’s log; site engineer’s email the same day | E7: 48450 | F7: Commercial | L7: =IF(G7="","",IF(COUNTIF(H7:K7,"Y")=4,"✔ valid","Check: "&MID(IF(H7<>"Y",", writing","")&IF(I7<>"Y",", identified","")&IF(J7<>"Y",", delivery","")&IF(K7<>"Y",", address",""),3,60))) | M7: =IF(C7="","",C7+28) -> 46112 | N7: =IF(OR(C7="",G7<>""),"",M7-Setup!$B$7) -> -13 | P7: =IF(C7="","",C7+84) -> 46168 | Q7: =IF(OR(C7="",R7<>""),"",P7-Setup!$B$7) -> 43 | T7: =IF(OR(B7="",C7=""),"",IF(G7="",IF(Setup!$B$7<=M7,"Notice due in "&(M7-Setup!$B$7)&" days",(Setup!$B$7-M7)&" days past the 28: serve it now; the Engineer has 14 days to object"),IF(G7<=M7,IF(L7="✔ valid","Served on time","Served on time, but it fails a test"),IF(O7<>"","Late, and the Engineer objected in time: argued in the determination",IF(Setup!$B$7>G7+14,"Late, but no objection within 14 days: treated as valid","Late: the Engineer has until "&TEXT(G7+14,"d mmm")&" to object"))))) -> 13 days past the 28: serve it now; the Engineer has 14 days to object | U7: =IF(OR(B7="",C7=""),"",IF(R7<>"",IF(S7="Y","Detailed claim in, with its contractual basis","Claim in without the contractual basis: the Notice may lapse"),IF(Setup!$B$7<=P7,(P7-Setup!$B$7)&" days left for the detailed claim","84 days passed: the Engineer has 14 days to declare a lapse"))) -> 43 days left for the detailed claim | V7: =IF(OR(B7="",C7=""),"",IF(G7="","Serve the Notice of Claim: identified as a Notice, to "&Setup!$B$9&", the stated way",IF(L7<>"✔ valid","Re-serve: the Notice fails a test",IF(R7="","Build the detailed claim: due "&TEXT(P7,"d mmm yyyy"),IF(S7<>"Y","Add the contractual basis to the claim","Wait: consultation, then the determination"))))) -> Serve the Notice of Claim: identified as a Notice, to the Engineer, the stated way | W7: Email to the resident engineer: "noted, discuss Thursday". No Notice served.
A8: E02 | B8: Late bar schedule revision, raft bay 2 | C8: 46085 | D8: Constraint raised at the weekly meeting | F8: Commercial | G8: 46101 | H8: Y | I8: Y | J8: Y | K8: Y | L8: =IF(G8="","",IF(COUNTIF(H8:K8,"Y")=4,"✔ valid","Check: "&MID(IF(H8<>"Y",", writing","")&IF(I8<>"Y",", identified","")&IF(J8<>"Y",", delivery","")&IF(K8<>"Y",", address",""),3,60))) -> ✔ valid | M8: =IF(C8="","",C8+28) -> 46113 | N8: =IF(OR(C8="",G8<>""),"",M8-Setup!$B$7) | P8: =IF(C8="","",C8+84) -> 46169 | Q8: =IF(OR(C8="",R8<>""),"",P8-Setup!$B$7) -> 44 | T8: =IF(OR(B8="",C8=""),"",IF(G8="",IF(Setup!$B$7<=M8,"Notice due in "&(M8-Setup!$B$7)&" days",(Setup!$B$7-M8)&" days past the 28: serve it now; the Engineer has 14 days to object"),IF(G8<=M8,IF(L8="✔ valid","Served on time","Served on time, but it fails a test"),IF(O8<>"","Late, and the Engineer objected in time: argued in the determination",IF(Setup!$B$7>G8+14,"Late, but no objection within 14 days: treated as valid","Late: the Engineer has until "&TEXT(G8+14,"d mmm")&" to object"))))) -> Served on time | U8: =IF(OR(B8="",C8=""),"",IF(R8<>"",IF(S8="Y","Detailed claim in, with its contractual basis","Claim in without the contractual basis: the Notice may lapse"),IF(Setup!$B$7<=P8,(P8-Setup!$B$7)&" days left for the detailed claim","84 days passed: the Engineer has 14 days to declare a lapse"))) -> 44 days left for the detailed claim | V8: =IF(OR(B8="",C8=""),"",IF(G8="","Serve the Notice of Claim: identified as a Notice, to "&Setup!$B$9&", the stated way",IF(L8<>"✔ valid","Re-serve: the Notice fails a test",IF(R8="","Build the detailed claim: due "&TEXT(P8,"d mmm yyyy"),IF(S8<>"Y","Add the contractual basis to the claim","Wait: consultation, then the determination"))))) -> Build the detailed claim: due 27 May 2026 | W8: Served on day 16, to the stated address.
A9: E03 | B9: Groundwater in the raft excavation | C9: 46101 | D9: Site diary: pumps running all shift | F9: Commercial | L9: =IF(G9="","",IF(COUNTIF(H9:K9,"Y")=4,"✔ valid","Check: "&MID(IF(H9<>"Y",", writing","")&IF(I9<>"Y",", identified","")&IF(J9<>"Y",", delivery","")&IF(K9<>"Y",", address",""),3,60))) | M9: =IF(C9="","",C9+28) -> 46129 | N9: =IF(OR(C9="",G9<>""),"",M9-Setup!$B$7) -> 4 | P9: =IF(C9="","",C9+84) -> 46185 | Q9: =IF(OR(C9="",R9<>""),"",P9-Setup!$B$7) -> 60 | T9: =IF(OR(B9="",C9=""),"",IF(G9="",IF(Setup!$B$7<=M9,"Notice due in "&(M9-Setup!$B$7)&" days",(Setup!$B$7-M9)&" days past the 28: serve it now; the Engineer has 14 days to object"),IF(G9<=M9,IF(L9="✔ valid","Served on time","Served on time, but it fails a test"),IF(O9<>"","Late, and the Engineer objected in time: argued in the determination",IF(Setup!$B$7>G9+14,"Late, but no objection within 14 days: treated as valid","Late: the Engineer has until "&TEXT(G9+14,"d mmm")&" to object"))))) -> Notice due in 4 days | U9: =IF(OR(B9="",C9=""),"",IF(R9<>"",IF(S9="Y","Detailed claim in, with its contractual basis","Claim in without the contractual basis: the Notice may lapse"),IF(Setup!$B$7<=P9,(P9-Setup!$B$7)&" days left for the detailed claim","84 days passed: the Engineer has 14 days to declare a lapse"))) -> 60 days left for the detailed claim | V9: =IF(OR(B9="",C9=""),"",IF(G9="","Serve the Notice of Claim: identified as a Notice, to "&Setup!$B$9&", the stated way",IF(L9<>"✔ valid","Re-serve: the Notice fails a test",IF(R9="","Build the detailed claim: due "&TEXT(P9,"d mmm yyyy"),IF(S9<>"Y","Add the contractual basis to the claim","Wait: consultation, then the determination"))))) -> Serve the Notice of Claim: identified as a Notice, to the Engineer, the stated way | W9: Dewatering started. Notice drafted, not yet sent.
A10: E04 | L10: =IF(G10="","",IF(COUNTIF(H10:K10,"Y")=4,"✔ valid","Check: "&MID(IF(H10<>"Y",", writing","")&IF(I10<>"Y",", identified","")&IF(J10<>"Y",", delivery","")&IF(K10<>"Y",", address",""),3,60))) | M10: =IF(C10="","",C10+28) | N10: =IF(OR(C10="",G10<>""),"",M10-Setup!$B$7) | P10: =IF(C10="","",C10+84) | Q10: =IF(OR(C10="",R10<>""),"",P10-Setup!$B$7) | T10: =IF(OR(B10="",C10=""),"",IF(G10="",IF(Setup!$B$7<=M10,"Notice due in "&(M10-Setup!$B$7)&" days",(Setup!$B$7-M10)&" days past the 28: serve it now; the Engineer has 14 days to object"),IF(G10<=M10,IF(L10="✔ valid","Served on time","Served on time, but it fails a test"),IF(O10<>"","Late, and the Engineer objected in time: argued in the determination",IF(Setup!$B$7>G10+14,"Late, but no objection within 14 days: treated as valid","Late: the Engineer has until "&TEXT(G10+14,"d mmm")&" to object"))))) | U10: =IF(OR(B10="",C10=""),"",IF(R10<>"",IF(S10="Y","Detailed claim in, with its contractual basis","Claim in without the contractual basis: the Notice may lapse"),IF(Setup!$B$7<=P10,(P10-Setup!$B$7)&" days left for the detailed claim","84 days passed: the Engineer has 14 days to declare a lapse"))) | V10: =IF(OR(B10="",C10=""),"",IF(G10="","Serve the Notice of Claim: identified as a Notice, to "&Setup!$B$9&", the stated way",IF(L10<>"✔ valid","Re-serve: the Notice fails a test",IF(R10="","Build the detailed claim: due "&TEXT(P10,"d mmm yyyy"),IF(S10<>"Y","Add the contractual basis to the claim","Wait: consultation, then the determination")))))
A11: E05 | L11: =IF(G11="","",IF(COUNTIF(H11:K11,"Y")=4,"✔ valid","Check: "&MID(IF(H11<>"Y",", writing","")&IF(I11<>"Y",", identified","")&IF(J11<>"Y",", delivery","")&IF(K11<>"Y",", address",""),3,60))) | M11: =IF(C11="","",C11+28) | N11: =IF(OR(C11="",G11<>""),"",M11-Setup!$B$7) | P11: =IF(C11="","",C11+84) | Q11: =IF(OR(C11="",R11<>""),"",P11-Setup!$B$7) | T11: =IF(OR(B11="",C11=""),"",IF(G11="",IF(Setup!$B$7<=M11,"Notice due in "&(M11-Setup!$B$7)&" days",(Setup!$B$7-M11)&" days past the 28: serve it now; the Engineer has 14 days to object"),IF(G11<=M11,IF(L11="✔ valid","Served on time","Served on time, but it fails a test"),IF(O11<>"","Late, and the Engineer objected in time: argued in the determination",IF(Setup!$B$7>G11+14,"Late, but no objection within 14 days: treated as valid","Late: the Engineer has until "&TEXT(G11+14,"d mmm")&" to object"))))) | U11: =IF(OR(B11="",C11=""),"",IF(R11<>"",IF(S11="Y","Detailed claim in, with its contractual basis","Claim in without the contractual basis: the Notice may lapse"),IF(Setup!$B$7<=P11,(P11-Setup!$B$7)&" days left for the detailed claim","84 days passed: the Engineer has 14 days to declare a lapse"))) | V11: =IF(OR(B11="",C11=""),"",IF(G11="","Serve the Notice of Claim: identified as a Notice, to "&Setup!$B$9&", the stated way",IF(L11<>"✔ valid","Re-serve: the Notice fails a test",IF(R11="","Build the detailed claim: due "&TEXT(P11,"d mmm yyyy"),IF(S11<>"Y","Add the contractual basis to the claim","Wait: consultation, then the determination")))))
A12: E06 | L12: =IF(G12="","",IF(COUNTIF(H12:K12,"Y")=4,"✔ valid","Check: "&MID(IF(H12<>"Y",", writing","")&IF(I12<>"Y",", identified","")&IF(J12<>"Y",", delivery","")&IF(K12<>"Y",", address",""),3,60))) | M12: =IF(C12="","",C12+28) | N12: =IF(OR(C12="",G12<>""),"",M12-Setup!$B$7) | P12: =IF(C12="","",C12+84) | Q12: =IF(OR(C12="",R12<>""),"",P12-Setup!$B$7) | T12: =IF(OR(B12="",C12=""),"",IF(G12="",IF(Setup!$B$7<=M12,"Notice due in "&(M12-Setup!$B$7)&" days",(Setup!$B$7-M12)&" days past the 28: serve it now; the Engineer has 14 days to object"),IF(G12<=M12,IF(L12="✔ valid","Served on time","Served on time, but it fails a test"),IF(O12<>"","Late, and the Engineer objected in time: argued in the determination",IF(Setup!$B$7>G12+14,"Late, but no objection within 14 days: treated as valid","Late: the Engineer has until "&TEXT(G12+14,"d mmm")&" to object"))))) | U12: =IF(OR(B12="",C12=""),"",IF(R12<>"",IF(S12="Y","Detailed claim in, with its contractual basis","Claim in without the contractual basis: the Notice may lapse"),IF(Setup!$B$7<=P12,(P12-Setup!$B$7)&" days left for the detailed claim","84 days passed: the Engineer has 14 days to declare a lapse"))) | V12: =IF(OR(B12="",C12=""),"",IF(G12="","Serve the Notice of Claim: identified as a Notice, to "&Setup!$B$9&", the stated way",IF(L12<>"✔ valid","Re-serve: the Notice fails a test",IF(R12="","Build the detailed claim: due "&TEXT(P12,"d mmm yyyy"),IF(S12<>"Y","Add the contractual basis to the claim","Wait: consultation, then the determination")))))
A13: E07 | L13: =IF(G13="","",IF(COUNTIF(H13:K13,"Y")=4,"✔ valid","Check: "&MID(IF(H13<>"Y",", writing","")&IF(I13<>"Y",", identified","")&IF(J13<>"Y",", delivery","")&IF(K13<>"Y",", address",""),3,60))) | M13: =IF(C13="","",C13+28) | N13: =IF(OR(C13="",G13<>""),"",M13-Setup!$B$7) | P13: =IF(C13="","",C13+84) | Q13: =IF(OR(C13="",R13<>""),"",P13-Setup!$B$7) | T13: =IF(OR(B13="",C13=""),"",IF(G13="",IF(Setup!$B$7<=M13,"Notice due in "&(M13-Setup!$B$7)&" days",(Setup!$B$7-M13)&" days past the 28: serve it now; the Engineer has 14 days to object"),IF(G13<=M13,IF(L13="✔ valid","Served on time","Served on time, but it fails a test"),IF(O13<>"","Late, and the Engineer objected in time: argued in the determination",IF(Setup!$B$7>G13+14,"Late, but no objection within 14 days: treated as valid","Late: the Engineer has until "&TEXT(G13+14,"d mmm")&" to object"))))) | U13: =IF(OR(B13="",C13=""),"",IF(R13<>"",IF(S13="Y","Detailed claim in, with its contractual basis","Claim in without the contractual basis: the Notice may lapse"),IF(Setup!$B$7<=P13,(P13-Setup!$B$7)&" days left for the detailed claim","84 days passed: the Engineer has 14 days to declare a lapse"))) | V13: =IF(OR(B13="",C13=""),"",IF(G13="","Serve the Notice of Claim: identified as a Notice, to "&Setup!$B$9&", the stated way",IF(L13<>"✔ valid","Re-serve: the Notice fails a test",IF(R13="","Build the detailed claim: due "&TEXT(P13,"d mmm yyyy"),IF(S13<>"Y","Add the contractual basis to the claim","Wait: consultation, then the determination")))))
A14: E08 | L14: =IF(G14="","",IF(COUNTIF(H14:K14,"Y")=4,"✔ valid","Check: "&MID(IF(H14<>"Y",", writing","")&IF(I14<>"Y",", identified","")&IF(J14<>"Y",", delivery","")&IF(K14<>"Y",", address",""),3,60))) | M14: =IF(C14="","",C14+28) | N14: =IF(OR(C14="",G14<>""),"",M14-Setup!$B$7) | P14: =IF(C14="","",C14+84) | Q14: =IF(OR(C14="",R14<>""),"",P14-Setup!$B$7) | T14: =IF(OR(B14="",C14=""),"",IF(G14="",IF(Setup!$B$7<=M14,"Notice due in "&(M14-Setup!$B$7)&" days",(Setup!$B$7-M14)&" days past the 28: serve it now; the Engineer has 14 days to object"),IF(G14<=M14,IF(L14="✔ valid","Served on time","Served on time, but it fails a test"),IF(O14<>"","Late, and the Engineer objected in time: argued in the determination",IF(Setup!$B$7>G14+14,"Late, but no objection within 14 days: treated as valid","Late: the Engineer has until "&TEXT(G14+14,"d mmm")&" to object"))))) | U14: =IF(OR(B14="",C14=""),"",IF(R14<>"",IF(S14="Y","Detailed claim in, with its contractual basis","Claim in without the contractual basis: the Notice may lapse"),IF(Setup!$B$7<=P14,(P14-Setup!$B$7)&" days left for the detailed claim","84 days passed: the Engineer has 14 days to declare a lapse"))) | V14: =IF(OR(B14="",C14=""),"",IF(G14="","Serve the Notice of Claim: identified as a Notice, to "&Setup!$B$9&", the stated way",IF(L14<>"✔ valid","Re-serve: the Notice fails a test",IF(R14="","Build the detailed claim: due "&TEXT(P14,"d mmm yyyy"),IF(S14<>"Y","Add the contractual basis to the claim","Wait: consultation, then the determination")))))
A15: E09 | L15: =IF(G15="","",IF(COUNTIF(H15:K15,"Y")=4,"✔ valid","Check: "&MID(IF(H15<>"Y",", writing","")&IF(I15<>"Y",", identified","")&IF(J15<>"Y",", delivery","")&IF(K15<>"Y",", address",""),3,60))) | M15: =IF(C15="","",C15+28) | N15: =IF(OR(C15="",G15<>""),"",M15-Setup!$B$7) | P15: =IF(C15="","",C15+84) | Q15: =IF(OR(C15="",R15<>""),"",P15-Setup!$B$7) | T15: =IF(OR(B15="",C15=""),"",IF(G15="",IF(Setup!$B$7<=M15,"Notice due in "&(M15-Setup!$B$7)&" days",(Setup!$B$7-M15)&" days past the 28: serve it now; the Engineer has 14 days to object"),IF(G15<=M15,IF(L15="✔ valid","Served on time","Served on time, but it fails a test"),IF(O15<>"","Late, and the Engineer objected in time: argued in the determination",IF(Setup!$B$7>G15+14,"Late, but no objection within 14 days: treated as valid","Late: the Engineer has until "&TEXT(G15+14,"d mmm")&" to object"))))) | U15: =IF(OR(B15="",C15=""),"",IF(R15<>"",IF(S15="Y","Detailed claim in, with its contractual basis","Claim in without the contractual basis: the Notice may lapse"),IF(Setup!$B$7<=P15,(P15-Setup!$B$7)&" days left for the detailed claim","84 days passed: the Engineer has 14 days to declare a lapse"))) | V15: =IF(OR(B15="",C15=""),"",IF(G15="","Serve the Notice of Claim: identified as a Notice, to "&Setup!$B$9&", the stated way",IF(L15<>"✔ valid","Re-serve: the Notice fails a test",IF(R15="","Build the detailed claim: due "&TEXT(P15,"d mmm yyyy"),IF(S15<>"Y","Add the contractual basis to the claim","Wait: consultation, then the determination")))))
A16: E10 | L16: =IF(G16="","",IF(COUNTIF(H16:K16,"Y")=4,"✔ valid","Check: "&MID(IF(H16<>"Y",", writing","")&IF(I16<>"Y",", identified","")&IF(J16<>"Y",", delivery","")&IF(K16<>"Y",", address",""),3,60))) | M16: =IF(C16="","",C16+28) | N16: =IF(OR(C16="",G16<>""),"",M16-Setup!$B$7) | P16: =IF(C16="","",C16+84) | Q16: =IF(OR(C16="",R16<>""),"",P16-Setup!$B$7) | T16: =IF(OR(B16="",C16=""),"",IF(G16="",IF(Setup!$B$7<=M16,"Notice due in "&(M16-Setup!$B$7)&" days",(Setup!$B$7-M16)&" days past the 28: serve it now; the Engineer has 14 days to object"),IF(G16<=M16,IF(L16="✔ valid","Served on time","Served on time, but it fails a test"),IF(O16<>"","Late, and the Engineer objected in time: argued in the determination",IF(Setup!$B$7>G16+14,"Late, but no objection within 14 days: treated as valid","Late: the Engineer has until "&TEXT(G16+14,"d mmm")&" to object"))))) | U16: =IF(OR(B16="",C16=""),"",IF(R16<>"",IF(S16="Y","Detailed claim in, with its contractual basis","Claim in without the contractual basis: the Notice may lapse"),IF(Setup!$B$7<=P16,(P16-Setup!$B$7)&" days left for the detailed claim","84 days passed: the Engineer has 14 days to declare a lapse"))) | V16: =IF(OR(B16="",C16=""),"",IF(G16="","Serve the Notice of Claim: identified as a Notice, to "&Setup!$B$9&", the stated way",IF(L16<>"✔ valid","Re-serve: the Notice fails a test",IF(R16="","Build the detailed claim: due "&TEXT(P16,"d mmm yyyy"),IF(S16<>"Y","Add the contractual basis to the claim","Wait: consultation, then the determination")))))
A17: E11 | L17: =IF(G17="","",IF(COUNTIF(H17:K17,"Y")=4,"✔ valid","Check: "&MID(IF(H17<>"Y",", writing","")&IF(I17<>"Y",", identified","")&IF(J17<>"Y",", delivery","")&IF(K17<>"Y",", address",""),3,60))) | M17: =IF(C17="","",C17+28) | N17: =IF(OR(C17="",G17<>""),"",M17-Setup!$B$7) | P17: =IF(C17="","",C17+84) | Q17: =IF(OR(C17="",R17<>""),"",P17-Setup!$B$7) | T17: =IF(OR(B17="",C17=""),"",IF(G17="",IF(Setup!$B$7<=M17,"Notice due in "&(M17-Setup!$B$7)&" days",(Setup!$B$7-M17)&" days past the 28: serve it now; the Engineer has 14 days to object"),IF(G17<=M17,IF(L17="✔ valid","Served on time","Served on time, but it fails a test"),IF(O17<>"","Late, and the Engineer objected in time: argued in the determination",IF(Setup!$B$7>G17+14,"Late, but no objection within 14 days: treated as valid","Late: the Engineer has until "&TEXT(G17+14,"d mmm")&" to object"))))) | U17: =IF(OR(B17="",C17=""),"",IF(R17<>"",IF(S17="Y","Detailed claim in, with its contractual basis","Claim in without the contractual basis: the Notice may lapse"),IF(Setup!$B$7<=P17,(P17-Setup!$B$7)&" days left for the detailed claim","84 days passed: the Engineer has 14 days to declare a lapse"))) | V17: =IF(OR(B17="",C17=""),"",IF(G17="","Serve the Notice of Claim: identified as a Notice, to "&Setup!$B$9&", the stated way",IF(L17<>"✔ valid","Re-serve: the Notice fails a test",IF(R17="","Build the detailed claim: due "&TEXT(P17,"d mmm yyyy"),IF(S17<>"Y","Add the contractual basis to the claim","Wait: consultation, then the determination")))))
A18: E12 | L18: =IF(G18="","",IF(COUNTIF(H18:K18,"Y")=4,"✔ valid","Check: "&MID(IF(H18<>"Y",", writing","")&IF(I18<>"Y",", identified","")&IF(J18<>"Y",", delivery","")&IF(K18<>"Y",", address",""),3,60))) | M18: =IF(C18="","",C18+28) | N18: =IF(OR(C18="",G18<>""),"",M18-Setup!$B$7) | P18: =IF(C18="","",C18+84) | Q18: =IF(OR(C18="",R18<>""),"",P18-Setup!$B$7) | T18: =IF(OR(B18="",C18=""),"",IF(G18="",IF(Setup!$B$7<=M18,"Notice due in "&(M18-Setup!$B$7)&" days",(Setup!$B$7-M18)&" days past the 28: serve it now; the Engineer has 14 days to object"),IF(G18<=M18,IF(L18="✔ valid","Served on time","Served on time, but it fails a test"),IF(O18<>"","Late, and the Engineer objected in time: argued in the determination",IF(Setup!$B$7>G18+14,"Late, but no objection within 14 days: treated as valid","Late: the Engineer has until "&TEXT(G18+14,"d mmm")&" to object"))))) | U18: =IF(OR(B18="",C18=""),"",IF(R18<>"",IF(S18="Y","Detailed claim in, with its contractual basis","Claim in without the contractual basis: the Notice may lapse"),IF(Setup!$B$7<=P18,(P18-Setup!$B$7)&" days left for the detailed claim","84 days passed: the Engineer has 14 days to declare a lapse"))) | V18: =IF(OR(B18="",C18=""),"",IF(G18="","Serve the Notice of Claim: identified as a Notice, to "&Setup!$B$9&", the stated way",IF(L18<>"✔ valid","Re-serve: the Notice fails a test",IF(R18="","Build the detailed claim: due "&TEXT(P18,"d mmm yyyy"),IF(S18<>"Y","Add the contractual basis to the claim","Wait: consultation, then the determination")))))
A19: E13 | L19: =IF(G19="","",IF(COUNTIF(H19:K19,"Y")=4,"✔ valid","Check: "&MID(IF(H19<>"Y",", writing","")&IF(I19<>"Y",", identified","")&IF(J19<>"Y",", delivery","")&IF(K19<>"Y",", address",""),3,60))) | M19: =IF(C19="","",C19+28) | N19: =IF(OR(C19="",G19<>""),"",M19-Setup!$B$7) | P19: =IF(C19="","",C19+84) | Q19: =IF(OR(C19="",R19<>""),"",P19-Setup!$B$7) | T19: =IF(OR(B19="",C19=""),"",IF(G19="",IF(Setup!$B$7<=M19,"Notice due in "&(M19-Setup!$B$7)&" days",(Setup!$B$7-M19)&" days past the 28: serve it now; the Engineer has 14 days to object"),IF(G19<=M19,IF(L19="✔ valid","Served on time","Served on time, but it fails a test"),IF(O19<>"","Late, and the Engineer objected in time: argued in the determination",IF(Setup!$B$7>G19+14,"Late, but no objection within 14 days: treated as valid","Late: the Engineer has until "&TEXT(G19+14,"d mmm")&" to object"))))) | U19: =IF(OR(B19="",C19=""),"",IF(R19<>"",IF(S19="Y","Detailed claim in, with its contractual basis","Claim in without the contractual basis: the Notice may lapse"),IF(Setup!$B$7<=P19,(P19-Setup!$B$7)&" days left for the detailed claim","84 days passed: the Engineer has 14 days to declare a lapse"))) | V19: =IF(OR(B19="",C19=""),"",IF(G19="","Serve the Notice of Claim: identified as a Notice, to "&Setup!$B$9&", the stated way",IF(L19<>"✔ valid","Re-serve: the Notice fails a test",IF(R19="","Build the detailed claim: due "&TEXT(P19,"d mmm yyyy"),IF(S19<>"Y","Add the contractual basis to the claim","Wait: consultation, then the determination")))))
A20: E14 | L20: =IF(G20="","",IF(COUNTIF(H20:K20,"Y")=4,"✔ valid","Check: "&MID(IF(H20<>"Y",", writing","")&IF(I20<>"Y",", identified","")&IF(J20<>"Y",", delivery","")&IF(K20<>"Y",", address",""),3,60))) | M20: =IF(C20="","",C20+28) | N20: =IF(OR(C20="",G20<>""),"",M20-Setup!$B$7) | P20: =IF(C20="","",C20+84) | Q20: =IF(OR(C20="",R20<>""),"",P20-Setup!$B$7) | T20: =IF(OR(B20="",C20=""),"",IF(G20="",IF(Setup!$B$7<=M20,"Notice due in "&(M20-Setup!$B$7)&" days",(Setup!$B$7-M20)&" days past the 28: serve it now; the Engineer has 14 days to object"),IF(G20<=M20,IF(L20="✔ valid","Served on time","Served on time, but it fails a test"),IF(O20<>"","Late, and the Engineer objected in time: argued in the determination",IF(Setup!$B$7>G20+14,"Late, but no objection within 14 days: treated as valid","Late: the Engineer has until "&TEXT(G20+14,"d mmm")&" to object"))))) | U20: =IF(OR(B20="",C20=""),"",IF(R20<>"",IF(S20="Y","Detailed claim in, with its contractual basis","Claim in without the contractual basis: the Notice may lapse"),IF(Setup!$B$7<=P20,(P20-Setup!$B$7)&" days left for the detailed claim","84 days passed: the Engineer has 14 days to declare a lapse"))) | V20: =IF(OR(B20="",C20=""),"",IF(G20="","Serve the Notice of Claim: identified as a Notice, to "&Setup!$B$9&", the stated way",IF(L20<>"✔ valid","Re-serve: the Notice fails a test",IF(R20="","Build the detailed claim: due "&TEXT(P20,"d mmm yyyy"),IF(S20<>"Y","Add the contractual basis to the claim","Wait: consultation, then the determination")))))
A21: E15 | L21: =IF(G21="","",IF(COUNTIF(H21:K21,"Y")=4,"✔ valid","Check: "&MID(IF(H21<>"Y",", writing","")&IF(I21<>"Y",", identified","")&IF(J21<>"Y",", delivery","")&IF(K21<>"Y",", address",""),3,60))) | M21: =IF(C21="","",C21+28) | N21: =IF(OR(C21="",G21<>""),"",M21-Setup!$B$7) | P21: =IF(C21="","",C21+84) | Q21: =IF(OR(C21="",R21<>""),"",P21-Setup!$B$7) | T21: =IF(OR(B21="",C21=""),"",IF(G21="",IF(Setup!$B$7<=M21,"Notice due in "&(M21-Setup!$B$7)&" days",(Setup!$B$7-M21)&" days past the 28: serve it now; the Engineer has 14 days to object"),IF(G21<=M21,IF(L21="✔ valid","Served on time","Served on time, but it fails a test"),IF(O21<>"","Late, and the Engineer objected in time: argued in the determination",IF(Setup!$B$7>G21+14,"Late, but no objection within 14 days: treated as valid","Late: the Engineer has until "&TEXT(G21+14,"d mmm")&" to object"))))) | U21: =IF(OR(B21="",C21=""),"",IF(R21<>"",IF(S21="Y","Detailed claim in, with its contractual basis","Claim in without the contractual basis: the Notice may lapse"),IF(Setup!$B$7<=P21,(P21-Setup!$B$7)&" days left for the detailed claim","84 days passed: the Engineer has 14 days to declare a lapse"))) | V21: =IF(OR(B21="",C21=""),"",IF(G21="","Serve the Notice of Claim: identified as a Notice, to "&Setup!$B$9&", the stated way",IF(L21<>"✔ valid","Re-serve: the Notice fails a test",IF(R21="","Build the detailed claim: due "&TEXT(P21,"d mmm yyyy"),IF(S21<>"Y","Add the contractual basis to the claim","Wait: consultation, then the determination")))))
... A36: E30 | L36: =IF(G36="","",IF(COUNTIF(H36:K36,"Y")=4,"✔ valid","Check: "&MID(IF(H36<>"Y",", writing","")&IF(I36<>"Y",", identified","")&IF(J36<>"Y",", delivery","")&IF(K36<>"Y",", address",""),3,60))) | M36: =IF(C36="","",C36+28) | N36: =IF(OR(C36="",G36<>""),"",M36-Setup!$B$7) | P36: =IF(C36="","",C36+84) | Q36: =IF(OR(C36="",R36<>""),"",P36-Setup!$B$7) | T36: =IF(OR(B36="",C36=""),"",IF(G36="",IF(Setup!$B$7<=M36,"Notice due in "&(M36-Setup!$B$7)&" days",(Setup!$B$7-M36)&" days past the 28: serve it now; the Engineer has 14 days to object"),IF(G36<=M36,IF(L36="✔ valid","Served on time","Served on time, but it fails a test"),IF(O36<>"","Late, and the Engineer objected in time: argued in the determination",IF(Setup!$B$7>G36+14,"Late, but no objection within 14 days: treated as valid","Late: the Engineer has until "&TEXT(G36+14,"d mmm")&" to object"))))) | U36: =IF(OR(B36="",C36=""),"",IF(R36<>"",IF(S36="Y","Detailed claim in, with its contractual basis","Claim in without the contractual basis: the Notice may lapse"),IF(Setup!$B$7<=P36,(P36-Setup!$B$7)&" days left for the detailed claim","84 days passed: the Engineer has 14 days to declare a lapse"))) | V36: =IF(OR(B36="",C36=""),"",IF(G36="","Serve the Notice of Claim: identified as a Notice, to "&Setup!$B$9&", the stated way",IF(L36<>"✔ valid","Re-serve: the Notice fails a test",IF(R36="","Build the detailed claim: due "&TEXT(P36,"d mmm yyyy"),IF(S36<>"Y","Add the contractual basis to the claim","Wait: consultation, then the determination")))))

Sheet Engineer clocks
A1: Engineer clocks | I1: The Project Control Hub
A2: Somebody else’s deadline. If nothing comes back, the position moves your way.
A3: Diarise these precisely: nobody is going to tell you they have expired.
A6: Ref | B6: About | C6: Clock | D6: Starts (date) | E6: Days | F6: Ends | G6: Days left | H6: Engineer responded on | I6: Status
A7: S01 | E7: =IF(C7="","",IF(LEFT(C7,6)="Answer",7,14)) | F7: =IF(OR(D7="",E7=""),"",D7+E7) | G7: =IF(OR(F7="",H7<>""),"",F7-Setup!$B$7) | I7: =IF(OR(C7="",D7=""),"",IF(H7<>"","The Engineer responded: deal with the substance",IF(Setup!$B$7>F7,"Expired in your favour: "&IF(LEFT(C7,4)="Late","your Notice is treated as valid",IF(LEFT(C7,5)="Lapse","your Notice survives","the instruction is revoked")),"Running: "&G7&" days left")))
A8: S02 | E8: =IF(C8="","",IF(LEFT(C8,6)="Answer",7,14)) | F8: =IF(OR(D8="",E8=""),"",D8+E8) | G8: =IF(OR(F8="",H8<>""),"",F8-Setup!$B$7) | I8: =IF(OR(C8="",D8=""),"",IF(H8<>"","The Engineer responded: deal with the substance",IF(Setup!$B$7>F8,"Expired in your favour: "&IF(LEFT(C8,4)="Late","your Notice is treated as valid",IF(LEFT(C8,5)="Lapse","your Notice survives","the instruction is revoked")),"Running: "&G8&" days left")))
A9: S03 | E9: =IF(C9="","",IF(LEFT(C9,6)="Answer",7,14)) | F9: =IF(OR(D9="",E9=""),"",D9+E9) | G9: =IF(OR(F9="",H9<>""),"",F9-Setup!$B$7) | I9: =IF(OR(C9="",D9=""),"",IF(H9<>"","The Engineer responded: deal with the substance",IF(Setup!$B$7>F9,"Expired in your favour: "&IF(LEFT(C9,4)="Late","your Notice is treated as valid",IF(LEFT(C9,5)="Lapse","your Notice survives","the instruction is revoked")),"Running: "&G9&" days left")))
A10: S04 | E10: =IF(C10="","",IF(LEFT(C10,6)="Answer",7,14)) | F10: =IF(OR(D10="",E10=""),"",D10+E10) | G10: =IF(OR(F10="",H10<>""),"",F10-Setup!$B$7) | I10: =IF(OR(C10="",D10=""),"",IF(H10<>"","The Engineer responded: deal with the substance",IF(Setup!$B$7>F10,"Expired in your favour: "&IF(LEFT(C10,4)="Late","your Notice is treated as valid",IF(LEFT(C10,5)="Lapse","your Notice survives","the instruction is revoked")),"Running: "&G10&" days left")))
A11: S05 | E11: =IF(C11="","",IF(LEFT(C11,6)="Answer",7,14)) | F11: =IF(OR(D11="",E11=""),"",D11+E11) | G11: =IF(OR(F11="",H11<>""),"",F11-Setup!$B$7) | I11: =IF(OR(C11="",D11=""),"",IF(H11<>"","The Engineer responded: deal with the substance",IF(Setup!$B$7>F11,"Expired in your favour: "&IF(LEFT(C11,4)="Late","your Notice is treated as valid",IF(LEFT(C11,5)="Lapse","your Notice survives","the instruction is revoked")),"Running: "&G11&" days left")))
A12: S06 | E12: =IF(C12="","",IF(LEFT(C12,6)="Answer",7,14)) | F12: =IF(OR(D12="",E12=""),"",D12+E12) | G12: =IF(OR(F12="",H12<>""),"",F12-Setup!$B$7) | I12: =IF(OR(C12="",D12=""),"",IF(H12<>"","The Engineer responded: deal with the substance",IF(Setup!$B$7>F12,"Expired in your favour: "&IF(LEFT(C12,4)="Late","your Notice is treated as valid",IF(LEFT(C12,5)="Lapse","your Notice survives","the instruction is revoked")),"Running: "&G12&" days left")))
A13: S07 | E13: =IF(C13="","",IF(LEFT(C13,6)="Answer",7,14)) | F13: =IF(OR(D13="",E13=""),"",D13+E13) | G13: =IF(OR(F13="",H13<>""),"",F13-Setup!$B$7) | I13: =IF(OR(C13="",D13=""),"",IF(H13<>"","The Engineer responded: deal with the substance",IF(Setup!$B$7>F13,"Expired in your favour: "&IF(LEFT(C13,4)="Late","your Notice is treated as valid",IF(LEFT(C13,5)="Lapse","your Notice survives","the instruction is revoked")),"Running: "&G13&" days left")))
A14: S08 | E14: =IF(C14="","",IF(LEFT(C14,6)="Answer",7,14)) | F14: =IF(OR(D14="",E14=""),"",D14+E14) | G14: =IF(OR(F14="",H14<>""),"",F14-Setup!$B$7) | I14: =IF(OR(C14="",D14=""),"",IF(H14<>"","The Engineer responded: deal with the substance",IF(Setup!$B$7>F14,"Expired in your favour: "&IF(LEFT(C14,4)="Late","your Notice is treated as valid",IF(LEFT(C14,5)="Lapse","your Notice survives","the instruction is revoked")),"Running: "&G14&" days left")))
A15: S09 | E15: =IF(C15="","",IF(LEFT(C15,6)="Answer",7,14)) | F15: =IF(OR(D15="",E15=""),"",D15+E15) | G15: =IF(OR(F15="",H15<>""),"",F15-Setup!$B$7) | I15: =IF(OR(C15="",D15=""),"",IF(H15<>"","The Engineer responded: deal with the substance",IF(Setup!$B$7>F15,"Expired in your favour: "&IF(LEFT(C15,4)="Late","your Notice is treated as valid",IF(LEFT(C15,5)="Lapse","your Notice survives","the instruction is revoked")),"Running: "&G15&" days left")))
A16: S10 | E16: =IF(C16="","",IF(LEFT(C16,6)="Answer",7,14)) | F16: =IF(OR(D16="",E16=""),"",D16+E16) | G16: =IF(OR(F16="",H16<>""),"",F16-Setup!$B$7) | I16: =IF(OR(C16="",D16=""),"",IF(H16<>"","The Engineer responded: deal with the substance",IF(Setup!$B$7>F16,"Expired in your favour: "&IF(LEFT(C16,4)="Late","your Notice is treated as valid",IF(LEFT(C16,5)="Lapse","your Notice survives","the instruction is revoked")),"Running: "&G16&" days left")))
A17: S11 | E17: =IF(C17="","",IF(LEFT(C17,6)="Answer",7,14)) | F17: =IF(OR(D17="",E17=""),"",D17+E17) | G17: =IF(OR(F17="",H17<>""),"",F17-Setup!$B$7) | I17: =IF(OR(C17="",D17=""),"",IF(H17<>"","The Engineer responded: deal with the substance",IF(Setup!$B$7>F17,"Expired in your favour: "&IF(LEFT(C17,4)="Late","your Notice is treated as valid",IF(LEFT(C17,5)="Lapse","your Notice survives","the instruction is revoked")),"Running: "&G17&" days left")))
A18: S12 | E18: =IF(C18="","",IF(LEFT(C18,6)="Answer",7,14)) | F18: =IF(OR(D18="",E18=""),"",D18+E18) | G18: =IF(OR(F18="",H18<>""),"",F18-Setup!$B$7) | I18: =IF(OR(C18="",D18=""),"",IF(H18<>"","The Engineer responded: deal with the substance",IF(Setup!$B$7>F18,"Expired in your favour: "&IF(LEFT(C18,4)="Late","your Notice is treated as valid",IF(LEFT(C18,5)="Lapse","your Notice survives","the instruction is revoked")),"Running: "&G18&" days left")))
... A26: S20 | E26: =IF(C26="","",IF(LEFT(C26,6)="Answer",7,14)) | F26: =IF(OR(D26="",E26=""),"",D26+E26) | G26: =IF(OR(F26="",H26<>""),"",F26-Setup!$B$7) | I26: =IF(OR(C26="",D26=""),"",IF(H26<>"","The Engineer responded: deal with the substance",IF(Setup!$B$7>F26,"Expired in your favour: "&IF(LEFT(C26,4)="Late","your Notice is treated as valid",IF(LEFT(C26,5)="Lapse","your Notice survives","the instruction is revoked")),"Running: "&G26&" days left")))

Sheet Determinations
A1: Determinations | H1: The Project Control Hub
A2: The clock with no rescue: 28 days to give a Notice of Dissatisfaction.
A3: Log every determination the day it lands. Nobody else will tell you this clock has started.
A6: Ref | B6: Determination about | C6: Event ID | D6: Received (date) | E6: Notice of Dissatisfaction deadline | F6: Days left | G6: Notice of Dissatisfaction given (date) | H6: Status
A7: D01 | E7: =IF(D7="","",D7+28) | F7: =IF(OR(D7="",G7<>""),"",E7-Setup!$B$7) | H7: =IF(OR(B7="",D7=""),"",IF(G7<>"",IF(G7<=E7,"Given in time","Given late: final and binding"),IF(Setup!$B$7>E7,"Missed: final and binding. No rescue",(E7-Setup!$B$7)&" days left. No rescue if missed")))
A8: D02 | E8: =IF(D8="","",D8+28) | F8: =IF(OR(D8="",G8<>""),"",E8-Setup!$B$7) | H8: =IF(OR(B8="",D8=""),"",IF(G8<>"",IF(G8<=E8,"Given in time","Given late: final and binding"),IF(Setup!$B$7>E8,"Missed: final and binding. No rescue",(E8-Setup!$B$7)&" days left. No rescue if missed")))
A9: D03 | E9: =IF(D9="","",D9+28) | F9: =IF(OR(D9="",G9<>""),"",E9-Setup!$B$7) | H9: =IF(OR(B9="",D9=""),"",IF(G9<>"",IF(G9<=E9,"Given in time","Given late: final and binding"),IF(Setup!$B$7>E9,"Missed: final and binding. No rescue",(E9-Setup!$B$7)&" days left. No rescue if missed")))
A10: D04 | E10: =IF(D10="","",D10+28) | F10: =IF(OR(D10="",G10<>""),"",E10-Setup!$B$7) | H10: =IF(OR(B10="",D10=""),"",IF(G10<>"",IF(G10<=E10,"Given in time","Given late: final and binding"),IF(Setup!$B$7>E10,"Missed: final and binding. No rescue",(E10-Setup!$B$7)&" days left. No rescue if missed")))
A11: D05 | E11: =IF(D11="","",D11+28) | F11: =IF(OR(D11="",G11<>""),"",E11-Setup!$B$7) | H11: =IF(OR(B11="",D11=""),"",IF(G11<>"",IF(G11<=E11,"Given in time","Given late: final and binding"),IF(Setup!$B$7>E11,"Missed: final and binding. No rescue",(E11-Setup!$B$7)&" days left. No rescue if missed")))
A12: D06 | E12: =IF(D12="","",D12+28) | F12: =IF(OR(D12="",G12<>""),"",E12-Setup!$B$7) | H12: =IF(OR(B12="",D12=""),"",IF(G12<>"",IF(G12<=E12,"Given in time","Given late: final and binding"),IF(Setup!$B$7>E12,"Missed: final and binding. No rescue",(E12-Setup!$B$7)&" days left. No rescue if missed")))
A13: D07 | E13: =IF(D13="","",D13+28) | F13: =IF(OR(D13="",G13<>""),"",E13-Setup!$B$7) | H13: =IF(OR(B13="",D13=""),"",IF(G13<>"",IF(G13<=E13,"Given in time","Given late: final and binding"),IF(Setup!$B$7>E13,"Missed: final and binding. No rescue",(E13-Setup!$B$7)&" days left. No rescue if missed")))
A14: D08 | E14: =IF(D14="","",D14+28) | F14: =IF(OR(D14="",G14<>""),"",E14-Setup!$B$7) | H14: =IF(OR(B14="",D14=""),"",IF(G14<>"",IF(G14<=E14,"Given in time","Given late: final and binding"),IF(Setup!$B$7>E14,"Missed: final and binding. No rescue",(E14-Setup!$B$7)&" days left. No rescue if missed")))
A15: D09 | E15: =IF(D15="","",D15+28) | F15: =IF(OR(D15="",G15<>""),"",E15-Setup!$B$7) | H15: =IF(OR(B15="",D15=""),"",IF(G15<>"",IF(G15<=E15,"Given in time","Given late: final and binding"),IF(Setup!$B$7>E15,"Missed: final and binding. No rescue",(E15-Setup!$B$7)&" days left. No rescue if missed")))
A16: D10 | E16: =IF(D16="","",D16+28) | F16: =IF(OR(D16="",G16<>""),"",E16-Setup!$B$7) | H16: =IF(OR(B16="",D16=""),"",IF(G16<>"",IF(G16<=E16,"Given in time","Given late: final and binding"),IF(Setup!$B$7>E16,"Missed: final and binding. No rescue",(E16-Setup!$B$7)&" days left. No rescue if missed")))
A17: D11 | E17: =IF(D17="","",D17+28) | F17: =IF(OR(D17="",G17<>""),"",E17-Setup!$B$7) | H17: =IF(OR(B17="",D17=""),"",IF(G17<>"",IF(G17<=E17,"Given in time","Given late: final and binding"),IF(Setup!$B$7>E17,"Missed: final and binding. No rescue",(E17-Setup!$B$7)&" days left. No rescue if missed")))
A18: D12 | E18: =IF(D18="","",D18+28) | F18: =IF(OR(D18="",G18<>""),"",E18-Setup!$B$7) | H18: =IF(OR(B18="",D18=""),"",IF(G18<>"",IF(G18<=E18,"Given in time","Given late: final and binding"),IF(Setup!$B$7>E18,"Missed: final and binding. No rescue",(E18-Setup!$B$7)&" days left. No rescue if missed")))
... A26: D20 | E26: =IF(D26="","",D26+28) | F26: =IF(OR(D26="",G26<>""),"",E26-Setup!$B$7) | H26: =IF(OR(B26="",D26=""),"",IF(G26<>"",IF(G26<=E26,"Given in time","Given late: final and binding"),IF(Setup!$B$7>E26,"Missed: final and binding. No rescue",(E26-Setup!$B$7)&" days left. No rescue if missed")))

Sheet Deadlines
A1: Deadlines
A2: Every open deadline in one list. The Dashboard reads it; nothing to fill in here.
A6: Deadline | B6: Event / item | C6: Clock | D6: Rescue | E6: Sort key
A7: =IF(AND(Events!B7<>"",Events!C7<>"",Events!G7=""),Events!M7,"") -> 46112 | B7: =IF(A7="","",Events!A7&" · "&Events!B7) -> E01 · Rock in the north pile bores | C7: Notice of Claim · 28 d | D7: Engineer silent 14 days | E7: =IF(A7="","",A7+ROW()/100000) -> 46112
A8: =IF(AND(Events!B7<>"",Events!C7<>"",Events!R7=""),Events!P7,"") -> 46168 | B8: =IF(A8="","",Events!A7&" · "&Events!B7) -> E01 · Rock in the north pile bores | C8: Detailed claim · 84 d | D8: Engineer silent 14 days | E8: =IF(A8="","",A8+ROW()/100000) -> 46168
A9: =IF(AND(Events!B8<>"",Events!C8<>"",Events!G8=""),Events!M8,"") | B9: =IF(A9="","",Events!A8&" · "&Events!B8) | C9: Notice of Claim · 28 d | D9: Engineer silent 14 days | E9: =IF(A9="","",A9+ROW()/100000)
A10: =IF(AND(Events!B8<>"",Events!C8<>"",Events!R8=""),Events!P8,"") -> 46169 | B10: =IF(A10="","",Events!A8&" · "&Events!B8) -> E02 · Late bar schedule revision, raft bay 2 | C10: Detailed claim · 84 d | D10: Engineer silent 14 days | E10: =IF(A10="","",A10+ROW()/100000) -> 46169
A11: =IF(AND(Events!B9<>"",Events!C9<>"",Events!G9=""),Events!M9,"") -> 46129 | B11: =IF(A11="","",Events!A9&" · "&Events!B9) -> E03 · Groundwater in the raft excavation | C11: Notice of Claim · 28 d | D11: Engineer silent 14 days | E11: =IF(A11="","",A11+ROW()/100000) -> 46129
A12: =IF(AND(Events!B9<>"",Events!C9<>"",Events!R9=""),Events!P9,"") -> 46185 | B12: =IF(A12="","",Events!A9&" · "&Events!B9) -> E03 · Groundwater in the raft excavation | C12: Detailed claim · 84 d | D12: Engineer silent 14 days | E12: =IF(A12="","",A12+ROW()/100000) -> 46185
A13: =IF(AND(Events!B10<>"",Events!C10<>"",Events!G10=""),Events!M10,"") | B13: =IF(A13="","",Events!A10&" · "&Events!B10) | C13: Notice of Claim · 28 d | D13: Engineer silent 14 days | E13: =IF(A13="","",A13+ROW()/100000)
A14: =IF(AND(Events!B10<>"",Events!C10<>"",Events!R10=""),Events!P10,"") | B14: =IF(A14="","",Events!A10&" · "&Events!B10) | C14: Detailed claim · 84 d | D14: Engineer silent 14 days | E14: =IF(A14="","",A14+ROW()/100000)
A15: =IF(AND(Events!B11<>"",Events!C11<>"",Events!G11=""),Events!M11,"") | B15: =IF(A15="","",Events!A11&" · "&Events!B11) | C15: Notice of Claim · 28 d | D15: Engineer silent 14 days | E15: =IF(A15="","",A15+ROW()/100000)
A16: =IF(AND(Events!B11<>"",Events!C11<>"",Events!R11=""),Events!P11,"") | B16: =IF(A16="","",Events!A11&" · "&Events!B11) | C16: Detailed claim · 84 d | D16: Engineer silent 14 days | E16: =IF(A16="","",A16+ROW()/100000)
A17: =IF(AND(Events!B12<>"",Events!C12<>"",Events!G12=""),Events!M12,"") | B17: =IF(A17="","",Events!A12&" · "&Events!B12) | C17: Notice of Claim · 28 d | D17: Engineer silent 14 days | E17: =IF(A17="","",A17+ROW()/100000)
A18: =IF(AND(Events!B12<>"",Events!C12<>"",Events!R12=""),Events!P12,"") | B18: =IF(A18="","",Events!A12&" · "&Events!B12) | C18: Detailed claim · 84 d | D18: Engineer silent 14 days | E18: =IF(A18="","",A18+ROW()/100000)
A19: =IF(AND(Events!B13<>"",Events!C13<>"",Events!G13=""),Events!M13,"") | B19: =IF(A19="","",Events!A13&" · "&Events!B13) | C19: Notice of Claim · 28 d | D19: Engineer silent 14 days | E19: =IF(A19="","",A19+ROW()/100000)
A20: =IF(AND(Events!B13<>"",Events!C13<>"",Events!R13=""),Events!P13,"") | B20: =IF(A20="","",Events!A13&" · "&Events!B13) | C20: Detailed claim · 84 d | D20: Engineer silent 14 days | E20: =IF(A20="","",A20+ROW()/100000)
A21: =IF(AND(Events!B14<>"",Events!C14<>"",Events!G14=""),Events!M14,"") | B21: =IF(A21="","",Events!A14&" · "&Events!B14) | C21: Notice of Claim · 28 d | D21: Engineer silent 14 days | E21: =IF(A21="","",A21+ROW()/100000)
A22: =IF(AND(Events!B14<>"",Events!C14<>"",Events!R14=""),Events!P14,"") | B22: =IF(A22="","",Events!A14&" · "&Events!B14) | C22: Detailed claim · 84 d | D22: Engineer silent 14 days | E22: =IF(A22="","",A22+ROW()/100000)
A23: =IF(AND(Events!B15<>"",Events!C15<>"",Events!G15=""),Events!M15,"") | B23: =IF(A23="","",Events!A15&" · "&Events!B15) | C23: Notice of Claim · 28 d | D23: Engineer silent 14 days | E23: =IF(A23="","",A23+ROW()/100000)
A24: =IF(AND(Events!B15<>"",Events!C15<>"",Events!R15=""),Events!P15,"") | B24: =IF(A24="","",Events!A15&" · "&Events!B15) | C24: Detailed claim · 84 d | D24: Engineer silent 14 days | E24: =IF(A24="","",A24+ROW()/100000)
A25: =IF(AND(Events!B16<>"",Events!C16<>"",Events!G16=""),Events!M16,"") | B25: =IF(A25="","",Events!A16&" · "&Events!B16) | C25: Notice of Claim · 28 d | D25: Engineer silent 14 days | E25: =IF(A25="","",A25+ROW()/100000)
A26: =IF(AND(Events!B16<>"",Events!C16<>"",Events!R16=""),Events!P16,"") | B26: =IF(A26="","",Events!A16&" · "&Events!B16) | C26: Detailed claim · 84 d | D26: Engineer silent 14 days | E26: =IF(A26="","",A26+ROW()/100000)
A27: =IF(AND(Events!B17<>"",Events!C17<>"",Events!G17=""),Events!M17,"") | B27: =IF(A27="","",Events!A17&" · "&Events!B17) | C27: Notice of Claim · 28 d | D27: Engineer silent 14 days | E27: =IF(A27="","",A27+ROW()/100000)
A28: =IF(AND(Events!B17<>"",Events!C17<>"",Events!R17=""),Events!P17,"") | B28: =IF(A28="","",Events!A17&" · "&Events!B17) | C28: Detailed claim · 84 d | D28: Engineer silent 14 days | E28: =IF(A28="","",A28+ROW()/100000)
A29: =IF(AND(Events!B18<>"",Events!C18<>"",Events!G18=""),Events!M18,"") | B29: =IF(A29="","",Events!A18&" · "&Events!B18) | C29: Notice of Claim · 28 d | D29: Engineer silent 14 days | E29: =IF(A29="","",A29+ROW()/100000)
A30: =IF(AND(Events!B18<>"",Events!C18<>"",Events!R18=""),Events!P18,"") | B30: =IF(A30="","",Events!A18&" · "&Events!B18) | C30: Detailed claim · 84 d | D30: Engineer silent 14 days | E30: =IF(A30="","",A30+ROW()/100000)
A31: =IF(AND(Events!B19<>"",Events!C19<>"",Events!G19=""),Events!M19,"") | B31: =IF(A31="","",Events!A19&" · "&Events!B19) | C31: Notice of Claim · 28 d | D31: Engineer silent 14 days | E31: =IF(A31="","",A31+ROW()/100000)
A32: =IF(AND(Events!B19<>"",Events!C19<>"",Events!R19=""),Events!P19,"") | B32: =IF(A32="","",Events!A19&" · "&Events!B19) | C32: Detailed claim · 84 d | D32: Engineer silent 14 days | E32: =IF(A32="","",A32+ROW()/100000)
A33: =IF(AND(Events!B20<>"",Events!C20<>"",Events!G20=""),Events!M20,"") | B33: =IF(A33="","",Events!A20&" · "&Events!B20) | C33: Notice of Claim · 28 d | D33: Engineer silent 14 days | E33: =IF(A33="","",A33+ROW()/100000)
A34: =IF(AND(Events!B20<>"",Events!C20<>"",Events!R20=""),Events!P20,"") | B34: =IF(A34="","",Events!A20&" · "&Events!B20) | C34: Detailed claim · 84 d | D34: Engineer silent 14 days | E34: =IF(A34="","",A34+ROW()/100000)
A35: =IF(AND(Events!B21<>"",Events!C21<>"",Events!G21=""),Events!M21,"") | B35: =IF(A35="","",Events!A21&" · "&Events!B21) | C35: Notice of Claim · 28 d | D35: Engineer silent 14 days | E35: =IF(A35="","",A35+ROW()/100000)
A36: =IF(AND(Events!B21<>"",Events!C21<>"",Events!R21=""),Events!P21,"") | B36: =IF(A36="","",Events!A21&" · "&Events!B21) | C36: Detailed claim · 84 d | D36: Engineer silent 14 days | E36: =IF(A36="","",A36+ROW()/100000)
A37: =IF(AND(Events!B22<>"",Events!C22<>"",Events!G22=""),Events!M22,"") | B37: =IF(A37="","",Events!A22&" · "&Events!B22) | C37: Notice of Claim · 28 d | D37: Engineer silent 14 days | E37: =IF(A37="","",A37+ROW()/100000)
A38: =IF(AND(Events!B22<>"",Events!C22<>"",Events!R22=""),Events!P22,"") | B38: =IF(A38="","",Events!A22&" · "&Events!B22) | C38: Detailed claim · 84 d | D38: Engineer silent 14 days | E38: =IF(A38="","",A38+ROW()/100000)
A39: =IF(AND(Events!B23<>"",Events!C23<>"",Events!G23=""),Events!M23,"") | B39: =IF(A39="","",Events!A23&" · "&Events!B23) | C39: Notice of Claim · 28 d | D39: Engineer silent 14 days | E39: =IF(A39="","",A39+ROW()/100000)
A40: =IF(AND(Events!B23<>"",Events!C23<>"",Events!R23=""),Events!P23,"") | B40: =IF(A40="","",Events!A23&" · "&Events!B23) | C40: Detailed claim · 84 d | D40: Engineer silent 14 days | E40: =IF(A40="","",A40+ROW()/100000)
A41: =IF(AND(Events!B24<>"",Events!C24<>"",Events!G24=""),Events!M24,"") | B41: =IF(A41="","",Events!A24&" · "&Events!B24) | C41: Notice of Claim · 28 d | D41: Engineer silent 14 days | E41: =IF(A41="","",A41+ROW()/100000)
A42: =IF(AND(Events!B24<>"",Events!C24<>"",Events!R24=""),Events!P24,"") | B42: =IF(A42="","",Events!A24&" · "&Events!B24) | C42: Detailed claim · 84 d | D42: Engineer silent 14 days | E42: =IF(A42="","",A42+ROW()/100000)
A43: =IF(AND(Events!B25<>"",Events!C25<>"",Events!G25=""),Events!M25,"") | B43: =IF(A43="","",Events!A25&" · "&Events!B25) | C43: Notice of Claim · 28 d | D43: Engineer silent 14 days | E43: =IF(A43="","",A43+ROW()/100000)
...
