Workbook

Sheet Start
B2: Risk register
B3: Written as sentences, priced in money, split into what information can fix and what only money can cover.
B4: The Project Control Hub · free template
B7: A REVIEW, IN SIX STEPS
B8: 1 | C8: Setup → | D8: Set the review date and the contingency you carry. | E8: 1 minute
B9: 2 | C9: Register → | D9: Write each risk as one sentence: Because [a fact today], [an uncertain event] may occur, which would lead to [an effect in money or days]. The Sentence column checks all three parts. | E9: per risk
B10: 3 | C10: Register → | D10: Kind: ask the one question. If finding out would shrink it, it is epistemic; if not, aleatory. | E10: per risk
B11: 4 | C11: Register → | D11: Money: probability and impact give the expected value. For every epistemic risk, write what it would cost to find out. A zero is usually an email nobody has sent. | E11: per risk
B12: 5 | C12: Register → | D12: Response: a type, the action, its price, one person, a date, and the condition that closes the risk. | E12: per risk
B13: 6 | C13: Dashboard → | D13: Read it at the review. Then copy the "This review" row into History. | E13: 5 minutes
B15: THE ONE QUESTION
C16: Epistemic | D16: The answer already exists somewhere. Spend money finding out and it gets smaller. It wants information: a borehole, a phone call, a credit check.
C17: Aleatory | D17: It has not happened yet, so nobody can know it. It wants money: measure the spread and hold contingency against it.
C18: Mixed | D18: Part countable today, part not. Say so rather than forcing it into one column.
B20: HOW TO READ THE CELLS
C21: Yellow, blue text | D21: Yours to fill in.
C22: White, black text | D22: A formula. Leave it alone and it keeps working.
C23: Green | D23: Done, complete, or free to resolve.
C24: Amber | D24: Something is missing: a part of the sentence, a price, a date.
C25: Red | D25: Overdue, or an open risk with nobody against it.
B27: WHAT IS IN THIS FILE
C28: Dashboard | D28: Six numbers, four charts and the ten largest open risks.
C29: Setup | D29: Review date, contingency, and the team and category lists.
C30: Register | D30: Forty rows: sentence, kind, money, response, owner, date, status.
C31: History | D31: One row per review, for the exposure trend.
B33: EXPLAINED IN
C34: Risk Topic 4 · Writing a risk as a sentence
C35: Risk Topic 6 · Why the matrix misleads
C36: Risk Topic 8 · Aleatory and epistemic uncertainty
C37: Risk Topic 13 · Response strategies
B39: Blank: forty rows ready to fill. The example file shows the fourteen risks of the example project.
B43: Free to use and adapt on your own projects. https://theprojectcontrolhub.com/

Sheet Dashboard
B2: Risk register | K2: The Project Control Hub
B3: =IF(Setup!B6="","Fill in the Setup sheet first",Setup!B6&" · Review "&Setup!B7&" · "&TEXT(Setup!B8,"d mmm yyyy")&" · "&Setup!B10)
B5: TOTAL EXPECTED VALUE | D5: EPISTEMIC · BUY INFORMATION | F5: FREE TO RESOLVE | H5: RESPONSE SPEND | J5: CONTINGENCY CARRIED | L5: RESPONSES OVERDUE | P5: Chart data (formulas)
B6: =Register!$E$50 | D6: =Register!$E$51 | F6: =Register!$E$56 | H6: =Register!$E$57 | J6: =Setup!B9 | L6: =Register!$E$61 | P6: Top 10 by expected value
P7: =IFERROR(INDEX(Register!$B$7:$B$46,MATCH(1,Register!$X$7:$X$46,0)),"") | Q7: =IFERROR(INDEX(Register!$K$7:$K$46,MATCH(1,Register!$X$7:$X$46,0)),0)
B8: ="across "&Register!$E$49&" open risks" | D8: =Register!$E$54&" risks · "&TEXT(Register!$E$55,"$#,##0")&" to find out" | F8: ="epistemic risks: send the emails" | H8: =Register!$E$58&" priced · "&Register!$E$59&" done" | J8: =IF(OR(Setup!B9="",Register!$E$50=0),"",TEXT(Setup!B9/Register!$E$50,"0%")&" of the expected value") | L8: =Register!$E$60&" open risk(s) with no owner" | P8: =IFERROR(INDEX(Register!$B$7:$B$46,MATCH(2,Register!$X$7:$X$46,0)),"") | Q8: =IFERROR(INDEX(Register!$K$7:$K$46,MATCH(2,Register!$X$7:$X$46,0)),0)
P9: =IFERROR(INDEX(Register!$B$7:$B$46,MATCH(3,Register!$X$7:$X$46,0)),"") | Q9: =IFERROR(INDEX(Register!$K$7:$K$46,MATCH(3,Register!$X$7:$X$46,0)),0)
P10: =IFERROR(INDEX(Register!$B$7:$B$46,MATCH(4,Register!$X$7:$X$46,0)),"") | Q10: =IFERROR(INDEX(Register!$K$7:$K$46,MATCH(4,Register!$X$7:$X$46,0)),0)
B11: The one question for every line: if I spent money finding out, would the uncertainty get smaller? Yes → epistemic: buy information. No → aleatory: hold money. | P11: =IFERROR(INDEX(Register!$B$7:$B$46,MATCH(5,Register!$X$7:$X$46,0)),"") | Q11: =IFERROR(INDEX(Register!$K$7:$K$46,MATCH(5,Register!$X$7:$X$46,0)),0)
P12: =IFERROR(INDEX(Register!$B$7:$B$46,MATCH(6,Register!$X$7:$X$46,0)),"") | Q12: =IFERROR(INDEX(Register!$K$7:$K$46,MATCH(6,Register!$X$7:$X$46,0)),0)
B13: WHERE THE MONEY IS | P13: =IFERROR(INDEX(Register!$B$7:$B$46,MATCH(7,Register!$X$7:$X$46,0)),"") | Q13: =IFERROR(INDEX(Register!$K$7:$K$46,MATCH(7,Register!$X$7:$X$46,0)),0)
P14: =IFERROR(INDEX(Register!$B$7:$B$46,MATCH(8,Register!$X$7:$X$46,0)),"") | Q14: =IFERROR(INDEX(Register!$K$7:$K$46,MATCH(8,Register!$X$7:$X$46,0)),0)
P15: =IFERROR(INDEX(Register!$B$7:$B$46,MATCH(9,Register!$X$7:$X$46,0)),"") | Q15: =IFERROR(INDEX(Register!$K$7:$K$46,MATCH(9,Register!$X$7:$X$46,0)),0)
P16: =IFERROR(INDEX(Register!$B$7:$B$46,MATCH(10,Register!$X$7:$X$46,0)),"") | Q16: =IFERROR(INDEX(Register!$K$7:$K$46,MATCH(10,Register!$X$7:$X$46,0)),0)
P18: Expected value by kind
P19: Epistemic | Q19: =Register!$E$51
P20: Aleatory | Q20: =Register!$E$52
P21: Mixed | Q21: =Register!$E$53
P23: Epistemic: expected value against cost to find out
P24: Risk | Q24: Expected value | R24: Cost to find out
P25: =IFERROR(INDEX(Register!$B$7:$B$46,MATCH(1,Register!$Y$7:$Y$46,0)),"") | Q25: =IFERROR(INDEX(Register!$K$7:$K$46,MATCH(1,Register!$Y$7:$Y$46,0)),0) | R25: =IFERROR(INDEX(Register!$L$7:$L$46,MATCH(1,Register!$Y$7:$Y$46,0))+0,0)
P26: =IFERROR(INDEX(Register!$B$7:$B$46,MATCH(2,Register!$Y$7:$Y$46,0)),"") | Q26: =IFERROR(INDEX(Register!$K$7:$K$46,MATCH(2,Register!$Y$7:$Y$46,0)),0) | R26: =IFERROR(INDEX(Register!$L$7:$L$46,MATCH(2,Register!$Y$7:$Y$46,0))+0,0)
P27: =IFERROR(INDEX(Register!$B$7:$B$46,MATCH(3,Register!$Y$7:$Y$46,0)),"") | Q27: =IFERROR(INDEX(Register!$K$7:$K$46,MATCH(3,Register!$Y$7:$Y$46,0)),0) | R27: =IFERROR(INDEX(Register!$L$7:$L$46,MATCH(3,Register!$Y$7:$Y$46,0))+0,0)
P28: =IFERROR(INDEX(Register!$B$7:$B$46,MATCH(4,Register!$Y$7:$Y$46,0)),"") | Q28: =IFERROR(INDEX(Register!$K$7:$K$46,MATCH(4,Register!$Y$7:$Y$46,0)),0) | R28: =IFERROR(INDEX(Register!$L$7:$L$46,MATCH(4,Register!$Y$7:$Y$46,0))+0,0)
P29: =IFERROR(INDEX(Register!$B$7:$B$46,MATCH(5,Register!$Y$7:$Y$46,0)),"") | Q29: =IFERROR(INDEX(Register!$K$7:$K$46,MATCH(5,Register!$Y$7:$Y$46,0)),0) | R29: =IFERROR(INDEX(Register!$L$7:$L$46,MATCH(5,Register!$Y$7:$Y$46,0))+0,0)
P30: =IFERROR(INDEX(Register!$B$7:$B$46,MATCH(6,Register!$Y$7:$Y$46,0)),"") | Q30: =IFERROR(INDEX(Register!$K$7:$K$46,MATCH(6,Register!$Y$7:$Y$46,0)),0) | R30: =IFERROR(INDEX(Register!$L$7:$L$46,MATCH(6,Register!$Y$7:$Y$46,0))+0,0)
B31: BUY INFORMATION OR HOLD MONEY | P31: =IFERROR(INDEX(Register!$B$7:$B$46,MATCH(7,Register!$Y$7:$Y$46,0)),"") | Q31: =IFERROR(INDEX(Register!$K$7:$K$46,MATCH(7,Register!$Y$7:$Y$46,0)),0) | R31: =IFERROR(INDEX(Register!$L$7:$L$46,MATCH(7,Register!$Y$7:$Y$46,0))+0,0)
P32: =IFERROR(INDEX(Register!$B$7:$B$46,MATCH(8,Register!$Y$7:$Y$46,0)),"") | Q32: =IFERROR(INDEX(Register!$K$7:$K$46,MATCH(8,Register!$Y$7:$Y$46,0)),0) | R32: =IFERROR(INDEX(Register!$L$7:$L$46,MATCH(8,Register!$Y$7:$Y$46,0))+0,0)
P33: =IFERROR(INDEX(Register!$B$7:$B$46,MATCH(9,Register!$Y$7:$Y$46,0)),"") | Q33: =IFERROR(INDEX(Register!$K$7:$K$46,MATCH(9,Register!$Y$7:$Y$46,0)),0) | R33: =IFERROR(INDEX(Register!$L$7:$L$46,MATCH(9,Register!$Y$7:$Y$46,0))+0,0)
P34: =IFERROR(INDEX(Register!$B$7:$B$46,MATCH(10,Register!$Y$7:$Y$46,0)),"") | Q34: =IFERROR(INDEX(Register!$K$7:$K$46,MATCH(10,Register!$Y$7:$Y$46,0)),0) | R34: =IFERROR(INDEX(Register!$L$7:$L$46,MATCH(10,Register!$Y$7:$Y$46,0))+0,0)
P35: =IFERROR(INDEX(Register!$B$7:$B$46,MATCH(11,Register!$Y$7:$Y$46,0)),"") | Q35: =IFERROR(INDEX(Register!$K$7:$K$46,MATCH(11,Register!$Y$7:$Y$46,0)),0) | R35: =IFERROR(INDEX(Register!$L$7:$L$46,MATCH(11,Register!$Y$7:$Y$46,0))+0,0)
P36: =IFERROR(INDEX(Register!$B$7:$B$46,MATCH(12,Register!$Y$7:$Y$46,0)),"") | Q36: =IFERROR(INDEX(Register!$K$7:$K$46,MATCH(12,Register!$Y$7:$Y$46,0)),0) | R36: =IFERROR(INDEX(Register!$L$7:$L$46,MATCH(12,Register!$Y$7:$Y$46,0))+0,0)
B49: THE TEN LARGEST OPEN RISKS
B50: Risk | E50: Kind | F50: EV ($) | G50: Response | H50: Owner | J50: Due | K50: Response status | L50: Overdue
B51: =IFERROR(INDEX(Register!$B$7:$B$46,MATCH(1,Register!$X$7:$X$46,0))&"","") | E51: =IFERROR(INDEX(Register!$H$7:$H$46,MATCH(1,Register!$X$7:$X$46,0))&"","") | F51: =IFERROR(IF(INDEX(Register!$K$7:$K$46,MATCH(1,Register!$X$7:$X$46,0))="","",INDEX(Register!$K$7:$K$46,MATCH(1,Register!$X$7:$X$46,0))),"") | G51: =IFERROR(INDEX(Register!$N$7:$N$46,MATCH(1,Register!$X$7:$X$46,0))&"","") | H51: =IFERROR(INDEX(Register!$Q$7:$Q$46,MATCH(1,Register!$X$7:$X$46,0))&"","") | J51: =IFERROR(IF(INDEX(Register!$R$7:$R$46,MATCH(1,Register!$X$7:$X$46,0))="","",INDEX(Register!$R$7:$R$46,MATCH(1,Register!$X$7:$X$46,0))),"") | K51: =IFERROR(INDEX(Register!$S$7:$S$46,MATCH(1,Register!$X$7:$X$46,0))&"","") | L51: =IFERROR(IF(INDEX(Register!$V$7:$V$46,MATCH(1,Register!$X$7:$X$46,0))="","",INDEX(Register!$V$7:$V$46,MATCH(1,Register!$X$7:$X$46,0))),"")
B52: =IFERROR(INDEX(Register!$B$7:$B$46,MATCH(2,Register!$X$7:$X$46,0))&"","") | E52: =IFERROR(INDEX(Register!$H$7:$H$46,MATCH(2,Register!$X$7:$X$46,0))&"","") | F52: =IFERROR(IF(INDEX(Register!$K$7:$K$46,MATCH(2,Register!$X$7:$X$46,0))="","",INDEX(Register!$K$7:$K$46,MATCH(2,Register!$X$7:$X$46,0))),"") | G52: =IFERROR(INDEX(Register!$N$7:$N$46,MATCH(2,Register!$X$7:$X$46,0))&"","") | H52: =IFERROR(INDEX(Register!$Q$7:$Q$46,MATCH(2,Register!$X$7:$X$46,0))&"","") | J52: =IFERROR(IF(INDEX(Register!$R$7:$R$46,MATCH(2,Register!$X$7:$X$46,0))="","",INDEX(Register!$R$7:$R$46,MATCH(2,Register!$X$7:$X$46,0))),"") | K52: =IFERROR(INDEX(Register!$S$7:$S$46,MATCH(2,Register!$X$7:$X$46,0))&"","") | L52: =IFERROR(IF(INDEX(Register!$V$7:$V$46,MATCH(2,Register!$X$7:$X$46,0))="","",INDEX(Register!$V$7:$V$46,MATCH(2,Register!$X$7:$X$46,0))),"")
B53: =IFERROR(INDEX(Register!$B$7:$B$46,MATCH(3,Register!$X$7:$X$46,0))&"","") | E53: =IFERROR(INDEX(Register!$H$7:$H$46,MATCH(3,Register!$X$7:$X$46,0))&"","") | F53: =IFERROR(IF(INDEX(Register!$K$7:$K$46,MATCH(3,Register!$X$7:$X$46,0))="","",INDEX(Register!$K$7:$K$46,MATCH(3,Register!$X$7:$X$46,0))),"") | G53: =IFERROR(INDEX(Register!$N$7:$N$46,MATCH(3,Register!$X$7:$X$46,0))&"","") | H53: =IFERROR(INDEX(Register!$Q$7:$Q$46,MATCH(3,Register!$X$7:$X$46,0))&"","") | J53: =IFERROR(IF(INDEX(Register!$R$7:$R$46,MATCH(3,Register!$X$7:$X$46,0))="","",INDEX(Register!$R$7:$R$46,MATCH(3,Register!$X$7:$X$46,0))),"") | K53: =IFERROR(INDEX(Register!$S$7:$S$46,MATCH(3,Register!$X$7:$X$46,0))&"","") | L53: =IFERROR(IF(INDEX(Register!$V$7:$V$46,MATCH(3,Register!$X$7:$X$46,0))="","",INDEX(Register!$V$7:$V$46,MATCH(3,Register!$X$7:$X$46,0))),"")
B54: =IFERROR(INDEX(Register!$B$7:$B$46,MATCH(4,Register!$X$7:$X$46,0))&"","") | E54: =IFERROR(INDEX(Register!$H$7:$H$46,MATCH(4,Register!$X$7:$X$46,0))&"","") | F54: =IFERROR(IF(INDEX(Register!$K$7:$K$46,MATCH(4,Register!$X$7:$X$46,0))="","",INDEX(Register!$K$7:$K$46,MATCH(4,Register!$X$7:$X$46,0))),"") | G54: =IFERROR(INDEX(Register!$N$7:$N$46,MATCH(4,Register!$X$7:$X$46,0))&"","") | H54: =IFERROR(INDEX(Register!$Q$7:$Q$46,MATCH(4,Register!$X$7:$X$46,0))&"","") | J54: =IFERROR(IF(INDEX(Register!$R$7:$R$46,MATCH(4,Register!$X$7:$X$46,0))="","",INDEX(Register!$R$7:$R$46,MATCH(4,Register!$X$7:$X$46,0))),"") | K54: =IFERROR(INDEX(Register!$S$7:$S$46,MATCH(4,Register!$X$7:$X$46,0))&"","") | L54: =IFERROR(IF(INDEX(Register!$V$7:$V$46,MATCH(4,Register!$X$7:$X$46,0))="","",INDEX(Register!$V$7:$V$46,MATCH(4,Register!$X$7:$X$46,0))),"")
B55: =IFERROR(INDEX(Register!$B$7:$B$46,MATCH(5,Register!$X$7:$X$46,0))&"","") | E55: =IFERROR(INDEX(Register!$H$7:$H$46,MATCH(5,Register!$X$7:$X$46,0))&"","") | F55: =IFERROR(IF(INDEX(Register!$K$7:$K$46,MATCH(5,Register!$X$7:$X$46,0))="","",INDEX(Register!$K$7:$K$46,MATCH(5,Register!$X$7:$X$46,0))),"") | G55: =IFERROR(INDEX(Register!$N$7:$N$46,MATCH(5,Register!$X$7:$X$46,0))&"","") | H55: =IFERROR(INDEX(Register!$Q$7:$Q$46,MATCH(5,Register!$X$7:$X$46,0))&"","") | J55: =IFERROR(IF(INDEX(Register!$R$7:$R$46,MATCH(5,Register!$X$7:$X$46,0))="","",INDEX(Register!$R$7:$R$46,MATCH(5,Register!$X$7:$X$46,0))),"") | K55: =IFERROR(INDEX(Register!$S$7:$S$46,MATCH(5,Register!$X$7:$X$46,0))&"","") | L55: =IFERROR(IF(INDEX(Register!$V$7:$V$46,MATCH(5,Register!$X$7:$X$46,0))="","",INDEX(Register!$V$7:$V$46,MATCH(5,Register!$X$7:$X$46,0))),"")
B56: =IFERROR(INDEX(Register!$B$7:$B$46,MATCH(6,Register!$X$7:$X$46,0))&"","") | E56: =IFERROR(INDEX(Register!$H$7:$H$46,MATCH(6,Register!$X$7:$X$46,0))&"","") | F56: =IFERROR(IF(INDEX(Register!$K$7:$K$46,MATCH(6,Register!$X$7:$X$46,0))="","",INDEX(Register!$K$7:$K$46,MATCH(6,Register!$X$7:$X$46,0))),"") | G56: =IFERROR(INDEX(Register!$N$7:$N$46,MATCH(6,Register!$X$7:$X$46,0))&"","") | H56: =IFERROR(INDEX(Register!$Q$7:$Q$46,MATCH(6,Register!$X$7:$X$46,0))&"","") | J56: =IFERROR(IF(INDEX(Register!$R$7:$R$46,MATCH(6,Register!$X$7:$X$46,0))="","",INDEX(Register!$R$7:$R$46,MATCH(6,Register!$X$7:$X$46,0))),"") | K56: =IFERROR(INDEX(Register!$S$7:$S$46,MATCH(6,Register!$X$7:$X$46,0))&"","") | L56: =IFERROR(IF(INDEX(Register!$V$7:$V$46,MATCH(6,Register!$X$7:$X$46,0))="","",INDEX(Register!$V$7:$V$46,MATCH(6,Register!$X$7:$X$46,0))),"")
...

Sheet Setup
A1: Setup | D1: The Project Control Hub
A2: The review date, the contingency you carry, and the lists the register uses.
A3: Change the review date at every review. Overdue responses are counted against it.
A6: Project
A7: Review number
A8: Review date (as at)
A9: Contingency carried ($) | D9: Risk Topic 1: the 5% rule gave $47,553.
A10: Prepared by
A14: Team (Owner drop-down) | D14: Categories (Category drop-down)

Sheet Register
A1: Risk register | W1: The Project Control Hub
A2: One risk per row, written as a sentence, priced in money, with one person against the response.
A3: The test for Kind: if you spent money finding out, would the uncertainty get smaller? Yes = Epistemic. No = Aleatory.
A6: ID | B6: Risk | C6: Because… (a fact today) | D6: …may occur (the uncertain event) | E6: …which would lead to (the effect) | F6: Sentence | G6: Category | H6: Kind | I6: Probability | J6: Impact ($) | K6: Expected value ($) | L6: Cost to find out ($) | M6: Value of finding out | N6: Response | O6: Response action | P6: Response cost ($) | Q6: Owner | R6: Due | S6: Response status | T6: Closes when | U6: Risk status | V6: Days overdue | W6: Note | X6: r | Y6: e
A7: R01 | F7: =IF(B7="","",IF(AND(C7<>"",D7<>"",E7<>""),"✔ complete","Missing "&MID(IF(C7="",", cause","")&IF(D7="",", event","")&IF(E7="",", effect",""),3,40))) | K7: =IF(AND(ISNUMBER(I7),ISNUMBER(J7)),I7*J7,"") | M7: =IF(OR(H7<>"Epistemic",L7="",K7=""),"",IF(L7=0,"Free: ask",K7/L7)) | V7: =IF(OR(B7="",R7="",S7="Done",U7="Closed"),"",IF(Setup!$B$8>R7,Setup!$B$8-R7,"")) | X7: =IF(AND(ISNUMBER(K7),U7<>"Closed"),RANK(K7,$K$7:$K$46)+COUNTIF($K$7:K7,K7)-1,"") | Y7: =IF(AND(H7="Epistemic",U7<>"Closed"),COUNTIF($H$7:H7,"Epistemic"),"")
A8: R02 | F8: =IF(B8="","",IF(AND(C8<>"",D8<>"",E8<>""),"✔ complete","Missing "&MID(IF(C8="",", cause","")&IF(D8="",", event","")&IF(E8="",", effect",""),3,40))) | K8: =IF(AND(ISNUMBER(I8),ISNUMBER(J8)),I8*J8,"") | M8: =IF(OR(H8<>"Epistemic",L8="",K8=""),"",IF(L8=0,"Free: ask",K8/L8)) | V8: =IF(OR(B8="",R8="",S8="Done",U8="Closed"),"",IF(Setup!$B$8>R8,Setup!$B$8-R8,"")) | X8: =IF(AND(ISNUMBER(K8),U8<>"Closed"),RANK(K8,$K$7:$K$46)+COUNTIF($K$7:K8,K8)-1,"") | Y8: =IF(AND(H8="Epistemic",U8<>"Closed"),COUNTIF($H$7:H8,"Epistemic"),"")
A9: R03 | F9: =IF(B9="","",IF(AND(C9<>"",D9<>"",E9<>""),"✔ complete","Missing "&MID(IF(C9="",", cause","")&IF(D9="",", event","")&IF(E9="",", effect",""),3,40))) | K9: =IF(AND(ISNUMBER(I9),ISNUMBER(J9)),I9*J9,"") | M9: =IF(OR(H9<>"Epistemic",L9="",K9=""),"",IF(L9=0,"Free: ask",K9/L9)) | V9: =IF(OR(B9="",R9="",S9="Done",U9="Closed"),"",IF(Setup!$B$8>R9,Setup!$B$8-R9,"")) | X9: =IF(AND(ISNUMBER(K9),U9<>"Closed"),RANK(K9,$K$7:$K$46)+COUNTIF($K$7:K9,K9)-1,"") | Y9: =IF(AND(H9="Epistemic",U9<>"Closed"),COUNTIF($H$7:H9,"Epistemic"),"")
A10: R04 | F10: =IF(B10="","",IF(AND(C10<>"",D10<>"",E10<>""),"✔ complete","Missing "&MID(IF(C10="",", cause","")&IF(D10="",", event","")&IF(E10="",", effect",""),3,40))) | K10: =IF(AND(ISNUMBER(I10),ISNUMBER(J10)),I10*J10,"") | M10: =IF(OR(H10<>"Epistemic",L10="",K10=""),"",IF(L10=0,"Free: ask",K10/L10)) | V10: =IF(OR(B10="",R10="",S10="Done",U10="Closed"),"",IF(Setup!$B$8>R10,Setup!$B$8-R10,"")) | X10: =IF(AND(ISNUMBER(K10),U10<>"Closed"),RANK(K10,$K$7:$K$46)+COUNTIF($K$7:K10,K10)-1,"") | Y10: =IF(AND(H10="Epistemic",U10<>"Closed"),COUNTIF($H$7:H10,"Epistemic"),"")
A11: R05 | F11: =IF(B11="","",IF(AND(C11<>"",D11<>"",E11<>""),"✔ complete","Missing "&MID(IF(C11="",", cause","")&IF(D11="",", event","")&IF(E11="",", effect",""),3,40))) | K11: =IF(AND(ISNUMBER(I11),ISNUMBER(J11)),I11*J11,"") | M11: =IF(OR(H11<>"Epistemic",L11="",K11=""),"",IF(L11=0,"Free: ask",K11/L11)) | V11: =IF(OR(B11="",R11="",S11="Done",U11="Closed"),"",IF(Setup!$B$8>R11,Setup!$B$8-R11,"")) | X11: =IF(AND(ISNUMBER(K11),U11<>"Closed"),RANK(K11,$K$7:$K$46)+COUNTIF($K$7:K11,K11)-1,"") | Y11: =IF(AND(H11="Epistemic",U11<>"Closed"),COUNTIF($H$7:H11,"Epistemic"),"")
A12: R06 | F12: =IF(B12="","",IF(AND(C12<>"",D12<>"",E12<>""),"✔ complete","Missing "&MID(IF(C12="",", cause","")&IF(D12="",", event","")&IF(E12="",", effect",""),3,40))) | K12: =IF(AND(ISNUMBER(I12),ISNUMBER(J12)),I12*J12,"") | M12: =IF(OR(H12<>"Epistemic",L12="",K12=""),"",IF(L12=0,"Free: ask",K12/L12)) | V12: =IF(OR(B12="",R12="",S12="Done",U12="Closed"),"",IF(Setup!$B$8>R12,Setup!$B$8-R12,"")) | X12: =IF(AND(ISNUMBER(K12),U12<>"Closed"),RANK(K12,$K$7:$K$46)+COUNTIF($K$7:K12,K12)-1,"") | Y12: =IF(AND(H12="Epistemic",U12<>"Closed"),COUNTIF($H$7:H12,"Epistemic"),"")
A13: R07 | F13: =IF(B13="","",IF(AND(C13<>"",D13<>"",E13<>""),"✔ complete","Missing "&MID(IF(C13="",", cause","")&IF(D13="",", event","")&IF(E13="",", effect",""),3,40))) | K13: =IF(AND(ISNUMBER(I13),ISNUMBER(J13)),I13*J13,"") | M13: =IF(OR(H13<>"Epistemic",L13="",K13=""),"",IF(L13=0,"Free: ask",K13/L13)) | V13: =IF(OR(B13="",R13="",S13="Done",U13="Closed"),"",IF(Setup!$B$8>R13,Setup!$B$8-R13,"")) | X13: =IF(AND(ISNUMBER(K13),U13<>"Closed"),RANK(K13,$K$7:$K$46)+COUNTIF($K$7:K13,K13)-1,"") | Y13: =IF(AND(H13="Epistemic",U13<>"Closed"),COUNTIF($H$7:H13,"Epistemic"),"")
A14: R08 | F14: =IF(B14="","",IF(AND(C14<>"",D14<>"",E14<>""),"✔ complete","Missing "&MID(IF(C14="",", cause","")&IF(D14="",", event","")&IF(E14="",", effect",""),3,40))) | K14: =IF(AND(ISNUMBER(I14),ISNUMBER(J14)),I14*J14,"") | M14: =IF(OR(H14<>"Epistemic",L14="",K14=""),"",IF(L14=0,"Free: ask",K14/L14)) | V14: =IF(OR(B14="",R14="",S14="Done",U14="Closed"),"",IF(Setup!$B$8>R14,Setup!$B$8-R14,"")) | X14: =IF(AND(ISNUMBER(K14),U14<>"Closed"),RANK(K14,$K$7:$K$46)+COUNTIF($K$7:K14,K14)-1,"") | Y14: =IF(AND(H14="Epistemic",U14<>"Closed"),COUNTIF($H$7:H14,"Epistemic"),"")
A15: R09 | F15: =IF(B15="","",IF(AND(C15<>"",D15<>"",E15<>""),"✔ complete","Missing "&MID(IF(C15="",", cause","")&IF(D15="",", event","")&IF(E15="",", effect",""),3,40))) | K15: =IF(AND(ISNUMBER(I15),ISNUMBER(J15)),I15*J15,"") | M15: =IF(OR(H15<>"Epistemic",L15="",K15=""),"",IF(L15=0,"Free: ask",K15/L15)) | V15: =IF(OR(B15="",R15="",S15="Done",U15="Closed"),"",IF(Setup!$B$8>R15,Setup!$B$8-R15,"")) | X15: =IF(AND(ISNUMBER(K15),U15<>"Closed"),RANK(K15,$K$7:$K$46)+COUNTIF($K$7:K15,K15)-1,"") | Y15: =IF(AND(H15="Epistemic",U15<>"Closed"),COUNTIF($H$7:H15,"Epistemic"),"")
A16: R10 | F16: =IF(B16="","",IF(AND(C16<>"",D16<>"",E16<>""),"✔ complete","Missing "&MID(IF(C16="",", cause","")&IF(D16="",", event","")&IF(E16="",", effect",""),3,40))) | K16: =IF(AND(ISNUMBER(I16),ISNUMBER(J16)),I16*J16,"") | M16: =IF(OR(H16<>"Epistemic",L16="",K16=""),"",IF(L16=0,"Free: ask",K16/L16)) | V16: =IF(OR(B16="",R16="",S16="Done",U16="Closed"),"",IF(Setup!$B$8>R16,Setup!$B$8-R16,"")) | X16: =IF(AND(ISNUMBER(K16),U16<>"Closed"),RANK(K16,$K$7:$K$46)+COUNTIF($K$7:K16,K16)-1,"") | Y16: =IF(AND(H16="Epistemic",U16<>"Closed"),COUNTIF($H$7:H16,"Epistemic"),"")
A17: R11 | F17: =IF(B17="","",IF(AND(C17<>"",D17<>"",E17<>""),"✔ complete","Missing "&MID(IF(C17="",", cause","")&IF(D17="",", event","")&IF(E17="",", effect",""),3,40))) | K17: =IF(AND(ISNUMBER(I17),ISNUMBER(J17)),I17*J17,"") | M17: =IF(OR(H17<>"Epistemic",L17="",K17=""),"",IF(L17=0,"Free: ask",K17/L17)) | V17: =IF(OR(B17="",R17="",S17="Done",U17="Closed"),"",IF(Setup!$B$8>R17,Setup!$B$8-R17,"")) | X17: =IF(AND(ISNUMBER(K17),U17<>"Closed"),RANK(K17,$K$7:$K$46)+COUNTIF($K$7:K17,K17)-1,"") | Y17: =IF(AND(H17="Epistemic",U17<>"Closed"),COUNTIF($H$7:H17,"Epistemic"),"")
A18: R12 | F18: =IF(B18="","",IF(AND(C18<>"",D18<>"",E18<>""),"✔ complete","Missing "&MID(IF(C18="",", cause","")&IF(D18="",", event","")&IF(E18="",", effect",""),3,40))) | K18: =IF(AND(ISNUMBER(I18),ISNUMBER(J18)),I18*J18,"") | M18: =IF(OR(H18<>"Epistemic",L18="",K18=""),"",IF(L18=0,"Free: ask",K18/L18)) | V18: =IF(OR(B18="",R18="",S18="Done",U18="Closed"),"",IF(Setup!$B$8>R18,Setup!$B$8-R18,"")) | X18: =IF(AND(ISNUMBER(K18),U18<>"Closed"),RANK(K18,$K$7:$K$46)+COUNTIF($K$7:K18,K18)-1,"") | Y18: =IF(AND(H18="Epistemic",U18<>"Closed"),COUNTIF($H$7:H18,"Epistemic"),"")
... A46: R40 | F46: =IF(B46="","",IF(AND(C46<>"",D46<>"",E46<>""),"✔ complete","Missing "&MID(IF(C46="",", cause","")&IF(D46="",", event","")&IF(E46="",", effect",""),3,40))) | K46: =IF(AND(ISNUMBER(I46),ISNUMBER(J46)),I46*J46,"") | M46: =IF(OR(H46<>"Epistemic",L46="",K46=""),"",IF(L46=0,"Free: ask",K46/L46)) | V46: =IF(OR(B46="",R46="",S46="Done",U46="Closed"),"",IF(Setup!$B$8>R46,Setup!$B$8-R46,"")) | X46: =IF(AND(ISNUMBER(K46),U46<>"Closed"),RANK(K46,$K$7:$K$46)+COUNTIF($K$7:K46,K46)-1,"") | Y46: =IF(AND(H46="Epistemic",U46<>"Closed"),COUNTIF($H$7:H46,"Epistemic"),"")
B48: Summary
B49: Open risks | E49: =COUNTIFS(B7:B46,"<>",U7:U46,"<>Closed")
B50: Total expected value ($) | E50: =SUMIF(U7:U46,"<>Closed",K7:K46)
B51: epistemic ($) | E51: =SUMIFS(K7:K46,H7:H46,"Epistemic",U7:U46,"<>Closed")
B52: aleatory ($) | E52: =SUMIFS(K7:K46,H7:H46,"Aleatory",U7:U46,"<>Closed")
B53: mixed ($) | E53: =SUMIFS(K7:K46,H7:H46,"Mixed",U7:U46,"<>Closed")
B54: Epistemic risks | E54: =COUNTIFS(H7:H46,"Epistemic",U7:U46,"<>Closed")
B55: Cost to resolve the epistemic risks ($) | E55: =SUMIFS(L7:L46,H7:H46,"Epistemic",U7:U46,"<>Closed")
B56: Epistemic risks that cost nothing to resolve | E56: =COUNTIFS(H7:H46,"Epistemic",L7:L46,0,U7:U46,"<>Closed")
B57: Total response spend ($) | E57: =SUMIF(U7:U46,"<>Closed",P7:P46)
B58: Responses priced | E58: =COUNTIFS(N7:N46,"<>",U7:U46,"<>Closed")
B59: Responses done | E59: =COUNTIF(S7:S46,"Done")
B60: Open risks with no owner | E60: =COUNTIFS(B7:B46,"<>",Q7:Q46,"",U7:U46,"<>Closed")
B61: Responses overdue | E61: =COUNTIF(V7:V46,">0")
B62: Sentences incomplete | E62: =COUNTIF(F7:F46,"Missing*")

Sheet History
A1: History | H1: The Project Control Hub
A2: One row per review, so the trend is visible: is the register getting shorter and cheaper?
A3: At each review: copy the blue "This review" row and Paste Special → Values into the next empty row.
A5: This review (live)
A6: =Setup!B7 | B6: =Setup!B8 | C6: =Register!E49 | D6: =Register!E50 | E6: =Register!E51 | F6: =Register!E52 | G6: =Setup!B9 | H6: =Register!E57
A7: Review | B7: Date | C7: Open risks | D7: Total EV ($) | E7: Epistemic EV ($) | F7: Aleatory EV ($) | G7: Contingency ($) | H7: Response spend ($)
