Workbook

Sheet Start
B2: Schedule update checklist
B3: Keep the model honest while ten thousand things try to make it lie. Then report.
B4: The Project Control Hub · free template · example: update six of the example project
B7: EVERY PERIOD, SAME DAY, SAME RULES · analyse, then act, then report
B8: 1 | C8: Updates → | D8: Add this update’s line: data date, the scheduling option, the forecast finish. Set its number in Setup. | E8: 2 minutes
B9: 2 | C9: Remaining days → | D9: Every started activity: "how many days do you still need?" Write who said it and from which record. | E9: 15 minutes
B10: 3 | C10: Health check → | D10: The ten-minute check: count open ends, hard constraints, negative and huge float, long lags, out-of-sequence work. | E10: 10 minutes
B11: 4 | C11: Float trend → | D11: The float of your top ten activities. The sheet reads the slope and says when each one runs out. | E11: 5 minutes
B12: 5 | C12: Actions → | D12: Every slipping path: an action, a person and a date. | E12: 10 minutes
B13: 6 | C13: Checklist → | D13: Work down the list. The verdict turns green when every must-do line is done. Then write the report. | E13: 10 minutes
B15: ASK THE OTHER QUESTION
C16: "How far along are you?" | D16: "About ninety percent." He said that last month too. Percent complete looks backwards.
C17: "How many days left?" | D17: "Eight. We are waiting on the glass." Now you have a forecast, and a reason you can go and fix.
B19: THREE PLACES THE ROT HIDES · Topic 17
C20: Progress override | D20: The default in most tools. Drops the logic when the site builds out of order. The finish is early, and fiction. Use retained logic.
C21: A hard constraint | D21: Does not protect the date. It protects you from hearing about it: the delay arrives and the float still says zero.
C22: An open end | D22: Nothing to push against, so the software hands out 180 days of imaginary float. Huge float is a broken gauge.
B24: HOW TO READ THE CELLS
C25: Yellow, blue text | D25: Yours to fill in: Setup, Updates, Remaining days, Health check, Float trend, Actions, and Status in the Checklist.
C26: White, black text | D26: A formula. Leave it alone and it keeps working. The Dashboard is all formulas.
C27: Red | D27: A must-do line still open, negative float, a finish that moved, a path without an owner.
B29: WHAT IS IN THIS FILE
C30: Dashboard | D30: The verdict, seven numbers, a paragraph, what is open, the float radar and three charts.
C31: Checklist | D31: 29 lines in seven steps, each with why it matters and what the file shows.
C32: Health check | D32: Eight counts per update, against a target, with the action for each.
C33: Float trend | D33: Twenty activities, twelve updates: change, burn per update, when it runs out.
C34: Remaining days | D34: Days left from site, with the source, stuck percentages and finishes that moved.
C35: Actions | D35: Every slipping path: action, owner, date, and what is missing.
C36: Updates | D36: One line per update: data date, scheduling option, forecast finish, why it moved.
C37: Setup | D37: This update’s number, the contract date, the limits and the drop-down lists.
B39: EXPLAINED IN
C40: Schedule Topic 16 · Keeping the model honest
C41: Schedule Topic 17 · Updated perfectly, completely wrong
B43: Example: update six of the example project, data date Tuesday 30 June 2026. The update switches the scheduling option from progress override to retained logic and takes the must-finish-on off the substation slab: the finish moves 21 days later and the slab shows -10 days of float. It stopped hiding. The switchgear has lost five days of float every update and is now four days late. Two slipping paths have no owner, so the update is not ready to issue. The rock, the raft rebar and the switchgear lead time are the example project’s; the floats, counts and dates are illustrative.
B48: Free to use and adapt on your own projects. https://theprojectcontrolhub.com/

Sheet Dashboard
B2: Schedule update | L2: The Project Control Hub
B3: =IF(Setup!B6="","",Setup!B6&" · ")&"update "&Setup!$B$7&IF(Setup!$B$8="",""," · data date "&TEXT(Setup!$B$8,"d mmm yyyy"))&" · "&IFERROR(INDEX(Updates!$D$7:$D$18,Setup!$B$7),"") -> Example project · update 6 · data date 30 Jun 2026 · Retained logic
B5: =Checklist!A5 -> NOT READY TO ISSUE · 1 must-do item(s) still open
B8: CHECKLIST | D8: HEALTH CHECKS FAILING | F8: FORECAST FINISH | H8: LATE AGAINST CONTRACT | J8: ALREADY LATE | L8: PATHS WITHOUT AN OWNER | N8: REMAINING-DAYS FLAGS
B9: =COUNTIF(Checklist!$F$8:$F$42,"Done")+COUNTIF(Checklist!$F$8:$F$42,"Fixed")+COUNTIF(Checklist!$F$8:$F$42,"N/A") -> 23 | D9: =IFERROR(COUNTIF('Health check'!$S$7:$S$14,"*found*"),0) -> 6 | F9: =IFERROR(IF(INDEX(Updates!$E$7:$E$18,Setup!$B$7)="","",INDEX(Updates!$E$7:$E$18,Setup!$B$7)),"") -> 46269 | H9: =IFERROR(IF(INDEX(Updates!$F$7:$F$18,Setup!$B$7)="","",INDEX(Updates!$F$7:$F$18,Setup!$B$7)),"") -> 42 | J9: =COUNTIF('Float trend'!$P$7:$P$26,"<0") -> 2 | L9: =COUNTIFS(Actions!$A$7:$A$36,"<>",Actions!$D$7:$D$36,"",Actions!$F$7:$F$36,"<>Done") -> 2 | N9: =COUNTIF('Remaining days'!$M$7:$M$46,"?*") -> 7
B11: ="of "&COUNTA(Checklist!$B$8:$B$42)&" lines · "&COUNT(Checklist!$J$8:$J$42)&" open" -> of 29 lines · 6 open | D11: ="of "&ROWS('Health check'!$O$7:$O$14)&" · "&IFERROR(SUM('Health check'!$O$7:$O$14),0)&" items found" -> of 8 · 12 items found | F11: =IFERROR(IF(INDEX(Updates!$G$7:$G$18,Setup!$B$7)="","",TEXT(INDEX(Updates!$G$7:$G$18,Setup!$B$7),"+0;-0;0")&" days since last update"),"") -> +21 days since last update | H11: =IF(Setup!B9="","set the contract date in Setup","days after "&TEXT(Setup!B9,"d mmm yyyy")) -> days after 24 Jul 2026 | J11: ="activities with negative float · "&COUNTIF('Float trend'!$U$7:$U$26,"Runs out*")&" running out" -> activities with negative float · 4 running out | L11: =COUNTIF(Actions!$I$7:$I$36,"Overdue*")&" action(s) overdue" -> 0 action(s) overdue | N11: ="of "&COUNTA('Remaining days'!$B$7:$B$46)&" started activities" -> of 12 started activities
B14: =IF(Setup!$B$8="","Add this update’s line in Updates and set its number in Setup.","The finish is forecast for "&IFERROR(TEXT(F9,"d mmmm yyyy"),"—")&IF(H9="","",", "&H9&" days against the contract")&". "&J9&" activit"&IF(J9=1,"y is","ies are")&" already late and "&COUNTIF('Float trend'!$U$7:$U$26,"Runs out*")&" will run out of float within "&Setup!$B$14&" updates. The health check found "&IFERROR(SUM('Health check'!$O$7:$O$14),0)&" items. "&IF(L9>0,L9&" slipping path(s) still have no owner.","Every slipping path has an owner.")) -> The finish is forecast for 4 September 2026, 42 days against the contract. 2 activities are already late and 4 will run out of float within 3 updates. The health check found 12 items. 2 slipping path(s) still have no owner.
B17: BEFORE YOU ISSUE · open lines, must-do first
B18: No. | C18: Check | H18: Must | I18: Status | J18: Owner | L18: Evidence / note
B19: =IFERROR(INDEX(Checklist!$A$8:$A$42,MATCH(SMALL(Checklist!$J$8:$J$42,1),Checklist!$J$8:$J$42,0))&"","") -> 6.1 | C19: =IFERROR(INDEX(Checklist!$B$8:$B$42,MATCH(SMALL(Checklist!$J$8:$J$42,1),Checklist!$J$8:$J$42,0))&"","") -> Every slipping path has an action, a person and a date | H19: =IFERROR(INDEX(Checklist!$D$8:$D$42,MATCH(SMALL(Checklist!$J$8:$J$42,1),Checklist!$J$8:$J$42,0))&"","") -> Must | I19: =IFERROR(INDEX(Checklist!$F$8:$F$42,MATCH(SMALL(Checklist!$J$8:$J$42,1),Checklist!$J$8:$J$42,0))&"","") -> Not done | J19: =IFERROR(INDEX(Checklist!$H$8:$H$42,MATCH(SMALL(Checklist!$J$8:$J$42,1),Checklist!$J$8:$J$42,0))&"","") -> Project manager | L19: =IFERROR(INDEX(Checklist!$G$8:$G$42,MATCH(SMALL(Checklist!$J$8:$J$42,1),Checklist!$J$8:$J$42,0))&"","") -> Two paths still without an owner
B20: =IFERROR(INDEX(Checklist!$A$8:$A$42,MATCH(SMALL(Checklist!$J$8:$J$42,2),Checklist!$J$8:$J$42,0))&"","") -> 1.4 | C20: =IFERROR(INDEX(Checklist!$B$8:$B$42,MATCH(SMALL(Checklist!$J$8:$J$42,2),Checklist!$J$8:$J$42,0))&"","") -> No percentage taken from a phone call; stuck percentages challenged | H20: =IFERROR(INDEX(Checklist!$D$8:$D$42,MATCH(SMALL(Checklist!$J$8:$J$42,2),Checklist!$J$8:$J$42,0))&"","") | I20: =IFERROR(INDEX(Checklist!$F$8:$F$42,MATCH(SMALL(Checklist!$J$8:$J$42,2),Checklist!$J$8:$J$42,0))&"","") -> Open | J20: =IFERROR(INDEX(Checklist!$H$8:$H$42,MATCH(SMALL(Checklist!$J$8:$J$42,2),Checklist!$J$8:$J$42,0))&"","") -> Site engineer | L20: =IFERROR(INDEX(Checklist!$G$8:$G$42,MATCH(SMALL(Checklist!$J$8:$J$42,2),Checklist!$J$8:$J$42,0))&"","") -> Earthing came by phone. Switchgear and the outfall stuck: causes written down
B21: =IFERROR(INDEX(Checklist!$A$8:$A$42,MATCH(SMALL(Checklist!$J$8:$J$42,3),Checklist!$J$8:$J$42,0))&"","") -> 4.4 | C21: =IFERROR(INDEX(Checklist!$B$8:$B$42,MATCH(SMALL(Checklist!$J$8:$J$42,3),Checklist!$J$8:$J$42,0))&"","") -> Unusually large float investigated, not reported as good news | H21: =IFERROR(INDEX(Checklist!$D$8:$D$42,MATCH(SMALL(Checklist!$J$8:$J$42,3),Checklist!$J$8:$J$42,0))&"","") | I21: =IFERROR(INDEX(Checklist!$F$8:$F$42,MATCH(SMALL(Checklist!$J$8:$J$42,3),Checklist!$J$8:$J$42,0))&"","") -> Open | J21: =IFERROR(INDEX(Checklist!$H$8:$H$42,MATCH(SMALL(Checklist!$J$8:$J$42,3),Checklist!$J$8:$J$42,0))&"","") -> Planner | L21: =IFERROR(INDEX(Checklist!$G$8:$G$42,MATCH(SMALL(Checklist!$J$8:$J$42,3),Checklist!$J$8:$J$42,0))&"","") -> Temporary compound removal, 180 days: linked only to the finish
B22: =IFERROR(INDEX(Checklist!$A$8:$A$42,MATCH(SMALL(Checklist!$J$8:$J$42,4),Checklist!$J$8:$J$42,0))&"","") -> 4.5 | C22: =IFERROR(INDEX(Checklist!$B$8:$B$42,MATCH(SMALL(Checklist!$J$8:$J$42,4),Checklist!$J$8:$J$42,0))&"","") -> Long lags turned into activities with an owner | H22: =IFERROR(INDEX(Checklist!$D$8:$D$42,MATCH(SMALL(Checklist!$J$8:$J$42,4),Checklist!$J$8:$J$42,0))&"","") | I22: =IFERROR(INDEX(Checklist!$F$8:$F$42,MATCH(SMALL(Checklist!$J$8:$J$42,4),Checklist!$J$8:$J$42,0))&"","") -> Open | J22: =IFERROR(INDEX(Checklist!$H$8:$H$42,MATCH(SMALL(Checklist!$J$8:$J$42,4),Checklist!$J$8:$J$42,0))&"","") -> Planner | L22: =IFERROR(INDEX(Checklist!$G$8:$G$42,MATCH(SMALL(Checklist!$J$8:$J$42,4),Checklist!$J$8:$J$42,0))&"","") -> Three over 10 days. Two are curing; one is an approval
B23: =IFERROR(INDEX(Checklist!$A$8:$A$42,MATCH(SMALL(Checklist!$J$8:$J$42,5),Checklist!$J$8:$J$42,0))&"","") -> 7.3 | C23: =IFERROR(INDEX(Checklist!$B$8:$B$42,MATCH(SMALL(Checklist!$J$8:$J$42,5),Checklist!$J$8:$J$42,0))&"","") -> Issued on the same working day after the cut-off as every period | H23: =IFERROR(INDEX(Checklist!$D$8:$D$42,MATCH(SMALL(Checklist!$J$8:$J$42,5),Checklist!$J$8:$J$42,0))&"","") | I23: =IFERROR(INDEX(Checklist!$F$8:$F$42,MATCH(SMALL(Checklist!$J$8:$J$42,5),Checklist!$J$8:$J$42,0))&"","") -> Not done | J23: =IFERROR(INDEX(Checklist!$H$8:$H$42,MATCH(SMALL(Checklist!$J$8:$J$42,5),Checklist!$J$8:$J$42,0))&"","") -> Planner | L23: =IFERROR(INDEX(Checklist!$G$8:$G$42,MATCH(SMALL(Checklist!$J$8:$J$42,5),Checklist!$J$8:$J$42,0))&"","")
B24: =IFERROR(INDEX(Checklist!$A$8:$A$42,MATCH(SMALL(Checklist!$J$8:$J$42,6),Checklist!$J$8:$J$42,0))&"","") -> 7.4 | C24: =IFERROR(INDEX(Checklist!$B$8:$B$42,MATCH(SMALL(Checklist!$J$8:$J$42,6),Checklist!$J$8:$J$42,0))&"","") -> Schedule file, this checklist and the report archived together | H24: =IFERROR(INDEX(Checklist!$D$8:$D$42,MATCH(SMALL(Checklist!$J$8:$J$42,6),Checklist!$J$8:$J$42,0))&"","") | I24: =IFERROR(INDEX(Checklist!$F$8:$F$42,MATCH(SMALL(Checklist!$J$8:$J$42,6),Checklist!$J$8:$J$42,0))&"","") -> Not done | J24: =IFERROR(INDEX(Checklist!$H$8:$H$42,MATCH(SMALL(Checklist!$J$8:$J$42,6),Checklist!$J$8:$J$42,0))&"","") -> Planner | L24: =IFERROR(INDEX(Checklist!$G$8:$G$42,MATCH(SMALL(Checklist!$J$8:$J$42,6),Checklist!$J$8:$J$42,0))&"","")
B25: =IFERROR(INDEX(Checklist!$A$8:$A$42,MATCH(SMALL(Checklist!$J$8:$J$42,7),Checklist!$J$8:$J$42,0))&"","") | C25: =IFERROR(INDEX(Checklist!$B$8:$B$42,MATCH(SMALL(Checklist!$J$8:$J$42,7),Checklist!$J$8:$J$42,0))&"","") | H25: =IFERROR(INDEX(Checklist!$D$8:$D$42,MATCH(SMALL(Checklist!$J$8:$J$42,7),Checklist!$J$8:$J$42,0))&"","") | I25: =IFERROR(INDEX(Checklist!$F$8:$F$42,MATCH(SMALL(Checklist!$J$8:$J$42,7),Checklist!$J$8:$J$42,0))&"","") | J25: =IFERROR(INDEX(Checklist!$H$8:$H$42,MATCH(SMALL(Checklist!$J$8:$J$42,7),Checklist!$J$8:$J$42,0))&"","") | L25: =IFERROR(INDEX(Checklist!$G$8:$G$42,MATCH(SMALL(Checklist!$J$8:$J$42,7),Checklist!$J$8:$J$42,0))&"","")
B26: =IFERROR(INDEX(Checklist!$A$8:$A$42,MATCH(SMALL(Checklist!$J$8:$J$42,8),Checklist!$J$8:$J$42,0))&"","") | C26: =IFERROR(INDEX(Checklist!$B$8:$B$42,MATCH(SMALL(Checklist!$J$8:$J$42,8),Checklist!$J$8:$J$42,0))&"","") | H26: =IFERROR(INDEX(Checklist!$D$8:$D$42,MATCH(SMALL(Checklist!$J$8:$J$42,8),Checklist!$J$8:$J$42,0))&"","") | I26: =IFERROR(INDEX(Checklist!$F$8:$F$42,MATCH(SMALL(Checklist!$J$8:$J$42,8),Checklist!$J$8:$J$42,0))&"","") | J26: =IFERROR(INDEX(Checklist!$H$8:$H$42,MATCH(SMALL(Checklist!$J$8:$J$42,8),Checklist!$J$8:$J$42,0))&"","") | L26: =IFERROR(INDEX(Checklist!$G$8:$G$42,MATCH(SMALL(Checklist!$J$8:$J$42,8),Checklist!$J$8:$J$42,0))&"","")
B27: =IF(COUNT(Checklist!$J$8:$J$42)=0,"Nothing open on the checklist.",IF(COUNT(Checklist!$J$8:$J$42)>8,"…and "&(COUNT(Checklist!$J$8:$J$42)-8)&" more in the Checklist.",""))
B30: THE FLOAT RADAR · lowest float first
B31: Activity | G31: Float now | H31: Change | I31: Burn / upd. | J31: Reading
B32: =IFERROR(INDEX('Float trend'!$B$7:$B$26,MATCH(SMALL('Float trend'!$W$7:$W$26,1),'Float trend'!$W$7:$W$26,0)),"") -> Substation slab | G32: =IFERROR(INDEX('Float trend'!$P$7:$P$26,MATCH(SMALL('Float trend'!$W$7:$W$26,1),'Float trend'!$W$7:$W$26,0)),"") -> -10 | H32: =IFERROR(INDEX('Float trend'!$R$7:$R$26,MATCH(SMALL('Float trend'!$W$7:$W$26,1),'Float trend'!$W$7:$W$26,0)),"") -> -10 | I32: =IFERROR(INDEX('Float trend'!$S$7:$S$26,MATCH(SMALL('Float trend'!$W$7:$W$26,1),'Float trend'!$W$7:$W$26,0)),"") -> 3.3333333 | J32: =IFERROR(INDEX('Float trend'!$U$7:$U$26,MATCH(SMALL('Float trend'!$W$7:$W$26,1),'Float trend'!$W$7:$W$26,0)),"") -> Already late by 10 days
B33: =IFERROR(INDEX('Float trend'!$B$7:$B$26,MATCH(SMALL('Float trend'!$W$7:$W$26,2),'Float trend'!$W$7:$W$26,0)),"") -> Switchgear delivery and installation | G33: =IFERROR(INDEX('Float trend'!$P$7:$P$26,MATCH(SMALL('Float trend'!$W$7:$W$26,2),'Float trend'!$W$7:$W$26,0)),"") -> -4 | H33: =IFERROR(INDEX('Float trend'!$R$7:$R$26,MATCH(SMALL('Float trend'!$W$7:$W$26,2),'Float trend'!$W$7:$W$26,0)),"") -> -5 | I33: =IFERROR(INDEX('Float trend'!$S$7:$S$26,MATCH(SMALL('Float trend'!$W$7:$W$26,2),'Float trend'!$W$7:$W$26,0)),"") -> 4.3333333 | J33: =IFERROR(INDEX('Float trend'!$U$7:$U$26,MATCH(SMALL('Float trend'!$W$7:$W$26,2),'Float trend'!$W$7:$W$26,0)),"") -> Already late by 4 days
B34: =IFERROR(INDEX('Float trend'!$B$7:$B$26,MATCH(SMALL('Float trend'!$W$7:$W$26,3),'Float trend'!$W$7:$W$26,0)),"") -> Raft concrete pours | G34: =IFERROR(INDEX('Float trend'!$P$7:$P$26,MATCH(SMALL('Float trend'!$W$7:$W$26,3),'Float trend'!$W$7:$W$26,0)),"") -> 2 | H34: =IFERROR(INDEX('Float trend'!$R$7:$R$26,MATCH(SMALL('Float trend'!$W$7:$W$26,3),'Float trend'!$W$7:$W$26,0)),"") -> -2 | I34: =IFERROR(INDEX('Float trend'!$S$7:$S$26,MATCH(SMALL('Float trend'!$W$7:$W$26,3),'Float trend'!$W$7:$W$26,0)),"") -> 1.3333333 | J34: =IFERROR(INDEX('Float trend'!$U$7:$U$26,MATCH(SMALL('Float trend'!$W$7:$W$26,3),'Float trend'!$W$7:$W$26,0)),"") -> Runs out in about 2 update(s) at this rate
B35: =IFERROR(INDEX('Float trend'!$B$7:$B$26,MATCH(SMALL('Float trend'!$W$7:$W$26,4),'Float trend'!$W$7:$W$26,0)),"") -> Testing and commissioning | G35: =IFERROR(INDEX('Float trend'!$P$7:$P$26,MATCH(SMALL('Float trend'!$W$7:$W$26,4),'Float trend'!$W$7:$W$26,0)),"") -> 2 | H35: =IFERROR(INDEX('Float trend'!$R$7:$R$26,MATCH(SMALL('Float trend'!$W$7:$W$26,4),'Float trend'!$W$7:$W$26,0)),"") -> -4 | I35: =IFERROR(INDEX('Float trend'!$S$7:$S$26,MATCH(SMALL('Float trend'!$W$7:$W$26,4),'Float trend'!$W$7:$W$26,0)),"") -> 2 | J35: =IFERROR(INDEX('Float trend'!$U$7:$U$26,MATCH(SMALL('Float trend'!$W$7:$W$26,4),'Float trend'!$W$7:$W$26,0)),"") -> Runs out in about 1 update(s) at this rate
B36: =IFERROR(INDEX('Float trend'!$B$7:$B$26,MATCH(SMALL('Float trend'!$W$7:$W$26,5),'Float trend'!$W$7:$W$26,0)),"") -> Drainage connection to the outfall | G36: =IFERROR(INDEX('Float trend'!$P$7:$P$26,MATCH(SMALL('Float trend'!$W$7:$W$26,5),'Float trend'!$W$7:$W$26,0)),"") -> 3 | H36: =IFERROR(INDEX('Float trend'!$R$7:$R$26,MATCH(SMALL('Float trend'!$W$7:$W$26,5),'Float trend'!$W$7:$W$26,0)),"") -> -22 | I36: =IFERROR(INDEX('Float trend'!$S$7:$S$26,MATCH(SMALL('Float trend'!$W$7:$W$26,5),'Float trend'!$W$7:$W$26,0)),"") -> 8.3333333 | J36: =IFERROR(INDEX('Float trend'!$U$7:$U$26,MATCH(SMALL('Float trend'!$W$7:$W$26,5),'Float trend'!$W$7:$W$26,0)),"") -> Runs out in about 1 update(s) at this rate
B37: =IFERROR(INDEX('Float trend'!$B$7:$B$26,MATCH(SMALL('Float trend'!$W$7:$W$26,6),'Float trend'!$W$7:$W$26,0)),"") -> Handover documents | G37: =IFERROR(INDEX('Float trend'!$P$7:$P$26,MATCH(SMALL('Float trend'!$W$7:$W$26,6),'Float trend'!$W$7:$W$26,0)),"") -> 6 | H37: =IFERROR(INDEX('Float trend'!$R$7:$R$26,MATCH(SMALL('Float trend'!$W$7:$W$26,6),'Float trend'!$W$7:$W$26,0)),"") -> -4 | I37: =IFERROR(INDEX('Float trend'!$S$7:$S$26,MATCH(SMALL('Float trend'!$W$7:$W$26,6),'Float trend'!$W$7:$W$26,0)),"") -> 2 | J37: =IFERROR(INDEX('Float trend'!$U$7:$U$26,MATCH(SMALL('Float trend'!$W$7:$W$26,6),'Float trend'!$W$7:$W$26,0)),"") -> Runs out in about 3 update(s) at this rate
B38: =IFERROR(INDEX('Float trend'!$B$7:$B$26,MATCH(SMALL('Float trend'!$W$7:$W$26,7),'Float trend'!$W$7:$W$26,0)),"") -> Cable pulling and terminations | G38: =IFERROR(INDEX('Float trend'!$P$7:$P$26,MATCH(SMALL('Float trend'!$W$7:$W$26,7),'Float trend'!$W$7:$W$26,0)),"") -> 8 | H38: =IFERROR(INDEX('Float trend'!$R$7:$R$26,MATCH(SMALL('Float trend'!$W$7:$W$26,7),'Float trend'!$W$7:$W$26,0)),"") -> -2 | I38: =IFERROR(INDEX('Float trend'!$S$7:$S$26,MATCH(SMALL('Float trend'!$W$7:$W$26,7),'Float trend'!$W$7:$W$26,0)),"") -> 2.3333333 | J38: =IFERROR(INDEX('Float trend'!$U$7:$U$26,MATCH(SMALL('Float trend'!$W$7:$W$26,7),'Float trend'!$W$7:$W$26,0)),"") -> Burning 2.3 days an update
B39: =IFERROR(INDEX('Float trend'!$B$7:$B$26,MATCH(SMALL('Float trend'!$W$7:$W$26,8),'Float trend'!$W$7:$W$26,0)),"") -> Earthing and lightning protection | G39: =IFERROR(INDEX('Float trend'!$P$7:$P$26,MATCH(SMALL('Float trend'!$W$7:$W$26,8),'Float trend'!$W$7:$W$26,0)),"") -> 16 | H39: =IFERROR(INDEX('Float trend'!$R$7:$R$26,MATCH(SMALL('Float trend'!$W$7:$W$26,8),'Float trend'!$W$7:$W$26,0)),"") -> -2 | I39: =IFERROR(INDEX('Float trend'!$S$7:$S$26,MATCH(SMALL('Float trend'!$W$7:$W$26,8),'Float trend'!$W$7:$W$26,0)),"") -> 2 | J39: =IFERROR(INDEX('Float trend'!$U$7:$U$26,MATCH(SMALL('Float trend'!$W$7:$W$26,8),'Float trend'!$W$7:$W$26,0)),"") -> Burning 2.0 days an update
B40: =IFERROR(INDEX('Float trend'!$B$7:$B$26,MATCH(SMALL('Float trend'!$W$7:$W$26,9),'Float trend'!$W$7:$W$26,0)),"") -> Boundary fence and gates | G40: =IFERROR(INDEX('Float trend'!$P$7:$P$26,MATCH(SMALL('Float trend'!$W$7:$W$26,9),'Float trend'!$W$7:$W$26,0)),"") -> 36 | H40: =IFERROR(INDEX('Float trend'!$R$7:$R$26,MATCH(SMALL('Float trend'!$W$7:$W$26,9),'Float trend'!$W$7:$W$26,0)),"") -> -2 | I40: =IFERROR(INDEX('Float trend'!$S$7:$S$26,MATCH(SMALL('Float trend'!$W$7:$W$26,9),'Float trend'!$W$7:$W$26,0)),"") -> 1.3333333 | J40: =IFERROR(INDEX('Float trend'!$U$7:$U$26,MATCH(SMALL('Float trend'!$W$7:$W$26,9),'Float trend'!$W$7:$W$26,0)),"") -> Burning 1.3 days an update
B41: =IFERROR(INDEX('Float trend'!$B$7:$B$26,MATCH(SMALL('Float trend'!$W$7:$W$26,10),'Float trend'!$W$7:$W$26,0)),"") -> Temporary compound removal | G41: =IFERROR(INDEX('Float trend'!$P$7:$P$26,MATCH(SMALL('Float trend'!$W$7:$W$26,10),'Float trend'!$W$7:$W$26,0)),"") -> 180 | H41: =IFERROR(INDEX('Float trend'!$R$7:$R$26,MATCH(SMALL('Float trend'!$W$7:$W$26,10),'Float trend'!$W$7:$W$26,0)),"") -> 0 | I41: =IFERROR(INDEX('Float trend'!$S$7:$S$26,MATCH(SMALL('Float trend'!$W$7:$W$26,10),'Float trend'!$W$7:$W$26,0)),"") -> 0 | J41: =IFERROR(INDEX('Float trend'!$U$7:$U$26,MATCH(SMALL('Float trend'!$W$7:$W$26,10),'Float trend'!$W$7:$W$26,0)),"") -> Suspicious: 180 days is a missing link, not good news
B44: THE SLOPE, NOT THE VALUE
B63: Lines above 60 days are cut off: anything that high belongs in the Health check, not on this chart. The finish chart shows the forecast finish minus the contract date in Setup.
B83: Everything on this page reads from Setup, Updates, Checklist, Health check, Float trend, Remaining days and Actions.

Sheet Checklist
A1: Checklist | I1: The Project Control Hub
A2: Collect, enter, recalculate, check, analyse, act: then report. Same day, same rules, every period.
A3: Set the Status of each line. "What the file shows" reads the other sheets so you are not ticking from memory.
A5: =IF(COUNTA(F8:F42)=0,"Start with the Updates line, then work down the list.",IF(J5=0,"READY TO ISSUE · every must-do item is done or fixed","NOT READY TO ISSUE · "&J5&" must-do item(s) still open")) -> NOT READY TO ISSUE · 1 must-do item(s) still open | J5: =SUMPRODUCT((D8:D42="Must")*(F8:F42<>"Done")*(F8:F42<>"Fixed")) -> 1
A6: No. | B6: Check | C6: Why it matters | D6: Must | E6: What the file shows | F6: Status | G6: Evidence / note | H6: Owner | I6: Lesson | J6: Sort key
A7: 1 · COLLECT · before you open the software
A8: 1.1 | B8: Same cut-off day and the same rules as every update | C8: A schedule updated when someone remembers is not a control system. | D8: Must | E8: =IFERROR(IF(INDEX(Updates!$C$7:$C$18,Setup!$B$7)="","",IF(INDEX(Updates!$C$7:$C$18,Setup!$B$7)="Y","Same rule: ","Rule changed: ")&Setup!$B$10),"") -> Same rule: Last working day of the month | F8: Done | G8: Last working day of June, as every month | H8: Planner | I8: Topic 16 | J8: =IF(OR(F8="Done",F8="Fixed",F8="N/A"),"",IF(D8="Must",0,1000)+ROW())
A9: 1.2 | B9: Actual dates from site records: diary, inspection sheets, delivery notes | C9: An actual invented in a car anchors every forecast downstream of it. | D9: Must | E9: =IF(COUNTA('Remaining days'!$B$7:$B$46)=0,"",(COUNTIF('Remaining days'!$D$7:$D$46,"Phone call")+COUNTIF('Remaining days'!$D$7:$D$46,"Memory"))&" figure(s) from a phone call or memory") -> 1 figure(s) from a phone call or memory | F9: Done | G9: All actual dates from the daily reports. The one phone-call figure (earthing) is a percentage, not an actual date: see 1.4 | H9: Planner | I9: Topic 16 | J9: =IF(OR(F9="Done",F9="Fixed",F9="N/A"),"",IF(D9="Must",0,1000)+ROW())
A10: 1.3 | B10: Every started activity asked "how many days do you still need?" | C10: Percent complete looks backwards. Remaining duration is the only number that can move a date. | D10: Must | E10: =COUNTA('Remaining days'!$B$7:$B$46)&" in Remaining days, "&COUNTIFS('Remaining days'!$B$7:$B$46,"<>",'Remaining days'!$I$7:$I$46,"")&" without days left" -> 12 in Remaining days, 0 without days left | F10: Done | G10: Twelve activities asked, in the Remaining days sheet | H10: Planner | I10: Topic 16 | J10: =IF(OR(F10="Done",F10="Fixed",F10="N/A"),"",IF(D10="Must",0,1000)+ROW())
A11: 1.4 | B11: No percentage taken from a phone call; stuck percentages challenged | C11: Ninety percent for three months is not ninety percent complete. It is a problem nobody has described. | E11: =COUNTIF('Remaining days'!$M$7:$M$46,"*Stuck*")&" stuck, "&COUNTIF('Remaining days'!$M$7:$M$46,"*Not a site*")&" not from a record" -> 2 stuck, 1 not from a record | F11: Open | G11: Earthing came by phone. Switchgear and the outfall stuck: causes written down | H11: Site engineer | I11: Topic 16 | J11: =IF(OR(F11="Done",F11="Fixed",F11="N/A"),"",IF(D11="Must",0,1000)+ROW()) -> 1011
A12: 1.5 | B12: Subcontractor programmes received, and their scheduling option checked | C12: If they run progress override, they have been sending you optimistic fiction. | F12: Done | G12: Piling and electrical programmes in; both on retained logic | H12: Planner | I12: Topic 16 | J12: =IF(OR(F12="Done",F12="Fixed",F12="N/A"),"",IF(D12="Must",0,1000)+ROW())
A13: 2 · ENTER
A14: 2.1 | B14: Data date moved to the cut-off | C14: Everything before it is history, everything after it is forecast. | D14: Must | E14: =IF(Setup!$B$8="","Type the data date in Updates","Data date "&TEXT(Setup!$B$8,"d mmm yyyy")) -> Data date 30 Jun 2026 | F14: Done | H14: Planner | I14: Topic 16 | J14: =IF(OR(F14="Done",F14="Fixed",F14="N/A"),"",IF(D14="Must",0,1000)+ROW())
A15: 2.2 | B15: Actual starts and finishes entered for everything that moved | C15: An activity that finished on site but not in the model keeps pushing its successors. | F15: Done | H15: Planner | I15: Topic 16 | J15: =IF(OR(F15="Done",F15="Fixed",F15="N/A"),"",IF(D15="Must",0,1000)+ROW())
A16: 2.3 | B16: No actual date later than the data date | C16: An actual in the future is a typing error, never progress. | D16: Must | E16: =IF('Health check'!$O$13="","",'Health check'!$O$13&" found") -> 0 found | F16: Done | G16: None found | H16: Planner | I16: Topic 16 | J16: =IF(OR(F16="Done",F16="Fixed",F16="N/A"),"",IF(D16="Must",0,1000)+ROW())
A17: 2.4 | B17: Remaining durations entered, not only percent complete | C17: The software forecasts from remaining duration. | F17: Done | H17: Planner | I17: Topic 16 | J17: =IF(OR(F17="Done",F17="Fixed",F17="N/A"),"",IF(D17="Must",0,1000)+ROW())
A18: 3 · RECALCULATE
A19: 3.1 | B19: Scheduling option set to retained logic, not progress override | C19: Override deletes real dependencies and returns a date that is not real. | D19: Must | E19: =IFERROR(IF(INDEX(Updates!$D$7:$D$18,Setup!$B$7)="","",INDEX(Updates!$D$7:$D$18,Setup!$B$7)),"") -> Retained logic | F19: Fixed | G19: Was progress override since update 1. Switched: the finish moved 21 days | H19: Planner | I19: Topic 17 | J19: =IF(OR(F19="Done",F19="Fixed",F19="N/A"),"",IF(D19="Must",0,1000)+ROW())
A20: 3.2 | B20: Recalculated and saved as a new version; last update kept to compare | C20: Without last month’s file there is no trend. | F20: Done | G20: Saved as update 6; update 5 kept | H20: Planner | I20: Topic 17 | J20: =IF(OR(F20="Done",F20="Fixed",F20="N/A"),"",IF(D20="Must",0,1000)+ROW())
A21: 3.3 | B21: Baseline untouched | C21: Re-baselining without an approved change hides the slip you are meant to report. | F21: Done | H21: Planner | I21: Topic 17 | J21: =IF(OR(F21="Done",F21="Fixed",F21="N/A"),"",IF(D21="Must",0,1000)+ROW())
A22: 4 · HEALTH CHECK · ten minutes, before a word of the report
A23: 4.1 | B23: No open ends, apart from the first and the last activity | C23: An open end has nothing to push against, so it hands out imaginary float. | D23: Must | E23: =IF('Health check'!$O$7="","",'Health check'!$O$7&" found") -> 2 found | F23: Fixed | G23: Two found and linked. The compound removal: see 4.4 | H23: Planner | I23: Topic 17 | J23: =IF(OR(F23="Done",F23="Fixed",F23="N/A"),"",IF(D23="Must",0,1000)+ROW())
A24: 4.2 | B24: Every hard constraint justified in writing; none absorbing a delay | C24: A hard constraint does not protect the date. It protects you from hearing about it. | D24: Must | E24: =IF('Health check'!$O$8="","",'Health check'!$O$8&" found") -> 1 found | F24: Fixed | G24: Must-finish-on taken off the substation slab: float -10 | H24: Planner | I24: Topic 17 | J24: =IF(OR(F24="Done",F24="Fixed",F24="N/A"),"",IF(D24="Must",0,1000)+ROW())
A25: 4.3 | B25: Out-of-sequence progress reviewed, logic corrected where the site changed the order | C25: The default setting throws away the logic you spent weeks building. | E25: =IF('Health check'!$O$12="","",'Health check'!$O$12&" found") -> 3 found | F25: Fixed | G25: Three found; logic corrected by hand on all three | H25: Planner | I25: Topic 17 | J25: =IF(OR(F25="Done",F25="Fixed",F25="N/A"),"",IF(D25="Must",0,1000)+ROW())
A26: 4.4 | B26: Unusually large float investigated, not reported as good news | C26: Treat it like a pressure gauge reading zero: a broken instrument. | E26: =IF('Health check'!$O$10="","",'Health check'!$O$10&" found") -> 1 found | F26: Open | G26: Temporary compound removal, 180 days: linked only to the finish | H26: Planner | I26: Topic 17 | J26: =IF(OR(F26="Done",F26="Fixed",F26="N/A"),"",IF(D26="Must",0,1000)+ROW()) -> 1026
A27: 4.5 | B27: Long lags turned into activities with an owner | C27: Waiting that belongs to a person should have their name on it. | E27: =IF('Health check'!$O$11="","",'Health check'!$O$11&" found") -> 3 found | F27: Open | G27: Three over 10 days. Two are curing; one is an approval | H27: Planner | I27: Topic 17 | J27: =IF(OR(F27="Done",F27="Fixed",F27="N/A"),"",IF(D27="Must",0,1000)+ROW()) -> 1027
A28: 5 · ANALYSE
A29: 5.1 | B29: Float on the top ten compared with last update: the change, not the value | C29: Today’s float says where you stand. The slope says where you are going. | D29: Must | E29: =COUNT('Float trend'!$R$7:$R$26)&" compared; worst change "&IFERROR(TEXT(MIN('Float trend'!$R$7:$R$26),"+0;-0;0")&" days","—") -> 10 compared; worst change -22 days | F29: Done | G29: Ten compared in the Float trend sheet | H29: Planner | I29: Topic 16 | J29: =IF(OR(F29="Done",F29="Fixed",F29="N/A"),"",IF(D29="Must",0,1000)+ROW())
A30: 5.2 | B30: Every activity burning float named, with when it runs out | C30: The facade burns five days a month. In January it looked green; the trend already knew. | E30: =COUNTIF('Float trend'!$U$7:$U$26,"Runs out*")&" run out within "&Setup!$B$14&" updates" -> 4 run out within 3 updates | F30: Done | G30: Raft pours, commissioning, handover and the outfall named | H30: Planner | I30: Topic 16 | J30: =IF(OR(F30="Done",F30="Fixed",F30="N/A"),"",IF(D30="Must",0,1000)+ROW())
A31: 5.3 | B31: Every activity with negative float listed as already late | C31: Negative float is not a warning that you might be late. You are. | D31: Must | E31: =COUNTIF('Float trend'!$P$7:$P$26,"<0")&" with negative float" -> 2 with negative float | F31: Done | G31: Switchgear 4 days, substation slab 10 days | H31: Planner | I31: Topic 16 | J31: =IF(OR(F31="Done",F31="Fixed",F31="N/A"),"",IF(D31="Must",0,1000)+ROW())
A32: 5.4 | B32: Forecast finish compared with last update and with the contract; every move explained | C32: A finish that moves without a reason is a finish nobody understands. | D32: Must | E32: =IFERROR(IF(INDEX(Updates!$E$7:$E$18,Setup!$B$7)="","","Finish "&TEXT(INDEX(Updates!$E$7:$E$18,Setup!$B$7),"d mmm yy")&IF(INDEX(Updates!$G$7:$G$18,Setup!$B$7)="",""," · moved "&TEXT(INDEX(Updates!$G$7:$G$18,Setup!$B$7),"+0;-0;0")&" d")),"") -> Finish 4 Sep 26 · moved +21 d | F32: Done | G32: Retained logic and the slab constraint: 21 days | H32: Planner | I32: Topic 16 | J32: =IF(OR(F32="Done",F32="Fixed",F32="N/A"),"",IF(D32="Must",0,1000)+ROW())
A33: 5.5 | B33: Delay stated in time as well as money | C33: Earned schedule turns the cost report into months behind (Earned value calculator). | F33: Done | H33: Commercial | I33: Topic 16 | J33: =IF(OR(F33="Done",F33="Fixed",F33="N/A"),"",IF(D33="Must",0,1000)+ROW())
A34: 6 · ACT
A35: 6.1 | B35: Every slipping path has an action, a person and a date | C35: Analysis that ends without an owner is project journalism. | D35: Must | E35: =COUNTIFS(Actions!$A$7:$A$36,"<>",Actions!$D$7:$D$36,"",Actions!$F$7:$F$36,"<>Done")&" path(s) without an owner" -> 2 path(s) without an owner | F35: Not done | G35: Two paths still without an owner | H35: Project manager | I35: Topic 16 | J35: =IF(OR(F35="Done",F35="Fixed",F35="N/A"),"",IF(D35="Must",0,1000)+ROW()) -> 35
A36: 6.2 | B36: Recovery options tested in a copy, not in the live update | C36: The update records what is true; the copy tests what could be. | F36: Done | G36: Two-gang slab option tested in a copy: 6 of the 10 days back | H36: Planner | I36: Topic 16 | J36: =IF(OR(F36="Done",F36="Fixed",F36="N/A"),"",IF(D36="Must",0,1000)+ROW())
A37: 6.3 | B37: Decisions needed from the client written as requests, with a date | C37: A decision nobody asked for in writing is a decision nobody owes you. | F37: N/A | G37: None needed this month | I37: Topic 16 | J37: =IF(OR(F37="Done",F37="Fixed",F37="N/A"),"",IF(D37="Must",0,1000)+ROW())
A38: 7 · REPORT · last, not instead
A39: 7.1 | B39: Report written after the analysis, not instead of it | C39: Reporting without analysis is describing the accident instead of steering away from it. | D39: Must | F39: Done | G39: Draft written after the float review; not issued | H39: Planner | I39: Topic 16 | J39: =IF(OR(F39="Done",F39="Fixed",F39="N/A"),"",IF(D39="Must",0,1000)+ROW())
A40: 7.2 | B40: First paragraph: how far the finish moved, why, and what is being done | C40: Most readers stop after the first paragraph. | F40: Done | H40: Planner | I40: Topic 16 | J40: =IF(OR(F40="Done",F40="Fixed",F40="N/A"),"",IF(D40="Must",0,1000)+ROW())
A41: 7.3 | B41: Issued on the same working day after the cut-off as every period | C41: A late report is read as a hidden problem. | E41: =IFERROR(IF(INDEX(Updates!$J$7:$J$18,Setup!$B$7)="","Not issued yet","Issued "&TEXT(INDEX(Updates!$J$7:$J$18,Setup!$B$7),"d mmm")&", "&INDEX(Updates!$K$7:$K$18,Setup!$B$7)&" working days after"),"") -> Not issued yet | F41: Not done | H41: Planner | I41: Topic 16 | J41: =IF(OR(F41="Done",F41="Fixed",F41="N/A"),"",IF(D41="Must",0,1000)+ROW()) -> 1041
...

Sheet Health check
A1: Health check | S1: The Project Control Hub
A2: The ten-minute check, every update, before a word of the report. Count what you find.
A3: Type the count for each update in its column. Nobody has ever run this list on a live project and found nothing.
A6: Check | B6: How to find it | C6: U1 | D6: U2 | E6: U3 | F6: U4 | G6: U5 | H6: U6 | I6: U7 | J6: U8 | K6: U9 | L6: U10 | M6: U11 | N6: U12 | O6: This update | P6: Last update | Q6: Change | R6: Target | S6: Result
A7: Open ends | B7: Activities with no predecessor or no successor, apart from the first and the last. In P6: filter on predecessors / successors empty. | C7: 4 | D7: 3 | E7: 3 | F7: 2 | G7: 2 | H7: 2 | O7: =IFERROR(IF(INDEX($C7:$N7,Setup!$B$7)="","",INDEX($C7:$N7,Setup!$B$7)),"") -> 2 | P7: =IFERROR(IF(Setup!$B$7<2,"",IF(INDEX($C7:$N7,Setup!$B$7-1)="","",INDEX($C7:$N7,Setup!$B$7-1))),"") -> 2 | Q7: =IF(OR(O7="",P7=""),"",O7-P7) -> 0 | R7: 0 | S7: =IF(O7="","",IF(O7<=R7,"✔ clean",O7&" found. Link it. Open ends make float out of nothing.")) -> 2 found. Link it. Open ends make float out of nothing.
A8: Hard constraints without a written reason | B8: "Must finish on", "mandatory start / finish" and the like, with no note saying why. Each one stops a delay from travelling. | C8: 1 | D8: 1 | E8: 2 | F8: 2 | G8: 2 | H8: 1 | O8: =IFERROR(IF(INDEX($C8:$N8,Setup!$B$7)="","",INDEX($C8:$N8,Setup!$B$7)),"") -> 1 | P8: =IFERROR(IF(Setup!$B$7<2,"",IF(INDEX($C8:$N8,Setup!$B$7-1)="","",INDEX($C8:$N8,Setup!$B$7-1))),"") -> 2 | Q8: =IF(OR(O8="",P8=""),"",O8-P8) -> -1 | R8: 0 | S8: =IF(O8="","",IF(O8<=R8,"✔ clean",O8&" found. Write the reason or take it off.")) -> 1 found. Write the reason or take it off.
A9: Activities with negative float | B9: Total float below zero. The deadline has already passed the work. | C9: 0 | D9: 0 | E9: 0 | F9: 0 | G9: 0 | H9: 2 | O9: =IFERROR(IF(INDEX($C9:$N9,Setup!$B$7)="","",INDEX($C9:$N9,Setup!$B$7)),"") -> 2 | P9: =IFERROR(IF(Setup!$B$7<2,"",IF(INDEX($C9:$N9,Setup!$B$7-1)="","",INDEX($C9:$N9,Setup!$B$7-1))),"") -> 0 | Q9: =IF(OR(O9="",P9=""),"",O9-P9) -> 2 | R9: 0 | S9: =IF(O9="","",IF(O9<=R9,"✔ clean",O9&" found. List them as late, with how late, in the report.")) -> 2 found. List them as late, with how late, in the report.
A10: Float above the Setup limit | B10: Total float above the "suspicious" value in Setup. Usually a missing link, not good news. | C10: 2 | D10: 2 | E10: 2 | F10: 1 | G10: 1 | H10: 1 | O10: =IFERROR(IF(INDEX($C10:$N10,Setup!$B$7)="","",INDEX($C10:$N10,Setup!$B$7)),"") -> 1 | P10: =IFERROR(IF(Setup!$B$7<2,"",IF(INDEX($C10:$N10,Setup!$B$7-1)="","",INDEX($C10:$N10,Setup!$B$7-1))),"") -> 1 | Q10: =IF(OR(O10="",P10=""),"",O10-P10) -> 0 | R10: 0 | S10: =IF(O10="","",IF(O10<=R10,"✔ clean",O10&" found. Investigate: find the missing successor.")) -> 1 found. Investigate: find the missing successor.
A11: Lags longer than the Setup limit | B11: Long lags hide work that belongs to somebody: curing, approvals, deliveries. | C11: 5 | D11: 5 | E11: 4 | F11: 4 | G11: 3 | H11: 3 | O11: =IFERROR(IF(INDEX($C11:$N11,Setup!$B$7)="","",INDEX($C11:$N11,Setup!$B$7)),"") -> 3 | P11: =IFERROR(IF(Setup!$B$7<2,"",IF(INDEX($C11:$N11,Setup!$B$7-1)="","",INDEX($C11:$N11,Setup!$B$7-1))),"") -> 3 | Q11: =IF(OR(O11="",P11=""),"",O11-P11) -> 0 | R11: 0 | S11: =IF(O11="","",IF(O11<=R11,"✔ clean",O11&" found. Make it an activity with an owner.")) -> 3 found. Make it an activity with an owner.
A12: Out-of-sequence progress | B12: Started before its predecessor finished. Override drops the logic; retained logic keeps it. | C12: 0 | D12: 2 | E12: 3 | F12: 5 | G12: 4 | H12: 3 | O12: =IFERROR(IF(INDEX($C12:$N12,Setup!$B$7)="","",INDEX($C12:$N12,Setup!$B$7)),"") -> 3 | P12: =IFERROR(IF(Setup!$B$7<2,"",IF(INDEX($C12:$N12,Setup!$B$7-1)="","",INDEX($C12:$N12,Setup!$B$7-1))),"") -> 4 | Q12: =IF(OR(O12="",P12=""),"",O12-P12) -> -1 | R12: 0 | S12: =IF(O12="","",IF(O12<=R12,"✔ clean",O12&" found. Correct the logic by hand where the site changed the order.")) -> 3 found. Correct the logic by hand where the site changed the order.
A13: Actual dates after the data date | B13: An actual start or finish in the future. Always a typing error, never progress. | C13: 1 | D13: 0 | E13: 0 | F13: 0 | G13: 0 | H13: 0 | O13: =IFERROR(IF(INDEX($C13:$N13,Setup!$B$7)="","",INDEX($C13:$N13,Setup!$B$7)),"") -> 0 | P13: =IFERROR(IF(Setup!$B$7<2,"",IF(INDEX($C13:$N13,Setup!$B$7-1)="","",INDEX($C13:$N13,Setup!$B$7-1))),"") -> 0 | Q13: =IF(OR(O13="",P13=""),"",O13-P13) -> 0 | R13: 0 | S13: =IF(O13="","",IF(O13<=R13,"✔ clean",O13&" found. Correct it before you recalculate.")) -> ✔ clean
A14: Started activities with no remaining duration from site | B14: Anything in progress where nobody was asked "how many days do you still need?" | C14: 6 | D14: 4 | E14: 3 | F14: 2 | G14: 1 | H14: 0 | O14: =IFERROR(IF(INDEX($C14:$N14,Setup!$B$7)="","",INDEX($C14:$N14,Setup!$B$7)),"") -> 0 | P14: =IFERROR(IF(Setup!$B$7<2,"",IF(INDEX($C14:$N14,Setup!$B$7-1)="","",INDEX($C14:$N14,Setup!$B$7-1))),"") -> 1 | Q14: =IF(OR(O14="",P14=""),"",O14-P14) -> -1 | R14: 0 | S14: =IF(O14="","",IF(O14<=R14,"✔ clean",O14&" found. Ask the question. Percent complete cannot move a date.")) -> ✔ clean
A16: FOUND THIS UPDATE | B16: =IF(COUNT(O7:O14)=0,"",COUNTIF(S7:S14,"*found*")&" of "&ROWS(O7:O14)&" checks found something, "&SUM(O7:O14)&" items in all. Fix them, or say in the report why they stay.") -> 6 of 8 checks found something, 12 items in all. Fix them, or say in the report why they stay.
A18: The limits for "suspicious float" and "long lags" are in Setup. The highlighted column is the update in Setup. Retained logic or progress override is recorded per update in Updates.

Sheet Float trend
A1: Float trend | V1: The Project Control Hub
A2: Float is a radar, not a number: the change since last update, and the update it runs out.
A3: Type the total float of your ten (or twenty) most important activities at every update. Read the slope, not the value.
A6: ID | B6: Activity | C6: U1 | D6: U2 | E6: U3 | F6: U4 | G6: U5 | H6: U6 | I6: U7 | J6: U8 | K6: U9 | L6: U10 | M6: U11 | N6: U12 | O6: Path | P6: Float now | Q6: Last update | R6: Change | S6: Burn per update | T6: Runs out in (updates) | U6: Reading | V6: Note | W6: Sort key
A7: A13 | B7: Switchgear delivery and installation | C7: 24 | D7: 18 | E7: 9 | F7: 5 | G7: 1 | H7: -4 | O7: Procurement | P7: =IF(B7="","",IFERROR(IF(INDEX($C7:$N7,Setup!$B$7)="","",INDEX($C7:$N7,Setup!$B$7)),"")) -> -4 | Q7: =IF(OR(P7="",Setup!$B$7<2),"",IFERROR(IF(INDEX($C7:$N7,Setup!$B$7-1)="","",INDEX($C7:$N7,Setup!$B$7-1)),"")) -> 1 | R7: =IF(OR(P7="",Q7=""),"",P7-Q7) -> -5 | S7: =IF(P7="","",IFERROR(IF(OR((Setup!$B$7-MAX(1,Setup!$B$7-Setup!$B$13))=0,INDEX($C7:$N7,MAX(1,Setup!$B$7-Setup!$B$13))=""),"",(INDEX($C7:$N7,MAX(1,Setup!$B$7-Setup!$B$13))-P7)/(Setup!$B$7-MAX(1,Setup!$B$7-Setup!$B$13))),"")) -> 4.3333333 | T7: =IF(OR(P7="",S7=""),"",IF(AND(S7>0,P7>0),P7/S7,"")) | U7: =IF(P7="","",IF(P7>=Setup!$B$11,"Suspicious: "&P7&" days is a missing link, not good news",IF(P7<0,"Already late by "&-P7&" days",IF(P7=0,"Critical: no float left",IF(AND(T7<>"",T7<=Setup!$B$14),"Runs out in about "&ROUNDUP(T7,0)&" update(s) at this rate",IF(N(S7)>0,"Burning "&TEXT(S7,"0.0")&" days an update","Holding")))))) -> Already late by 4 days | V7: Five days an update, every update. In February it looked fine; the slope already knew. | W7: =IF(P7="","",P7+ROW()/1000) -> -3.993
A8: A11 | B8: Substation slab | C8: 18 | D8: 18 | E8: 0 | F8: 0 | G8: 0 | H8: -10 | O8: Substation | P8: =IF(B8="","",IFERROR(IF(INDEX($C8:$N8,Setup!$B$7)="","",INDEX($C8:$N8,Setup!$B$7)),"")) -> -10 | Q8: =IF(OR(P8="",Setup!$B$7<2),"",IFERROR(IF(INDEX($C8:$N8,Setup!$B$7-1)="","",INDEX($C8:$N8,Setup!$B$7-1)),"")) -> 0 | R8: =IF(OR(P8="",Q8=""),"",P8-Q8) -> -10 | S8: =IF(P8="","",IFERROR(IF(OR((Setup!$B$7-MAX(1,Setup!$B$7-Setup!$B$13))=0,INDEX($C8:$N8,MAX(1,Setup!$B$7-Setup!$B$13))=""),"",(INDEX($C8:$N8,MAX(1,Setup!$B$7-Setup!$B$13))-P8)/(Setup!$B$7-MAX(1,Setup!$B$7-Setup!$B$13))),"")) -> 3.3333333 | T8: =IF(OR(P8="",S8=""),"",IF(AND(S8>0,P8>0),P8/S8,"")) | U8: =IF(P8="","",IF(P8>=Setup!$B$11,"Suspicious: "&P8&" days is a missing link, not good news",IF(P8<0,"Already late by "&-P8&" days",IF(P8=0,"Critical: no float left",IF(AND(T8<>"",T8<=Setup!$B$14),"Runs out in about "&ROUNDUP(T8,0)&" update(s) at this rate",IF(N(S8)>0,"Burning "&TEXT(S8,"0.0")&" days an update","Holding")))))) -> Already late by 10 days | V8: Pinned by a must-finish-on from update 3 to 5. Taken off in update 6: the ten days were there all along. | W8: =IF(P8="","",P8+ROW()/1000) -> -9.992
A9: A10 | B9: Raft concrete pours | C9: 10 | D9: 10 | E9: 6 | F9: 4 | G9: 4 | H9: 2 | O9: Substation | P9: =IF(B9="","",IFERROR(IF(INDEX($C9:$N9,Setup!$B$7)="","",INDEX($C9:$N9,Setup!$B$7)),"")) -> 2 | Q9: =IF(OR(P9="",Setup!$B$7<2),"",IFERROR(IF(INDEX($C9:$N9,Setup!$B$7-1)="","",INDEX($C9:$N9,Setup!$B$7-1)),"")) -> 4 | R9: =IF(OR(P9="",Q9=""),"",P9-Q9) -> -2 | S9: =IF(P9="","",IFERROR(IF(OR((Setup!$B$7-MAX(1,Setup!$B$7-Setup!$B$13))=0,INDEX($C9:$N9,MAX(1,Setup!$B$7-Setup!$B$13))=""),"",(INDEX($C9:$N9,MAX(1,Setup!$B$7-Setup!$B$13))-P9)/(Setup!$B$7-MAX(1,Setup!$B$7-Setup!$B$13))),"")) -> 1.3333333 | T9: =IF(OR(P9="",S9=""),"",IF(AND(S9>0,P9>0),P9/S9,"")) -> 1.5 | U9: =IF(P9="","",IF(P9>=Setup!$B$11,"Suspicious: "&P9&" days is a missing link, not good news",IF(P9<0,"Already late by "&-P9&" days",IF(P9=0,"Critical: no float left",IF(AND(T9<>"",T9<=Setup!$B$14),"Runs out in about "&ROUNDUP(T9,0)&" update(s) at this rate",IF(N(S9)>0,"Burning "&TEXT(S9,"0.0")&" days an update","Holding")))))) -> Runs out in about 2 update(s) at this rate | V9: Follows the raft rebar. | W9: =IF(P9="","",P9+ROW()/1000) -> 2.009
A10: A15 | B10: Cable pulling and terminations | C10: 20 | D10: 20 | E10: 15 | F10: 12 | G10: 10 | H10: 8 | O10: Substation | P10: =IF(B10="","",IFERROR(IF(INDEX($C10:$N10,Setup!$B$7)="","",INDEX($C10:$N10,Setup!$B$7)),"")) -> 8 | Q10: =IF(OR(P10="",Setup!$B$7<2),"",IFERROR(IF(INDEX($C10:$N10,Setup!$B$7-1)="","",INDEX($C10:$N10,Setup!$B$7-1)),"")) -> 10 | R10: =IF(OR(P10="",Q10=""),"",P10-Q10) -> -2 | S10: =IF(P10="","",IFERROR(IF(OR((Setup!$B$7-MAX(1,Setup!$B$7-Setup!$B$13))=0,INDEX($C10:$N10,MAX(1,Setup!$B$7-Setup!$B$13))=""),"",(INDEX($C10:$N10,MAX(1,Setup!$B$7-Setup!$B$13))-P10)/(Setup!$B$7-MAX(1,Setup!$B$7-Setup!$B$13))),"")) -> 2.3333333 | T10: =IF(OR(P10="",S10=""),"",IF(AND(S10>0,P10>0),P10/S10,"")) -> 3.4285714 | U10: =IF(P10="","",IF(P10>=Setup!$B$11,"Suspicious: "&P10&" days is a missing link, not good news",IF(P10<0,"Already late by "&-P10&" days",IF(P10=0,"Critical: no float left",IF(AND(T10<>"",T10<=Setup!$B$14),"Runs out in about "&ROUNDUP(T10,0)&" update(s) at this rate",IF(N(S10)>0,"Burning "&TEXT(S10,"0.0")&" days an update","Holding")))))) -> Burning 2.3 days an update | W10: =IF(P10="","",P10+ROW()/1000) -> 8.01
A11: A16 | B11: Testing and commissioning | C11: 12 | D11: 12 | E11: 8 | F11: 6 | G11: 6 | H11: 2 | O11: Substation | P11: =IF(B11="","",IFERROR(IF(INDEX($C11:$N11,Setup!$B$7)="","",INDEX($C11:$N11,Setup!$B$7)),"")) -> 2 | Q11: =IF(OR(P11="",Setup!$B$7<2),"",IFERROR(IF(INDEX($C11:$N11,Setup!$B$7-1)="","",INDEX($C11:$N11,Setup!$B$7-1)),"")) -> 6 | R11: =IF(OR(P11="",Q11=""),"",P11-Q11) -> -4 | S11: =IF(P11="","",IFERROR(IF(OR((Setup!$B$7-MAX(1,Setup!$B$7-Setup!$B$13))=0,INDEX($C11:$N11,MAX(1,Setup!$B$7-Setup!$B$13))=""),"",(INDEX($C11:$N11,MAX(1,Setup!$B$7-Setup!$B$13))-P11)/(Setup!$B$7-MAX(1,Setup!$B$7-Setup!$B$13))),"")) -> 2 | T11: =IF(OR(P11="",S11=""),"",IF(AND(S11>0,P11>0),P11/S11,"")) -> 1 | U11: =IF(P11="","",IF(P11>=Setup!$B$11,"Suspicious: "&P11&" days is a missing link, not good news",IF(P11<0,"Already late by "&-P11&" days",IF(P11=0,"Critical: no float left",IF(AND(T11<>"",T11<=Setup!$B$14),"Runs out in about "&ROUNDUP(T11,0)&" update(s) at this rate",IF(N(S11)>0,"Burning "&TEXT(S11,"0.0")&" days an update","Holding")))))) -> Runs out in about 1 update(s) at this rate | W11: =IF(P11="","",P11+ROW()/1000) -> 2.011
A12: A17 | B12: Handover documents | C12: 15 | D12: 15 | E12: 12 | F12: 10 | G12: 10 | H12: 6 | O12: Site | P12: =IF(B12="","",IFERROR(IF(INDEX($C12:$N12,Setup!$B$7)="","",INDEX($C12:$N12,Setup!$B$7)),"")) -> 6 | Q12: =IF(OR(P12="",Setup!$B$7<2),"",IFERROR(IF(INDEX($C12:$N12,Setup!$B$7-1)="","",INDEX($C12:$N12,Setup!$B$7-1)),"")) -> 10 | R12: =IF(OR(P12="",Q12=""),"",P12-Q12) -> -4 | S12: =IF(P12="","",IFERROR(IF(OR((Setup!$B$7-MAX(1,Setup!$B$7-Setup!$B$13))=0,INDEX($C12:$N12,MAX(1,Setup!$B$7-Setup!$B$13))=""),"",(INDEX($C12:$N12,MAX(1,Setup!$B$7-Setup!$B$13))-P12)/(Setup!$B$7-MAX(1,Setup!$B$7-Setup!$B$13))),"")) -> 2 | T12: =IF(OR(P12="",S12=""),"",IF(AND(S12>0,P12>0),P12/S12,"")) -> 3 | U12: =IF(P12="","",IF(P12>=Setup!$B$11,"Suspicious: "&P12&" days is a missing link, not good news",IF(P12<0,"Already late by "&-P12&" days",IF(P12=0,"Critical: no float left",IF(AND(T12<>"",T12<=Setup!$B$14),"Runs out in about "&ROUNDUP(T12,0)&" update(s) at this rate",IF(N(S12)>0,"Burning "&TEXT(S12,"0.0")&" days an update","Holding")))))) -> Runs out in about 3 update(s) at this rate | W12: =IF(P12="","",P12+ROW()/1000) -> 6.012
A13: A18 | B13: Earthing and lightning protection | C13: 25 | D13: 25 | E13: 22 | F13: 20 | G13: 18 | H13: 16 | O13: Site | P13: =IF(B13="","",IFERROR(IF(INDEX($C13:$N13,Setup!$B$7)="","",INDEX($C13:$N13,Setup!$B$7)),"")) -> 16 | Q13: =IF(OR(P13="",Setup!$B$7<2),"",IFERROR(IF(INDEX($C13:$N13,Setup!$B$7-1)="","",INDEX($C13:$N13,Setup!$B$7-1)),"")) -> 18 | R13: =IF(OR(P13="",Q13=""),"",P13-Q13) -> -2 | S13: =IF(P13="","",IFERROR(IF(OR((Setup!$B$7-MAX(1,Setup!$B$7-Setup!$B$13))=0,INDEX($C13:$N13,MAX(1,Setup!$B$7-Setup!$B$13))=""),"",(INDEX($C13:$N13,MAX(1,Setup!$B$7-Setup!$B$13))-P13)/(Setup!$B$7-MAX(1,Setup!$B$7-Setup!$B$13))),"")) -> 2 | T13: =IF(OR(P13="",S13=""),"",IF(AND(S13>0,P13>0),P13/S13,"")) -> 8 | U13: =IF(P13="","",IF(P13>=Setup!$B$11,"Suspicious: "&P13&" days is a missing link, not good news",IF(P13<0,"Already late by "&-P13&" days",IF(P13=0,"Critical: no float left",IF(AND(T13<>"",T13<=Setup!$B$14),"Runs out in about "&ROUNDUP(T13,0)&" update(s) at this rate",IF(N(S13)>0,"Burning "&TEXT(S13,"0.0")&" days an update","Holding")))))) -> Burning 2.0 days an update | W13: =IF(P13="","",P13+ROW()/1000) -> 16.013
A14: A19 | B14: Drainage connection to the outfall | C14: 30 | D14: 30 | E14: 28 | F14: 26 | G14: 25 | H14: 3 | O14: Site | P14: =IF(B14="","",IFERROR(IF(INDEX($C14:$N14,Setup!$B$7)="","",INDEX($C14:$N14,Setup!$B$7)),"")) -> 3 | Q14: =IF(OR(P14="",Setup!$B$7<2),"",IFERROR(IF(INDEX($C14:$N14,Setup!$B$7-1)="","",INDEX($C14:$N14,Setup!$B$7-1)),"")) -> 25 | R14: =IF(OR(P14="",Q14=""),"",P14-Q14) -> -22 | S14: =IF(P14="","",IFERROR(IF(OR((Setup!$B$7-MAX(1,Setup!$B$7-Setup!$B$13))=0,INDEX($C14:$N14,MAX(1,Setup!$B$7-Setup!$B$13))=""),"",(INDEX($C14:$N14,MAX(1,Setup!$B$7-Setup!$B$13))-P14)/(Setup!$B$7-MAX(1,Setup!$B$7-Setup!$B$13))),"")) -> 8.3333333 | T14: =IF(OR(P14="",S14=""),"",IF(AND(S14>0,P14>0),P14/S14,"")) -> 0.36 | U14: =IF(P14="","",IF(P14>=Setup!$B$11,"Suspicious: "&P14&" days is a missing link, not good news",IF(P14<0,"Already late by "&-P14&" days",IF(P14=0,"Critical: no float left",IF(AND(T14<>"",T14<=Setup!$B$14),"Runs out in about "&ROUNDUP(T14,0)&" update(s) at this rate",IF(N(S14)>0,"Burning "&TEXT(S14,"0.0")&" days an update","Holding")))))) -> Runs out in about 1 update(s) at this rate | V14: Stuck at 90% for three updates, waiting for the discharge consent. This update the days left were asked for: -22. | W14: =IF(P14="","",P14+ROW()/1000) -> 3.014
A15: A20 | B15: Boundary fence and gates | C15: 40 | D15: 40 | E15: 40 | F15: 38 | G15: 38 | H15: 36 | O15: Site | P15: =IF(B15="","",IFERROR(IF(INDEX($C15:$N15,Setup!$B$7)="","",INDEX($C15:$N15,Setup!$B$7)),"")) -> 36 | Q15: =IF(OR(P15="",Setup!$B$7<2),"",IFERROR(IF(INDEX($C15:$N15,Setup!$B$7-1)="","",INDEX($C15:$N15,Setup!$B$7-1)),"")) -> 38 | R15: =IF(OR(P15="",Q15=""),"",P15-Q15) -> -2 | S15: =IF(P15="","",IFERROR(IF(OR((Setup!$B$7-MAX(1,Setup!$B$7-Setup!$B$13))=0,INDEX($C15:$N15,MAX(1,Setup!$B$7-Setup!$B$13))=""),"",(INDEX($C15:$N15,MAX(1,Setup!$B$7-Setup!$B$13))-P15)/(Setup!$B$7-MAX(1,Setup!$B$7-Setup!$B$13))),"")) -> 1.3333333 | T15: =IF(OR(P15="",S15=""),"",IF(AND(S15>0,P15>0),P15/S15,"")) -> 27 | U15: =IF(P15="","",IF(P15>=Setup!$B$11,"Suspicious: "&P15&" days is a missing link, not good news",IF(P15<0,"Already late by "&-P15&" days",IF(P15=0,"Critical: no float left",IF(AND(T15<>"",T15<=Setup!$B$14),"Runs out in about "&ROUNDUP(T15,0)&" update(s) at this rate",IF(N(S15)>0,"Burning "&TEXT(S15,"0.0")&" days an update","Holding")))))) -> Burning 1.3 days an update | W15: =IF(P15="","",P15+ROW()/1000) -> 36.015
A16: A21 | B16: Temporary compound removal | C16: 180 | D16: 180 | E16: 180 | F16: 180 | G16: 180 | H16: 180 | O16: Site | P16: =IF(B16="","",IFERROR(IF(INDEX($C16:$N16,Setup!$B$7)="","",INDEX($C16:$N16,Setup!$B$7)),"")) -> 180 | Q16: =IF(OR(P16="",Setup!$B$7<2),"",IFERROR(IF(INDEX($C16:$N16,Setup!$B$7-1)="","",INDEX($C16:$N16,Setup!$B$7-1)),"")) -> 180 | R16: =IF(OR(P16="",Q16=""),"",P16-Q16) -> 0 | S16: =IF(P16="","",IFERROR(IF(OR((Setup!$B$7-MAX(1,Setup!$B$7-Setup!$B$13))=0,INDEX($C16:$N16,MAX(1,Setup!$B$7-Setup!$B$13))=""),"",(INDEX($C16:$N16,MAX(1,Setup!$B$7-Setup!$B$13))-P16)/(Setup!$B$7-MAX(1,Setup!$B$7-Setup!$B$13))),"")) -> 0 | T16: =IF(OR(P16="",S16=""),"",IF(AND(S16>0,P16>0),P16/S16,"")) | U16: =IF(P16="","",IF(P16>=Setup!$B$11,"Suspicious: "&P16&" days is a missing link, not good news",IF(P16<0,"Already late by "&-P16&" days",IF(P16=0,"Critical: no float left",IF(AND(T16<>"",T16<=Setup!$B$14),"Runs out in about "&ROUNDUP(T16,0)&" update(s) at this rate",IF(N(S16)>0,"Burning "&TEXT(S16,"0.0")&" days an update","Holding")))))) -> Suspicious: 180 days is a missing link, not good news | V16: Linked only to the finish milestone: 180 days of float nobody can use. | W16: =IF(P16="","",P16+ROW()/1000) -> 180.016
P17: =IF(B17="","",IFERROR(IF(INDEX($C17:$N17,Setup!$B$7)="","",INDEX($C17:$N17,Setup!$B$7)),"")) | Q17: =IF(OR(P17="",Setup!$B$7<2),"",IFERROR(IF(INDEX($C17:$N17,Setup!$B$7-1)="","",INDEX($C17:$N17,Setup!$B$7-1)),"")) | R17: =IF(OR(P17="",Q17=""),"",P17-Q17) | S17: =IF(P17="","",IFERROR(IF(OR((Setup!$B$7-MAX(1,Setup!$B$7-Setup!$B$13))=0,INDEX($C17:$N17,MAX(1,Setup!$B$7-Setup!$B$13))=""),"",(INDEX($C17:$N17,MAX(1,Setup!$B$7-Setup!$B$13))-P17)/(Setup!$B$7-MAX(1,Setup!$B$7-Setup!$B$13))),"")) | T17: =IF(OR(P17="",S17=""),"",IF(AND(S17>0,P17>0),P17/S17,"")) | U17: =IF(P17="","",IF(P17>=Setup!$B$11,"Suspicious: "&P17&" days is a missing link, not good news",IF(P17<0,"Already late by "&-P17&" days",IF(P17=0,"Critical: no float left",IF(AND(T17<>"",T17<=Setup!$B$14),"Runs out in about "&ROUNDUP(T17,0)&" update(s) at this rate",IF(N(S17)>0,"Burning "&TEXT(S17,"0.0")&" days an update","Holding")))))) | W17: =IF(P17="","",P17+ROW()/1000)
P18: =IF(B18="","",IFERROR(IF(INDEX($C18:$N18,Setup!$B$7)="","",INDEX($C18:$N18,Setup!$B$7)),"")) | Q18: =IF(OR(P18="",Setup!$B$7<2),"",IFERROR(IF(INDEX($C18:$N18,Setup!$B$7-1)="","",INDEX($C18:$N18,Setup!$B$7-1)),"")) | R18: =IF(OR(P18="",Q18=""),"",P18-Q18) | S18: =IF(P18="","",IFERROR(IF(OR((Setup!$B$7-MAX(1,Setup!$B$7-Setup!$B$13))=0,INDEX($C18:$N18,MAX(1,Setup!$B$7-Setup!$B$13))=""),"",(INDEX($C18:$N18,MAX(1,Setup!$B$7-Setup!$B$13))-P18)/(Setup!$B$7-MAX(1,Setup!$B$7-Setup!$B$13))),"")) | T18: =IF(OR(P18="",S18=""),"",IF(AND(S18>0,P18>0),P18/S18,"")) | U18: =IF(P18="","",IF(P18>=Setup!$B$11,"Suspicious: "&P18&" days is a missing link, not good news",IF(P18<0,"Already late by "&-P18&" days",IF(P18=0,"Critical: no float left",IF(AND(T18<>"",T18<=Setup!$B$14),"Runs out in about "&ROUNDUP(T18,0)&" update(s) at this rate",IF(N(S18)>0,"Burning "&TEXT(S18,"0.0")&" days an update","Holding")))))) | W18: =IF(P18="","",P18+ROW()/1000)
P19: =IF(B19="","",IFERROR(IF(INDEX($C19:$N19,Setup!$B$7)="","",INDEX($C19:$N19,Setup!$B$7)),"")) | Q19: =IF(OR(P19="",Setup!$B$7<2),"",IFERROR(IF(INDEX($C19:$N19,Setup!$B$7-1)="","",INDEX($C19:$N19,Setup!$B$7-1)),"")) | R19: =IF(OR(P19="",Q19=""),"",P19-Q19) | S19: =IF(P19="","",IFERROR(IF(OR((Setup!$B$7-MAX(1,Setup!$B$7-Setup!$B$13))=0,INDEX($C19:$N19,MAX(1,Setup!$B$7-Setup!$B$13))=""),"",(INDEX($C19:$N19,MAX(1,Setup!$B$7-Setup!$B$13))-P19)/(Setup!$B$7-MAX(1,Setup!$B$7-Setup!$B$13))),"")) | T19: =IF(OR(P19="",S19=""),"",IF(AND(S19>0,P19>0),P19/S19,"")) | U19: =IF(P19="","",IF(P19>=Setup!$B$11,"Suspicious: "&P19&" days is a missing link, not good news",IF(P19<0,"Already late by "&-P19&" days",IF(P19=0,"Critical: no float left",IF(AND(T19<>"",T19<=Setup!$B$14),"Runs out in about "&ROUNDUP(T19,0)&" update(s) at this rate",IF(N(S19)>0,"Burning "&TEXT(S19,"0.0")&" days an update","Holding")))))) | W19: =IF(P19="","",P19+ROW()/1000)
P20: =IF(B20="","",IFERROR(IF(INDEX($C20:$N20,Setup!$B$7)="","",INDEX($C20:$N20,Setup!$B$7)),"")) | Q20: =IF(OR(P20="",Setup!$B$7<2),"",IFERROR(IF(INDEX($C20:$N20,Setup!$B$7-1)="","",INDEX($C20:$N20,Setup!$B$7-1)),"")) | R20: =IF(OR(P20="",Q20=""),"",P20-Q20) | S20: =IF(P20="","",IFERROR(IF(OR((Setup!$B$7-MAX(1,Setup!$B$7-Setup!$B$13))=0,INDEX($C20:$N20,MAX(1,Setup!$B$7-Setup!$B$13))=""),"",(INDEX($C20:$N20,MAX(1,Setup!$B$7-Setup!$B$13))-P20)/(Setup!$B$7-MAX(1,Setup!$B$7-Setup!$B$13))),"")) | T20: =IF(OR(P20="",S20=""),"",IF(AND(S20>0,P20>0),P20/S20,"")) | U20: =IF(P20="","",IF(P20>=Setup!$B$11,"Suspicious: "&P20&" days is a missing link, not good news",IF(P20<0,"Already late by "&-P20&" days",IF(P20=0,"Critical: no float left",IF(AND(T20<>"",T20<=Setup!$B$14),"Runs out in about "&ROUNDUP(T20,0)&" update(s) at this rate",IF(N(S20)>0,"Burning "&TEXT(S20,"0.0")&" days an update","Holding")))))) | W20: =IF(P20="","",P20+ROW()/1000)
P21: =IF(B21="","",IFERROR(IF(INDEX($C21:$N21,Setup!$B$7)="","",INDEX($C21:$N21,Setup!$B$7)),"")) | Q21: =IF(OR(P21="",Setup!$B$7<2),"",IFERROR(IF(INDEX($C21:$N21,Setup!$B$7-1)="","",INDEX($C21:$N21,Setup!$B$7-1)),"")) | R21: =IF(OR(P21="",Q21=""),"",P21-Q21) | S21: =IF(P21="","",IFERROR(IF(OR((Setup!$B$7-MAX(1,Setup!$B$7-Setup!$B$13))=0,INDEX($C21:$N21,MAX(1,Setup!$B$7-Setup!$B$13))=""),"",(INDEX($C21:$N21,MAX(1,Setup!$B$7-Setup!$B$13))-P21)/(Setup!$B$7-MAX(1,Setup!$B$7-Setup!$B$13))),"")) | T21: =IF(OR(P21="",S21=""),"",IF(AND(S21>0,P21>0),P21/S21,"")) | U21: =IF(P21="","",IF(P21>=Setup!$B$11,"Suspicious: "&P21&" days is a missing link, not good news",IF(P21<0,"Already late by "&-P21&" days",IF(P21=0,"Critical: no float left",IF(AND(T21<>"",T21<=Setup!$B$14),"Runs out in about "&ROUNDUP(T21,0)&" update(s) at this rate",IF(N(S21)>0,"Burning "&TEXT(S21,"0.0")&" days an update","Holding")))))) | W21: =IF(P21="","",P21+ROW()/1000)
P22: =IF(B22="","",IFERROR(IF(INDEX($C22:$N22,Setup!$B$7)="","",INDEX($C22:$N22,Setup!$B$7)),"")) | Q22: =IF(OR(P22="",Setup!$B$7<2),"",IFERROR(IF(INDEX($C22:$N22,Setup!$B$7-1)="","",INDEX($C22:$N22,Setup!$B$7-1)),"")) | R22: =IF(OR(P22="",Q22=""),"",P22-Q22) | S22: =IF(P22="","",IFERROR(IF(OR((Setup!$B$7-MAX(1,Setup!$B$7-Setup!$B$13))=0,INDEX($C22:$N22,MAX(1,Setup!$B$7-Setup!$B$13))=""),"",(INDEX($C22:$N22,MAX(1,Setup!$B$7-Setup!$B$13))-P22)/(Setup!$B$7-MAX(1,Setup!$B$7-Setup!$B$13))),"")) | T22: =IF(OR(P22="",S22=""),"",IF(AND(S22>0,P22>0),P22/S22,"")) | U22: =IF(P22="","",IF(P22>=Setup!$B$11,"Suspicious: "&P22&" days is a missing link, not good news",IF(P22<0,"Already late by "&-P22&" days",IF(P22=0,"Critical: no float left",IF(AND(T22<>"",T22<=Setup!$B$14),"Runs out in about "&ROUNDUP(T22,0)&" update(s) at this rate",IF(N(S22)>0,"Burning "&TEXT(S22,"0.0")&" days an update","Holding")))))) | W22: =IF(P22="","",P22+ROW()/1000)
P23: =IF(B23="","",IFERROR(IF(INDEX($C23:$N23,Setup!$B$7)="","",INDEX($C23:$N23,Setup!$B$7)),"")) | Q23: =IF(OR(P23="",Setup!$B$7<2),"",IFERROR(IF(INDEX($C23:$N23,Setup!$B$7-1)="","",INDEX($C23:$N23,Setup!$B$7-1)),"")) | R23: =IF(OR(P23="",Q23=""),"",P23-Q23) | S23: =IF(P23="","",IFERROR(IF(OR((Setup!$B$7-MAX(1,Setup!$B$7-Setup!$B$13))=0,INDEX($C23:$N23,MAX(1,Setup!$B$7-Setup!$B$13))=""),"",(INDEX($C23:$N23,MAX(1,Setup!$B$7-Setup!$B$13))-P23)/(Setup!$B$7-MAX(1,Setup!$B$7-Setup!$B$13))),"")) | T23: =IF(OR(P23="",S23=""),"",IF(AND(S23>0,P23>0),P23/S23,"")) | U23: =IF(P23="","",IF(P23>=Setup!$B$11,"Suspicious: "&P23&" days is a missing link, not good news",IF(P23<0,"Already late by "&-P23&" days",IF(P23=0,"Critical: no float left",IF(AND(T23<>"",T23<=Setup!$B$14),"Runs out in about "&ROUNDUP(T23,0)&" update(s) at this rate",IF(N(S23)>0,"Burning "&TEXT(S23,"0.0")&" days an update","Holding")))))) | W23: =IF(P23="","",P23+ROW()/1000)
P24: =IF(B24="","",IFERROR(IF(INDEX($C24:$N24,Setup!$B$7)="","",INDEX($C24:$N24,Setup!$B$7)),"")) | Q24: =IF(OR(P24="",Setup!$B$7<2),"",IFERROR(IF(INDEX($C24:$N24,Setup!$B$7-1)="","",INDEX($C24:$N24,Setup!$B$7-1)),"")) | R24: =IF(OR(P24="",Q24=""),"",P24-Q24) | S24: =IF(P24="","",IFERROR(IF(OR((Setup!$B$7-MAX(1,Setup!$B$7-Setup!$B$13))=0,INDEX($C24:$N24,MAX(1,Setup!$B$7-Setup!$B$13))=""),"",(INDEX($C24:$N24,MAX(1,Setup!$B$7-Setup!$B$13))-P24)/(Setup!$B$7-MAX(1,Setup!$B$7-Setup!$B$13))),"")) | T24: =IF(OR(P24="",S24=""),"",IF(AND(S24>0,P24>0),P24/S24,"")) | U24: =IF(P24="","",IF(P24>=Setup!$B$11,"Suspicious: "&P24&" days is a missing link, not good news",IF(P24<0,"Already late by "&-P24&" days",IF(P24=0,"Critical: no float left",IF(AND(T24<>"",T24<=Setup!$B$14),"Runs out in about "&ROUNDUP(T24,0)&" update(s) at this rate",IF(N(S24)>0,"Burning "&TEXT(S24,"0.0")&" days an update","Holding")))))) | W24: =IF(P24="","",P24+ROW()/1000)
P25: =IF(B25="","",IFERROR(IF(INDEX($C25:$N25,Setup!$B$7)="","",INDEX($C25:$N25,Setup!$B$7)),"")) | Q25: =IF(OR(P25="",Setup!$B$7<2),"",IFERROR(IF(INDEX($C25:$N25,Setup!$B$7-1)="","",INDEX($C25:$N25,Setup!$B$7-1)),"")) | R25: =IF(OR(P25="",Q25=""),"",P25-Q25) | S25: =IF(P25="","",IFERROR(IF(OR((Setup!$B$7-MAX(1,Setup!$B$7-Setup!$B$13))=0,INDEX($C25:$N25,MAX(1,Setup!$B$7-Setup!$B$13))=""),"",(INDEX($C25:$N25,MAX(1,Setup!$B$7-Setup!$B$13))-P25)/(Setup!$B$7-MAX(1,Setup!$B$7-Setup!$B$13))),"")) | T25: =IF(OR(P25="",S25=""),"",IF(AND(S25>0,P25>0),P25/S25,"")) | U25: =IF(P25="","",IF(P25>=Setup!$B$11,"Suspicious: "&P25&" days is a missing link, not good news",IF(P25<0,"Already late by "&-P25&" days",IF(P25=0,"Critical: no float left",IF(AND(T25<>"",T25<=Setup!$B$14),"Runs out in about "&ROUNDUP(T25,0)&" update(s) at this rate",IF(N(S25)>0,"Burning "&TEXT(S25,"0.0")&" days an update","Holding")))))) | W25: =IF(P25="","",P25+ROW()/1000)
